Workbook

Sheet 数据需求说明
A1: 序号 | B1: 数据说明
A2: 1 | B2: 所有销量和毛利数据四舍五入，不保留小数点
A3: 2 | B3: 销量单位默认吨，毛利单位默认万元
A4: 3 | B4: 荆州与江西合并，华南大区合并，大区中的“无”修改为“其他”
A5: 4 | B5: 毛利预算暂时只到产品线维度即可
A6: 5 | B6: 页签与数据需要做权限管理（待补充）

Sheet 总览一级页面
A1: 客户等级分布（最底部增加一个饼图
D2: 客户等级 | E2: 总销量
D3: S | E3: 10000
D4: A | E4: 8000
D5: B | E5: 6000
D6: C | E6: 7000
D7: D | E7: 10000
A22: 说明：针对全量客户的总销量等级划分

Sheet 客户分析一级页面
A1: 大客户数量达成 | C1: 指纷享系统中标识的大客户 | D1: 确定不变的预算数据 | E1: 增量300吨视为达标
B2: 类型 | C2: 总提案 | D2: 年度预算（个） | E2: 达标 | F2: 差距 | G2: 达成率
B3: 提档大客户 | C3: 随时间变动（分公司维护） | D3: 300 | E3: 10 | F3: =D3-E3 -> 290 | G3: =E3/D3 -> 0.033333333
B4: 新开大客户 | C4: 随时间变动（分公司维护） | D4: 200 | E4: 10 | F4: =D4-E4 -> 190 | G4: =E4/D4 -> 0.05
A5: 大客户销量达成
D6: 确定不变的预算数据
B7: 类型 | C7: 总销量 | D7: 年度增量预算 | E7: 同比增量 | F7: 差距 | G7: 达成率
B8: 提档大客户 | C8: 3900 | D8: 90000 | E8: 900 | F8: =D8-E8 -> 89100 | G8: =E8/D8 -> 0.01
B9: 新开大客户 | D9: 60000
A11: 大客户过程指标 | B11: 来自纷享 （按不同的操作角色取数）--待定 | C11: 来自纷享 | D11: 来自纷享
B12: 拜访数 | C12: 会议数 | D12: 示范户数
A15: 大客户销量结构
B16: 按客户新开和提档的总销量来分布一个饼图
A19: 大客户模块说明：
A20: 1 | B20: 提档大客户同比增量300吨，新开大客户销量300吨
A21: 2 | B21: 年度预算和年度增量预算固定不变，即永远与年累预算对比差距，取消当月维度

Sheet 客户分析二级页面
A1: 区域 | B1: 公司 | C1: 总销量 | D1: 新开增量 | E1: 提档增量 | F1: 增量预算 | G1: 增量达成率 | H1: 总提案数 | I1: 新开数 | J1: 提档数 | K1: 预算数 | L1: 数量达成率 | M1: 取消合计（由于集团目标是500，分公司合计是530，所以不显示合计）
A2: 华东一区 | B2: 福建 | C2: 30000 | D2: 3000 | E2: 9000 | F2: =K2*300 -> 13500 | G2: =(E2+D2)/F2 -> 0.88888889 | H2: 60 | I2: 10 | J2: 30 | K2: =VLOOKUP($B2,大客户目标!$B:$C,2,0) -> 45
A3: 华东一区 | B3: 唐山 | F3: =K3*300 -> 4200 | K3: =VLOOKUP($B3,大客户目标!$B:$C,2,0) -> 14
A4: 华东一区 | B4: 惠州 | F4: =K4*300 -> 6000 | K4: =VLOOKUP($B4,大客户目标!$B:$C,2,0) -> 20
A5: 华东一区 | B5: 浙江 | F5: =K5*300 -> 9000 | K5: =VLOOKUP($B5,大客户目标!$B:$C,2,0) -> 30
A6: 华东二区 | B6: 淮安 | F6: =K6*300 -> 10500 | K6: =VLOOKUP($B6,大客户目标!$B:$C,2,0) -> 35
A7: 华东二区 | B7: 南京 | F7: =K7*300 -> 3000 | K7: =VLOOKUP($B7,大客户目标!$B:$C,2,0) -> 10
A8: 华东二区 | B8: 泰州 | F8: =K8*300 -> 10200 | K8: =VLOOKUP($B8,大客户目标!$B:$C,2,0) -> 34
A9: 华中大区 | B9: 武汉 | F9: =K9*300 -> 10500 | K9: =VLOOKUP($B9,大客户目标!$B:$C,2,0) -> 35
A10: 华中大区 | B10: 湖南 | F10: =K10*300 -> 9000 | K10: =VLOOKUP($B10,大客户目标!$B:$C,2,0) -> 30
A11: 华中大区 | B11: 汉南 | F11: =K11*300 -> 8400 | K11: =VLOOKUP($B11,大客户目标!$B:$C,2,0) -> 28
A12: 华中大区 | B12: 江西 | F12: =K12*300 -> 6000 | K12: =VLOOKUP($B12,大客户目标!$B:$C,2,0) -> 20
A13: 华中大区 | B13: 荆州 | F13: =K13*300 -> 2400 | K13: =VLOOKUP($B13,大客户目标!$B:$C,2,0) -> 8
A14: 华中大区 | B14: 益阳 | F14: =K14*300 -> 1500 | K14: =VLOOKUP($B14,大客户目标!$B:$C,2,0) -> 5
... A24: 华南大区 | B24: 广澳 | F24: =K24*300 -> 1500 | K24: =VLOOKUP($B24,大客户目标!$B:$C,2,0) -> 5

Sheet 大客户目标
A1: 大区 | B1: 公司 | C1: 26年考核目标
A2: 华东一区 | B2: 福建 | C2: 45
B3: 浙江 | C3: 30
B4: 惠州 | C4: 20
B5: 唐山 | C5: 14
A6: 华东二区 | B6: 南京 | C6: 10
B7: 淮安 | C7: 35
B8: 泰州 | C8: 34
A9: 华南大区 | B9: 江门 | C9: 70
B10: 广澳 | C10: 5
B11: 四会 | C11: 32
B12: 湛江 | C12: 25
B13: 广西 | C13: 45
B14: 贵州 | C14: 3
B15: 云南 | C15: 7
B16: 四川 | C16: 3
B17: 海南 | C17: 10
A18: 华中大区 | B18: 汉南 | C18: 28
B19: 江西 | C19: 20
B20: 洛阳 | C20: 16
B21: 武汉 | C21: 35
B22: 湖南 | C22: 30
B23: 荆州 | C23: 8
B24: 益阳 | C24: 5

Sheet 产品分析二级页面
A2: 区域 | B2: 公司 | C2: 产品线 | D2: 总销量 | H2: 高价值 | L2: 详情按钮在总销量指标模块
D3: 实际达成 | E3: 预算 | F3: 差距 | G3: 完成率 | H3: 实际达成 | I3: 预算 | J3: 差距 | K3: 完成率
A4: 华东一区 | B4: 福建 | C4: 虾蟹料
C5: 普鱼料
C6: 海特料
C7: 畜禽料
B8: 唐山 | C8: 虾蟹料
C9: 普鱼料
C10: 海特料
C11: 畜禽料
A12: 华东一区 | B12: 惠州 | C12: ...
A13: 华东一区 | B13: 浙江 | C13: ...
A14: 华东二区 | B14: 淮安 | C14: ...
A15: 华东二区 | B15: 南京 | C15: ...
A16: 华东二区 | B16: 泰州 | C16: ...
A17: 华中大区 | B17: 武汉 | C17: ...
A18: 华中大区 | B18: 湖南 | C18: ...
A19: 华中大区 | B19: 汉南 | C19: ...
A20: 华中大区 | B20: 江西 | C20: ...
A21: 华中大区 | B21: 益阳 | C21: ...
A22: 华中大区 | B22: 洛阳 | C22: ...
A23: 华南大区 | B23: 江门 | C23: ...
... A33: 反刍事业部 | B33: 洛阳畜禽 | C33: ...

Sheet 产品分析三级页面（暂缓）
A1: 大类 | B1: 小类 | C1: 总销量 | G1: 高价值
C2: 实际达成 | D2: 预算 | E2: 差距 | F2: 完成率 | G2: 实际达成 | H2: 预算 | I2: 差距 | J2: 完成率
A3: 虾料 | B3: 虾安康
A4: 虾料 | B4: 中档南美白对虾料
A5: 虾料 | B5: 中档斑节虾料
A6: 虾料 | B6: 虾配合料
A7: 虾料 | B7: 高档南美白对虾料
A8: 虾料 | B8: 罗虾料
A9: 虾料 | B9: 高档斑节虾料
A10: 虾料 | B10: 普通混养虾料
A11: 虾料 | B11: 泥鳅料
A12: 虾料 | B12: 代工-YH
A13: 虾料 | B13: 草虾料
A14: 虾料 | B14: 代工-HD
... A23: 蟹料 | B23: 通用蟹料
A24: 普通膨化鱼料
A25: 沉水鱼料
A26: 高档膨化鱼料
A27: 猪饲料
A28: 浓缩/预混料
A29: 禽料
A30: 反刍料

Sheet 毛利分析二级页面 
A1: 区域毛利达成详情
B2: 区域 | C2: 公司 | D2: 产品线 | E2: 毛利实际（万） | F2: 同期毛利（万） | G2: 同比（%） | H2: 毛利预算（万） | I2: 差距（万） | J2: 达成率（%） | K2: 详情按钮在区域线模块
B3: 华东一区 | C3: 福建 | D3: 虾蟹料
D4: 普鱼料
D5: 海特料
D6: 畜禽料
C7: 唐山 | D7: 虾蟹料
D8: 普鱼料
D9: 海特料
D10: 畜禽料
B11: 华东一区 | C11: 惠州 | D11: ...
B12: 华东一区 | C12: 浙江 | D12: ...
B13: 华东二区 | C13: 淮安 | D13: ...
B14: 华东二区 | C14: 南京 | D14: ...
B15: 华东二区 | C15: 泰州 | D15: ...
B16: 华中大区 | C16: 武汉 | D16: ...
B17: 华中大区 | C17: 湖南 | D17: ...
B18: 华中大区 | C18: 汉南 | D18: ...
B19: 华中大区 | C19: 江西 | D19: ...
B20: 华中大区 | C20: 益阳 | D20: ...
B21: 华中大区 | C21: 洛阳 | D21: ...
B22: 华南大区 | C22: 江门 | D22: ...
... B32: 反刍事业部 | C32: 洛阳畜禽 | D32: ...
A33: 高价值毛利达成详情
B34: 区域 | C34: 公司 | D34: 产品线 | E34: 毛利实际（万） | F34: 毛利同期（万） | G34: 同比（%） | H34: 毛利预算（万） | I34: 差距（万） | J34: 达成率（%） | K34: 详情按钮在高价值模块
B35: 华东一区 | C35: 福建 | D35: 虾蟹料
D36: 普鱼料
D37: 海特料
D38: 畜禽料
C39: 唐山 | D39: 虾蟹料
D40: 普鱼料
D41: 海特料
D42: 畜禽料
A47: 吨毛利达成详情
B48: 区域 | C48: 公司 | D48: 产品线 | E48: 大类 | F48: 吨毛利实际（万） | G48: 吨毛利同期（万） | H48: 同比（%） | I48: 详情按钮在吨毛利模块
B49: 华东一区 | C49: 福建 | D49: 虾蟹料 | E49: 虾料
E50: 蟹料
E51: 龙虾料
D52: 普鱼料 | E52: 普通膨化鱼料
E53: 沉水鱼料
...

Sheet 毛利分析三级页面 
A1: 吨毛利达成详情
B2: 区域 | C2: 公司 | D2: 产品线 | E2: 大类 | F2: 小类 | G2: 吨毛利实际（万） | H2: 吨毛利同期（万） | I2: 同比（%） | J2: 详情按钮在吨毛利模块
B3: 华东一区 | C3: 福建 | D3: 虾蟹料 | E3: 虾料 | F3: 虾安康
F4: 中档南美白对虾料
F5: 中档斑节虾料
F6: 虾配合料
F7: 高档南美白对虾料
F8: 罗虾料
F9: 高档斑节虾料
F10: 普通混养虾料
F11: 泥鳅料
F12: 代工-YH
F13: 草虾料
F14: 代工-HD
F15: 低档南美白对虾料
... F18: 沉性膨化小龙虾料
A19: 说明：从二级页面中表体的大类点击穿透到三级页面小类，以单个公司的维度撑开

Sheet 大客户排行榜页面
B2: —综合排行榜—
B3: 类型： | C3: 销量 | E3: 大客户 | G3: 毛利
B6: ·大区
B7: 数量排行 | G7: 销量排行（吨）
B8: 华东一区 | C8: 10 | E8: ① | G8: 华东一区 | H8: 5000 | I8: ①
B9: 华南大区 | C9: 9 | E9: ② | G9: 华中大区 | H9: 4000 | I9: ②
B10: 华中大区 | C10: 8 | E10: ③ | G10: 华南大区 | H10: 3500 | I10: ③
B11: 华东二区 | C11: 5 | E11: ④ | G11: 华东二区 | H11: 2500 | I11: ④
B14: ·公司
B15: 数量排行 | G15: 销量排行（吨）
B16: 福建 | C16: 5 | E16: ① | G16: 江门 | H16: 2000 | I16: ①
B17: 江门 | C17: 4 | E17: ② | G17: 福建 | H17: 1800 | I17: ②
B18: 湛江 | C18: 3 | E18: ③ | G18: 浙江 | H18: 1200 | I18: ③
B19: 浙江 | C19: 2 | E19: ④ | G19: 湛江 | H19: 950 | I19: ④
B20: ... | C20: ... | E20: ... | G20: ... | H20: ... | I20: ...
B23: 排行榜说明： | C23: 销量和毛利保持原方案的设计
C24: 总览页签跳转销量排行榜
C25: 大客户页签跳转大客户排行榜
C26: 产品页签跳转销量排行榜
C27: 毛利页签跳转毛利排行榜

Sheet 切片管理
A1: 切片管理表
A2: 表格说明：“√”代表受切片关联，“×”代表不显示该切片或失效
A3: 页签 | B3: 组件 | C3: 置顶切片 | F3: 侧边切片
C4: 日期 | D4: 产品线 | E4: 区域 | F4: 当月 | G4: 年累 | H4: 排行
A5: 总览 | B5: 最新销量 | C5: √ | D5: √ | E5: √ | F5: √ | G5: √ | H5: 跳转至销量排行页面
A6: 总览 | B6: 销量达成 | C6: √ | D6: √ | E6: √ | F6: √ | G6: √
A7: 总览 | B7: 毛利达成 | C7: √ | D7: √ | E7: √ | F7: √ | G7: √
A8: 总览 | B8: 产品线 | C8: √ | D8: √ | E8: √ | F8: √ | G8: √
A9: 总览 | B9: 销量分布-每月 | C9: √ | D9: √ | E9: √ | F9: √ | G9: √
A10: 总览 | B10: 客户等级分布 | C10: √ | D10: √ | E10: √ | F10: √ | G10: √
A11: 大客户分析 | B11: 大客户销量达成 | C11: √ | D11: 无效 | E11: √ | F11: 隐藏 | G11: √ | H11: 跳转至大客户排行页面
A12: 大客户分析 | B12: 大客户数量达成 | C12: √ | D12: 无效 | E12: √ | F12: 隐藏 | G12: √
A13: 大客户分析 | B13: 大客户过程指标 | C13: √ | D13: 无效 | E13: √ | F13: 隐藏 | G13: √
A14: 大客户分析 | B14: 大客户销量结构 | C14: √ | D14: 无效 | E14: √ | F14: 隐藏 | G14: √
A15: 产品分析 | B15: 总销量指标 | C15: √ | D15: √ | E15: √ | F15: √ | G15: √ | H15: 跳转至销量排行页面
A16: 产品分析 | B16: 产品线总销量指标 | C16: √ | D16: √ | E16: √ | F16: √ | G16: √
A17: 产品分析 | B17: 产品线高价值指标 | C17: √ | D17: √ | E17: √ | F17: √ | G17: √
A18: 产品分析 | B18: 销量趋势 | C18: √ | D18: √ | E18: √ | F18: √ | G18: √
A19: 产品分析 | B19: 结构占比 | C19: √ | D19: √ | E19: √ | F19: √ | G19: √
A20: 毛利分析 | B20: 总毛利达成 | C20: √ | D20: √ | E20: √ | F20: √ | G20: √ | H20: 跳转至毛利排行页面
A21: 毛利分析 | B21: 高价值毛利指标 | C21: √ | D21: √ | E21: √ | F21: √ | G21: √
A22: 毛利分析 | B22: 区域毛利达成 | C22: √ | D22: √ | E22: √ | F22: √ | G22: √
A23: 毛利分析 | B23: 产品线毛利达成 | C23: √ | D23: √ | E23: √ | F23: √ | G23: √
A24: 毛利分析 | B24: 产品线毛利结构 | C24: √ | D24: √ | E24: √ | F24: √ | G24: √
A25: 毛利分析 | B25: 吨毛利达成 | C25: √ | D25: √ | E25: √ | F25: √ | G25: √
A26: 排行 | B26: 销量 | C26: 无效 | D26: 无效 | E26: 无效 | F26: √ | G26: √ | H26: /
A27: 排行 | B27: 客户 | C27: 无效 | D27: 无效 | E27: 无效 | F27: √ | G27: √
A28: 排行 | B28: 毛利 | C28: 无效 | D28: 无效 | E28: 无效 | F28: √ | G28: √

Sheet 工作计划
A1: 手机看板研发计划
A2: 模块 | B2: 任务 | C2: 负责人 | D2: 开始时间 | E2: 天数 | F2: 完成时间
A3: 数据准备 | B3: 过程指标 | C3: 邢超、蔡青松 | D3: 3.9 | E3: 2 | F3: 3.10
B4: 毛利预算 | C4: 蔡青松
A5: 数据应用 | B5: 客户分析 | C5: 邢超、蔡青松 | D5: 3.11 | E5: 1 | F5: 3.11
B6: 产品分析 | C6: 邢超、蔡青松 | D6: 3.12 | E6: 1 | F6: 3.12
B7: 毛利分析 | C7: 邢超、蔡青松 | D7: 3.13 | E7: 1 | F7: 3.13
B8: 排行榜 | C8: 邢超、蔡青松 | D8: 3.16 | E8: 1 | F8: 3.16
A9: 数据校验 | B9: 核对数据 | C9: 邢超、蔡青松、郑世杰 | D9: 3.17 | E9: 3 | F9: 3.19

Sheet 权限管理
A1: 类型 | B1: 模块 | C1: 角色 | I1: 备注
C2: 董事长 | D2: 总裁 | E2: 副总裁 | F2: 助理总裁 （非大区总） | G2: 大区总 | H2: 基地总
A3: 页签权限 | B3: 总览 | C3: √ | D3: √ | E3: √ | F3: √ | G3: √ | H3: √ | I3: 当切换区域时，大客户分析页签里的预算、差距和完成率全部显示“-”
A4: 页签权限 | B4: 大客户分析 | C4: √ | D4: √ | E4: √ | F4: √ | G4: √ | H4: √
A5: 页签权限 | B5: 产品分析 | C5: √ | D5: √ | E5: √ | F5: √ | G5: √ | H5: √
A6: 页签权限 | B6: 毛利分析 | C6: √ | D6: √ | E6: √ | F6: √ | G6: √ | H6: √
A7: 页签权限 | B7: 排行 | C7: √ | D7: √ | E7: √ | F7: √ | G7: √ | H7: √
A8: 数据权限 | C8: 集团 | D8: 集团 | E8: 集团 | F8: 集团 | G8: 大区 | H8: 基地

Sheet 数据核对
A1: 数据核对
A2: 数据整体说明： | B2: 【销量和毛利的实际达成】的取数来源： 【销量和毛利的预算】的取数来源： 整体取数准确性： 整体取数周期： 整体数据显示反应速度：
A3: 页签 | B3: 组件/页面 | C3: 置顶切片维度 | I3: 侧边切片维度
C4: 日期（1月-至今） | E4: 产品线 | G4: 区域 | I4: 当月 | K4: 年累 | L4: 年累
C5: 准确性 | D5: 速度 | E5: 准确性 | F5: 速度 | G5: 准确性 | H5: 速度 | I5: 准确性 | J5: 速度 | K5: 准确性 | L5: 速度
A6: 总览一级页面 | B6: 最新销量
A7: 总览一级页面 | B7: 销量达成
A8: 总览一级页面 | B8: 毛利达成
A9: 总览一级页面 | B9: 产品线
A10: 总览一级页面 | B10: 销量分布-每月
A11: 总览二级页面 | B11: 区域销量毛利详情
A12: 总览二级页面 | B12: 产品线销量毛利详情
A13: 大客户分析一级页面 | B13: 大客户销量达成 | C13: 提档总销量： 纷享65303.62，看板63965，差距 | E13: / | F13: / | I13: / | J13: / | K13: / | L13: /
A14: 大客户分析一级页面 | B14: 大客户数量达成 | E14: / | F14: / | I14: / | J14: / | K14: / | L14: /
A15: 大客户分析一级页面 | B15: 大客户过程指标 | E15: / | F15: / | I15: / | J15: / | K15: / | L15: /
A16: 大客户分析一级页面 | B16: 客户等级 | E16: / | F16: / | I16: / | J16: / | K16: / | L16: /
A17: 大客户分析二级页面 | B17: 区域大客户指标详情
A18: 产品分析一级页面 | B18: 总销量指标
A19: 产品分析一级页面 | B19: 产品线总销量指标
A20: 产品分析一级页面 | B20: 产品线高价值指标
A21: 产品分析一级页面 | B21: 销量趋势
A22: 产品分析一级页面 | B22: 结构占比
A23: 产品分析二级页面 | B23: 产品线大类销量详情
A24: 毛利分析一级页面 | B24: 总毛利达成
A25: 毛利分析一级页面 | B25: 高价值毛利指标
A26: 毛利分析一级页面 | B26: 区域毛利达成
A27: 毛利分析一级页面 | B27: 产品线毛利达成
A28: 毛利分析一级页面 | B28: 产品线毛利结构
... A33: 毛利分析二级页面 | B33: 吨毛利达成详情
A34: 排行 | B34: 销量 | C34: / | D34: / | E34: / | F34: / | G34: / | H34: /
A35: 排行 | B35: 客户 | C35: / | D35: / | E35: / | F35: / | G35: / | H35: /
A36: 排行 | B36: 毛利 | C36: / | D36: / | E36: / | F36: / | G36: / | H36: /

Sheet 核对明细表
A1: 页签 | B1: 数据项目/字段 | C1: 纷享 | D1: 看板 | E1: 差距 | F1: 取数逻辑
A2: 大客户分析 | B2: 大客户总销量提档 | C2: 65303.62 | D2: 63965 | E2: =D2-C2 -> -1338.62
A3: 大客户分析 | B3: 大客户总销量新开 | C3: 9714.6 | D3: 9617 | E3: =D3-C3 -> -97.6
A4: 大客户分析 | B4: 大客户提案数量提档 | C4: 1063 | D4: 970 | E4: =D4-C4 -> -93
A5: 大客户分析 | B5: 大客户提案数量新开 | C5: 678 | D5: 416 | E5: =D5-C5 -> -262
A6: 大客户分析 | B6: 大客户达标数量新开 | C6: 4 | D6: 5 | E6: =D6-C6 -> 1
A7: 大客户分析 | B7: 大客户拜访数 | C7: ？ | D7: 21022
A8: 大客户分析 | B8: 大客户会议数 | C8: ？ | D8: 283
A9: 大客户分析 | B9: 大客户示范户数 | C9: 178 | D9: 278 | E9: =D9-C9 -> 100
A10: 大客户分析 | B10: 客户等级（达标大客户结构） | F10: 需要加一个达标的条件
A15: 内容 | B15: 负责人 | C15: 时间
A16: 大客户分析数据核对 | B16: 邢超、蔡青松、郑世杰
A17: 毛利数据核对 | B17: 蔡青松、郑世杰
A18: UI进度 | B18: 莫砚德、郑世杰
A19: 权限管理 | B19: 蔡青松、姚雨宏、莫砚德、郑世杰
A23: 输入 | C23: 输出
A24: 登录人名称
A25: 角色 | B25: 集团
B26: 大区
B27: 公司
B28: 澳华集团_华南大区_湛江
C30: 江门 | D30: ID1
C31: 湛江 | D31: ID2

Sheet 角色权限表
A1: 序 | B1: 大区 | C1: 姓名 | D1: 所属公司 | E1: 所属部门
A2: 1 | B2: 华南 | C2: 张斌 | D2: 四会澳华 | E2: 办公室
A3: 2 | C3: 邹峰 | D3: 广西澳华 | E3: 办公室
A4: 3 | C4: 温立旨 | D4: 湛江澳华 | E4: 办公室
A5: 4 | C5: 戴宏 | D5: 贵州澳华 | E5: 办公室
A6: 5 | C6: 罗海 | D6: 云南澳华 | E6: 办公室
A7: 6 | C7: 牟晓龙 | D7: 四川澳华 | E7: 办公室
A8: 7 | C8: 冼华辉 | D8: 深圳海南 | E8: 深圳海南办公室
C9: 张哲 | D9: 海南广澳
A10: 8 | C10: 杨孟伯 | D10: 华南大区 | E10: 办公室 | F10: 兼江门总经理
A11: 9 | B11: 华中 | C11: 易新文 | D11: 华中大区 | E11: 办公室 | F11: 兼武汉总经理
A12: 10 | C12: 付文超 | D12: 荆州事业部 | E12: 荆州办公室
A13: 11 | C13: 李伟 | D13: 汉南澳华 | E13: 办公室
A14: 12 | C14: 谭天柱 | D14: 湖南澳华 | E14: 办公室
A15: 13 | C15: 肖云 | D15: 益阳澳华 | E15: 办公室
A16: 14 | C16: 袁晓红 | D16: 江西澳华 | E16: 办公室
A17: 15 | C17: 伍少华 | D17: 洛阳澳华 | E17: 办公室
A18: 16 | B18: 华东 | C18: 林建好 | D18: 华东大区 | E18: 办公室 | F18: 兼福建总经理
A19: 17 | C19: 丁长云 | D19: 华东二区 | E19: 办公室
A20: 18 | C20: 廖俊 | D20: 淮安澳华 | E20: 办公室
A21: 19 | C21: 曹炳元 | D21: 浙江澳华 | E21: 办公室
A22: 20 | C22: 杨先洪 | D22: 惠州澳华 | E22: 办公室
A23: 21 | C23: 程三虎 | D23: 唐山澳华 | E23: 办公室
A24: 22 | C24: 吕赞赞 | D24: 泰州澳华 | E24: 办公室
A25: 23 | C25: 黄晋 | D25: 南京澳华 | E25: 办公室
A26: 26 | B26: 其他 | C26: 卢德 | D26: 反刍事业部 | E26: 办公室 | F26: 兼甘肃总经理
A27: 27 | C27: 韦玉标 | D27: 山东福羊 | E27: 办公室
