Workbook
Name _B471721: #REF!
Name _B471721: #REF!
Name A: #REF!
Name A: #REF!
Name A: #REF!
Name A: #REF!
Name A: #REF!
Name A: #REF!
Name A: #REF!
Name A: #REF!
Name A: #REF!
Name A: #REF!
Name A: #REF!
Name A: #REF!
Name A: #REF!
Name A: #REF!
Name A: #REF!
Name A: #REF!
Name A: #REF!
Name A: #REF!
Name A: #REF!
Name A: #REF!
Name A: #REF!
Name A: #REF!
Name A: #REF!
Name A: #REF!
Name A: #REF!
Name A: #REF!
Name A: #REF!
Name A: #REF!
Name A: #REF!
Name A: #REF!
Name A: #REF!
Name A: #REF!
Name A: #REF!
Name A: #REF!
Name A: #REF!
Name A: #REF!
Name A: #REF!
Name combo_1_1_data: #REF!
Name combo_1_1_data: #REF!
Name CompanyType: #REF!
Name CompanyType: #REF!
Name dadadadadad: #REF!
Name dadadadadad: #REF!
Name date: #REF!
Name date: #REF!
Name didi: #REF!
Name didi: #REF!
Name didi: #REF!
Name didi: #REF!
Name didi: #REF!
Name didi: #REF!
Name didi: #REF!
Name didi: #REF!
Name didi: #REF!
Name didi: #REF!
Name didi: #REF!
Name didi: #REF!
Name didi: #REF!

Sheet 目录
A1: 序号 | B1: 预算模块 | C1: 工作表名称 | D1: 报表内容 | E1: 报表类型 | F1: 部门 | G1: 顺序 | H1: 填写顺序 | I1: 填写依赖 | J1: 负责人
A2: 1 | B2: 经营指标 | C2: 总体指标 | D2: 总体指标 | E2: 查阅 | G2: 3 | J2: 黎星宇 | K2: 查询表需要--集团，大区汇总 | N2: 营业收入（分内外销、产品系列）、营业成本（生产成本、销售成本、配方成本）、税金及附加、销售费用、管理费用、财务费用、营业外收支、所得税、利润总额、净利润
A3: 2 | B3: 利润表 | C3: 年度利润表 | D3: 年度指标 | E3: 查阅 | G3: 4 | J3: 黎星宇
A4: 3 | B4: 利润表 | C4: 月度利润表 | D4: 月度指标 | E4: 查阅 | G4: 5 | J4: 黎星宇
A5: 4 | B5: 产线贡献 | C5: 产线贡献表 | D5: 产线贡献 | E5: 查阅 | G5: 6 | J5: 邵苑君
A6: 5 | B6: 人效 | C6: 人效表 | D6: 人效 | E6: 查阅 | J6: 黎星宇
A7: 6 | B7: 预算主数据 | C7: 基础档案 | D7: 基础资料 | E7: 填写 | G7: 1 | H7: 0 | J7: 黎星宇
A8: 7 | B8: 预算主数据 | C8: 物料档案 | D8: 基础资料 | E8: 填写 | G8: 2 | H8: 0 | J8: 黎星宇
A9: 8 | B9: 销量毛利 | C9: A5 表样-聚焦镇量利（查阅） | D9: 聚焦镇指标 | E9: 查阅 | G9: 9 | J9: 邵苑君
A10: 9 | B10: 销量毛利 | C10: A6 表样-大类量利（查阅） | D10: 大类指标 | E10: 查阅 | G10: 7 | J10: 邵苑君
A11: 10 | B11: 销量毛利 | C11: A7 大类小类量利（查阅） | D11: 小类指标 | E11: 查阅 | G11: 8 | J11: 邵苑君
A12: 11 | B12: 销量毛利 | C12: 新增-产品系列配销差及吨毛利（查阅） | D12: 配销差吨毛利 | E12: 查阅 | G12: 12 | J12: 邵苑君
A13: 12 | B13: =D13 -> 毛利表（外销） | C13: A9-表样-客户产品毛利表（外销） | D13: 毛利表（外销） | E13: 查阅 | G13: 10 | J13: 邵苑君
A14: 13 | B14: =D14 -> 毛利表（内销） | C14: A9-表样-客户产品毛利表（内销） | D14: 毛利表（内销） | E14: 查阅 | G14: 11 | J14: 邵苑君
A15: 14 | B15: =D15 -> 生产成本 | C15: 查阅-产品生产成本 | D15: 生产成本 | E15: 查阅 | G15: 21 | J15: 黎星宇
A16: 15 | B16: 制造费用 | C16: 查阅-单吨制造费用-生产、财务 | D16: 制造费用 | E16: 查阅 | F16: 财务 | G16: 20 | H16: 3 | I16: 依赖产量（评审后）2 | J16: 黎星宇
A17: 16 | B17: =D17 -> 动保毛利 | C17: 查阅-动保产品大类毛利 | D17: 动保毛利 | E17: 查阅 | G17: 26 | J17: 邵苑君
A18: 17 | B18: =D18 -> 动保大类毛利 | C18: 查阅-动保产品大类毛利 (分月) | D18: 动保大类毛利 | E18: 查阅 | G18: 27 | J18: 邵苑君
A19: 18 | B19: =D19 -> 动保公司毛利 | C19: 查阅-动保产品公司毛利（分月） | D19: 动保公司毛利 | E19: 查阅 | G19: 28 | J19: 邵苑君
A20: 19 | B20: =D20 -> 动保产品毛利 | C20: 查阅-动保产品毛利表（明细） | D20: 动保产品毛利 | E20: 查阅 | G20: 29 | J20: 邵苑君
A21: 20 | B21: 销量 | C21: 填写-饲料销量-营销部 | D21: 饲料销量 | E21: 填写 | F21: 营销部（填）/营业部（审） | G21: 13 | H21: 1 | J21: 邵苑君
A22: 21 | B22: 动保销售额 | C22: 填写-动保销售额-营销部 | D22: 动保销售额 | E22: 填写 | F22: 营销部（填）/营业部（审） | G22: 22 | H22: 1 | J22: 邵苑君
A23: 22 | B23: 销量 | C23: 填写-动保发酵料-营销部 | D23: 动保销售额 | E23: 填写 | F23: 营销部（填）/营业部（审） | G23: 23 | H23: 1 | J23: 邵苑君
A24: 23 | B24: 动保销售额 | C24: 填写-动保销售额（除发酵料）-动保公司填写 | D24: 动保销售额 | E24: 填写 | F24: 营销部（填）/营业部（审） | H24: 1 | J24: 邵苑君 | K24: 应该可以与21合并，单位选择不一样
A25: 24 | B25: 销量 | C25: 填写-动保销量（发酵料）--动保公司填写 | D25: 动保销量 | E25: 填写 | F25: 营销部（填）/营业部（审） | H25: 1 | J25: 邵苑君 | K25: 应该可以与22合并，单位选择不一样
A26: 25 | B26: 动保成本 | C26: 填写-动保成本（除发酵料）--动保公司填写 | D26: 动保成本 | E26: 填写 | F26: 财务 | G26: 24 | H26: 3 | I26: 依赖销量（评审后）1 | J26: 黎星宇
A27: 26 | B27: 动保成本 | C27: 填写-动保成本（发酵料）--动保公司填写 | D27: 动保成本 | E27: 填写 | F27: 财务 | G27: 25 | H27: 3 | I27: 依赖销量（评审后）1 | J27: 黎星宇
A28: 27 | B28: 代工 | C28: 填写-内部代工（需求方）-营业部 | D28: 内部代工 | E28: 填写 | F28: 营业部/财务（代） | G28: 14 | H28: 2 | I28: 依赖销量1（销量评审后） | J28: 邵苑君
A29: 28 | B29: 代工 | C29: 填写-内部代工（生产方）-财务 | D29: 内部代工 | E29: 填写 | F29: 营业部/财务（代） | G29: 15 | H29: 2 | I29: 依赖销量1（销量评审后） | J29: 邵苑君
A30: 29 | B30: 产品价格 | C30: 填写-产品价目表-财务部 | D30: 产品价目表 | E30: 填写 | F30: 财务 | G30: 16 | H30: 2 | I30: 依赖销量1（销量评审后） | J30: 邵苑君
A31: 30 | B31: 配方成本 | C31: 填写-配方成本-配方师 | D31: 配方成本 | E31: 填写 | F31: 产品线（填）/财务（审）或（代） | G31: 18 | H31: 3 | I31: 依赖销量（评审后）1 | J31: 邵苑君
A32: 31 | B32: 产品折扣 | C32: 填写-产品折扣-财务部 | D32: 产品折扣 | E32: 填写 | F32: 财务 | G32: 17 | H32: 3 | I32: 依赖销量（评审后）1 | J32: 邵苑君
A33: 32 | B33: 包材成本 | C33: 填写-包材成本-采购、财务 | D33: 采购包材成本 | E33: 填写 | F33: 财务 | G33: 19 | H33: 3 | I33: 依赖销量（评审后）1 | J33: 邵苑君
A34: 33 | B34: 原料采购 | C34: 填写-主要原料价格-采购 | D34: 采购原料价格 | E34: 填写 | F34: 采购 | G34: 30 | H34: 3 | J34: 黎星宇
A35: 34 | B35: 产量 | C35: 表3 产量-生产产量填报表 | D35: 生产产量 | E35: 填写 | F35: 生产 | G35: 22 | H35: 2 | I35: 依赖销量1（销量评审后） | J35: 黎星宇
A36: 35 | B36: =D36 -> 生产产量 | C36: 表3 产量-汇总表（按大类） | D36: 生产产量 | E36: 查阅 | G36: 23 | J36: 黎星宇
A37: 36 | B37: 制造费用 | C37: 制造费用-填报生产部 | D37: 制造费用 | E37: 填写 | F37: 生产 | G37: 24 | H37: 3 | I37: 依赖产量（评审后）2 | J37: 黎星宇
A38: 37 | B38: =D38 -> 制造费用 | C38: 单吨制费计算表 | D38: 制造费用 | E38: 查阅 | G38: 25 | J38: 黎星宇
A39: 38 | B39: 人员编制 | C39: 表4.1 人员定编表（四定表）明细- 人资 | D39: 人资报表 | E39: 填写 | F39: 人资 | G39: 31 | H39: 3 | I39: 依赖销量产量（评审后）1、2 | J39: 朱勇金
A40: 39 | B40: 人员费用 | C40: 人工成本明细-人资 | D40: 人资报表 | E40: 填写 | F40: 人资 | G40: 32 | H40: 3 | I40: 依赖销量产量（评审后）1、2/依赖人员定编表 | J40: 朱勇金
...

Sheet 总体指标
A1: ← 返回目录
A2: 财务指标审核表
A3: 大区 | B3: 公司 | C3: 指标 | D3: 2026年预算 | E3: 2025年全年 | F3: 2024年全年 | G3: 预算增长额 | H3: 预算增长率 | I3: 异常数据说明
A4: 华东一区 | B4: 福建公司 | C4: 外销销量(万吨） | D4: 计算 | E4: 计算 | F4: 计算 | G4: 本表计算 | H4: 本表计算 | I4: 单位填写
A5: =A4 -> 华东一区 | B5: 福建公司 | C5: 主营业务收入(万元） | D5: 计算 | E5: 计算 | F5: 计算 | G5: 本表计算 | H5: 本表计算 | I5: 单位填写
A6: =A5 -> 华东一区 | B6: 福建公司 | C6: 毛利(万元） | D6: 计算 | E6: 计算 | F6: 计算 | G6: 本表计算 | H6: 本表计算 | I6: 单位填写
A7: =A6 -> 华东一区 | B7: 福建公司 | C7: 毛利率 | D7: 计算 | E7: 计算 | F7: 计算 | G7: 本表计算 | H7: 本表计算 | I7: 单位填写
A8: =A7 -> 华东一区 | B8: 福建公司 | C8: NC利润 | D8: 计算 | E8: 计算 | F8: 计算 | G8: 本表计算 | H8: 本表计算 | I8: 单位填写
A9: =A8 -> 华东一区 | B9: 福建公司 | C9: 特殊考核调整 | D9: 计算 | E9: 计算 | F9: 计算 | G9: 本表计算 | H9: 本表计算 | I9: 单位填写
A10: =A9 -> 华东一区 | B10: 福建公司 | C10: 考核利润(万元） | D10: 计算 | E10: 计算 | F10: 计算 | G10: 本表计算 | H10: 本表计算 | I10: 单位填写
A11: =A10 -> 华东一区 | B11: 福建公司 | C11: 其他业务利润(万元） | D11: 计算 | E11: 计算 | F11: 计算 | G11: 本表计算 | H11: 本表计算 | I11: 单位填写
A12: =A11 -> 华东一区 | B12: 福建公司 | C12: 销售费用 | D12: 计算 | E12: 计算 | F12: 计算 | G12: 本表计算 | H12: 本表计算 | I12: 单位填写
A13: =A12 -> 华东一区 | B13: 福建公司 | C13: 管理费用 | D13: 计算 | E13: 计算 | F13: 计算 | G13: 本表计算 | H13: 本表计算 | I13: 单位填写
A14: =A13 -> 华东一区 | B14: 福建公司 | C14: 财务费用 | D14: 计算 | E14: 计算 | F14: 计算 | G14: 本表计算 | H14: 本表计算 | I14: 单位填写
A15: =A14 -> 华东一区 | B15: 福建公司 | C15: 销售E值(万元） | D15: 本表计算 | E15: 本表计算 | F15: 本表计算 | G15: 本表计算 | H15: 本表计算 | I15: 单位填写
A16: =A15 -> 华东一区 | B16: 福建公司 | C16: 管理E值(万元） | D16: 本表计算 | E16: 本表计算 | F16: 本表计算 | G16: 本表计算 | H16: 本表计算 | I16: 单位填写
... A21: =A20 -> 华东一区 | B21: 福建公司 | C21: 单吨销售费用(元/吨） | D21: 本表计算 | E21: 本表计算 | F21: 本表计算 | G21: 本表计算 | H21: 本表计算 | I21: 单位填写
A22: =A20 -> 华东一区 | B22: 福建公司 | C22: 销售费用率 | D22: 本表计算 | E22: 本表计算 | F22: 本表计算 | G22: 本表计算 | H22: 本表计算 | I22: 单位填写
A23: =A22 -> 华东一区 | B23: 福建公司 | C23: 管理费用率 | D23: 本表计算 | E23: 本表计算 | F23: 本表计算 | G23: 本表计算 | H23: 本表计算 | I23: 单位填写
A24: =A23 -> 华东一区 | B24: 福建公司 | C24: 销售E/M值 | D24: 本表计算 | E24: 本表计算 | F24: 本表计算 | G24: 本表计算 | H24: 本表计算 | I24: 单位填写
A25: =A24 -> 华东一区 | B25: 福建公司 | C25: 管理E/M值 | D25: 本表计算 | E25: 本表计算 | F25: 本表计算 | G25: 本表计算 | H25: 本表计算 | I25: 单位填写
A26: 说明：所有指标同比偏差±30%以上，请填报人员必须说明原因，财务复核其合理性。

Sheet 年度利润表
A1: ← 返回目录
A2: 大区 | B2: 公司 | C2: 报表项目 | D2: 序号 | E2: 科目名称 | F2: 2026年预算 | G2: 2025年全年 | H2: 2024年全年 | I2: 同比额 | J2: 同比率 | K2: 异常说明
A3: ='[3]A1 预算指标总览'!$A$3 -> 华东一区 | B3: ='[3]A1 预算指标总览'!$B$3 -> 福建公司 | C3: 损益总表 | D3: 1 | E3: 销售量 | F3: 标题 | G3: 标题 | H3: 标题
A4: ='[3]A1 预算指标总览'!$A$3 -> 华东一区 | B4: ='[3]A1 预算指标总览'!$B$3 -> 福建公司 | C4: 损益总表 | D4: 2 | E4: 普通膨化鱼料 | F4: 计算 | G4: 计算 | H4: 计算 | I4: 本表计算 | J4: 本表计算
A5: ='[3]A1 预算指标总览'!$A$3 -> 华东一区 | B5: ='[3]A1 预算指标总览'!$B$3 -> 福建公司 | C5: 损益总表 | D5: 3 | E5: 高档膨化鱼料 | F5: 计算 | G5: 计算 | H5: 计算 | I5: 本表计算 | J5: 本表计算
A6: ='[3]A1 预算指标总览'!$A$3 -> 华东一区 | B6: ='[3]A1 预算指标总览'!$B$3 -> 福建公司 | C6: 损益总表 | D6: 4 | E6: 沉水鱼料 | F6: 计算 | G6: 计算 | H6: 计算 | I6: 本表计算 | J6: 本表计算
A7: ='[3]A1 预算指标总览'!$A$3 -> 华东一区 | B7: ='[3]A1 预算指标总览'!$B$3 -> 福建公司 | C7: 损益总表 | D7: 5 | E7: 虾料 | F7: 计算 | G7: 计算 | H7: 计算 | I7: 本表计算 | J7: 本表计算
A8: ='[3]A1 预算指标总览'!$A$3 -> 华东一区 | B8: ='[3]A1 预算指标总览'!$B$3 -> 福建公司 | C8: 损益总表 | D8: A1 | E8: 龙虾料 | F8: 计算 | G8: 计算 | H8: 计算 | I8: 本表计算 | J8: 本表计算
A9: ='[3]A1 预算指标总览'!$A$3 -> 华东一区 | B9: ='[3]A1 预算指标总览'!$B$3 -> 福建公司 | C9: 损益总表 | D9: 6 | E9: 蟹料 | F9: 计算 | G9: 计算 | H9: 计算 | I9: 本表计算 | J9: 本表计算
A10: ='[3]A1 预算指标总览'!$A$3 -> 华东一区 | B10: ='[3]A1 预算指标总览'!$B$3 -> 福建公司 | C10: 损益总表 | D10: 7 | E10: 浓缩/预混料 | F10: 计算 | G10: 计算 | H10: 计算 | I10: 本表计算 | J10: 本表计算
A11: ='[3]A1 预算指标总览'!$A$3 -> 华东一区 | B11: ='[3]A1 预算指标总览'!$B$3 -> 福建公司 | C11: 损益总表 | D11: 8 | E11: 猪饲料 | F11: 计算 | G11: 计算 | H11: 计算 | I11: 本表计算 | J11: 本表计算
A12: ='[3]A1 预算指标总览'!$A$3 -> 华东一区 | B12: ='[3]A1 预算指标总览'!$B$3 -> 福建公司 | C12: 损益总表 | D12: 9 | E12: 禽料 | F12: 计算 | G12: 计算 | H12: 计算 | I12: 本表计算 | J12: 本表计算
A13: ='[3]A1 预算指标总览'!$A$3 -> 华东一区 | B13: ='[3]A1 预算指标总览'!$B$3 -> 福建公司 | C13: 损益总表 | D13: 10 | E13: 反刍料 | F13: 计算 | G13: 计算 | H13: 计算 | I13: 本表计算 | J13: 本表计算
A14: ='[3]A1 预算指标总览'!$A$3 -> 华东一区 | B14: ='[3]A1 预算指标总览'!$B$3 -> 福建公司 | C14: 损益总表 | D14: 11 | E14: 销售量合计(吨) | F14: 本表计算 | G14: 本表计算 | H14: 本表计算 | I14: 本表计算 | J14: 本表计算
A15: ='[3]A1 预算指标总览'!$A$3 -> 华东一区 | B15: ='[3]A1 预算指标总览'!$B$3 -> 福建公司 | C15: 损益总表 | D15: 12 | E15: 一、主营业务收入 | F15: 计算 | G15: 计算 | H15: 计算 | I15: 本表计算 | J15: 本表计算
A16: ='[3]A1 预算指标总览'!$A$3 -> 华东一区 | B16: ='[3]A1 预算指标总览'!$B$3 -> 福建公司 | C16: 损益总表 | D16: 13 | E16: 减：主营业务成本 | F16: 计算 | G16: 计算 | H16: 计算 | I16: 本表计算 | J16: 本表计算
A17: ='[3]A1 预算指标总览'!$A$3 -> 华东一区 | B17: ='[3]A1 预算指标总览'!$B$3 -> 福建公司 | C17: 损益总表 | D17: 14 | E17: 二、毛利 | F17: 本表计算 | G17: 本表计算 | H17: 本表计算 | I17: 本表计算 | J17: 本表计算
A18: ='[3]A1 预算指标总览'!$A$3 -> 华东一区 | B18: ='[3]A1 预算指标总览'!$B$3 -> 福建公司 | C18: 损益总表 | D18: 15 | E18: 加：其它业务收入（代加工收入净额） | F18: 计算 | G18: 计算 | H18: 计算 | I18: 本表计算 | J18: 本表计算
A19: ='[3]A1 预算指标总览'!$A$3 -> 华东一区 | B19: ='[3]A1 预算指标总览'!$B$3 -> 福建公司 | C19: 损益总表 | D19: 16 | E19: 减：其它业务成本（代加工成本） | F19: 计算 | G19: 计算 | H19: 计算 | I19: 本表计算 | J19: 本表计算
A20: ='[3]A1 预算指标总览'!$A$3 -> 华东一区 | B20: ='[3]A1 预算指标总览'!$B$3 -> 福建公司 | C20: 损益总表 | D20: 17 | E20: 加：其它业务收入（外卖原料收益） | F20: 计算 | G20: 计算 | H20: 计算 | I20: 本表计算 | J20: 本表计算
... A43: ='[3]A1 预算指标总览'!$A$3 -> 华东一区 | B43: ='[3]A1 预算指标总览'!$B$3 -> 福建公司 | C43: 损益总表 | D43: 40 | E43: 五、净利润 | F43: 本表计算 | G43: 本表计算 | H43: 本表计算 | I43: 本表计算 | J43: 本表计算
A44: ='[3]A1 预算指标总览'!$A$3 -> 华东一区 | B44: ='[3]A1 预算指标总览'!$B$3 -> 福建公司 | C44: 损益总表 | D44: 41
A45: ='[3]A1 预算指标总览'!$A$3 -> 华东一区 | B45: ='[3]A1 预算指标总览'!$B$3 -> 福建公司 | C45: 损益总表 | D45: 42 | E45: 科目名称
A46: ='[3]A1 预算指标总览'!$A$3 -> 华东一区 | B46: ='[3]A1 预算指标总览'!$B$3 -> 福建公司 | C46: 损益总表 | D46: 43
A47: ='[3]A1 预算指标总览'!$A$3 -> 华东一区 | B47: ='[3]A1 预算指标总览'!$B$3 -> 福建公司 | C47: 损益总表 | D47: 44 | E47: 服务中心费用 | F47: 计算 | G47: 计算 | H47: 计算 | I47: 本表计算 | J47: 本表计算 | L47: 考核调整事项
A48: ='[3]A1 预算指标总览'!$A$3 -> 华东一区 | B48: ='[3]A1 预算指标总览'!$B$3 -> 福建公司 | C48: 损益总表 | D48: 45 | E48: 服务中心费用NC入账额对冲 | F48: 计算 | G48: 计算 | H48: 计算 | I48: 本表计算 | J48: 本表计算
A49: ='[3]A1 预算指标总览'!$A$3 -> 华东一区 | B49: ='[3]A1 预算指标总览'!$B$3 -> 福建公司 | C49: 损益总表 | D49: 46 | E49: 资金占用费-应收 | F49: 计算 | G49: 计算 | H49: 计算 | I49: 本表计算 | J49: 本表计算
A50: ='[3]A1 预算指标总览'!$A$3 -> 华东一区 | B50: ='[3]A1 预算指标总览'!$B$3 -> 福建公司 | C50: 损益总表 | D50: 47 | E50: 资金占用费-应付 | F50: 计算 | G50: 计算 | H50: 计算 | I50: 本表计算 | J50: 本表计算
A51: ='[3]A1 预算指标总览'!$A$3 -> 华东一区 | B51: ='[3]A1 预算指标总览'!$B$3 -> 福建公司 | C51: 损益总表 | D51: 48 | E51: 大区费用分摊 | F51: 计算 | G51: 计算 | H51: 计算 | I51: 本表计算 | J51: 本表计算
A52: ='[3]A1 预算指标总览'!$A$3 -> 华东一区 | B52: ='[3]A1 预算指标总览'!$B$3 -> 福建公司 | C52: 损益总表 | D52: 49 | E52: 大区费用NC入账额对冲 | F52: 计算 | G52: 计算 | H52: 计算 | I52: 本表计算 | J52: 本表计算
A53: ='[3]A1 预算指标总览'!$A$3 -> 华东一区 | B53: ='[3]A1 预算指标总览'!$B$3 -> 福建公司 | C53: 损益总表 | D53: 50 | E53: 代偿逾期费用 | F53: 计算 | G53: 计算 | H53: 计算 | I53: 本表计算 | J53: 本表计算
A54: ='[3]A1 预算指标总览'!$A$3 -> 华东一区 | B54: ='[3]A1 预算指标总览'!$B$3 -> 福建公司 | C54: 损益总表 | D54: 51 | E54: 兄弟公司间的原料买卖收益 | F54: 计算 | G54: 计算 | H54: 计算 | I54: 本表计算 | J54: 本表计算
A55: ='[3]A1 预算指标总览'!$A$3 -> 华东一区 | B55: ='[3]A1 预算指标总览'!$B$3 -> 福建公司 | C55: 损益总表 | D55: 52 | E55: 合计 | F55: 本表计算 | G55: 本表计算 | H55: 本表计算 | I55: 本表计算 | J55: 本表计算
A56: ='[3]A1 预算指标总览'!$A$3 -> 华东一区 | B56: ='[3]A1 预算指标总览'!$B$3 -> 福建公司 | C56: 损益总表 | D56: 53
A57: ='[3]A1 预算指标总览'!$A$3 -> 华东一区 | B57: ='[3]A1 预算指标总览'!$B$3 -> 福建公司 | C57: 损益总表 | D57: 54 | E57: NC利润 | F57: 本表计算 | G57: 本表计算 | H57: 本表计算 | I57: 本表计算 | J57: 本表计算
A58: ='[3]A1 预算指标总览'!$A$3 -> 华东一区 | B58: ='[3]A1 预算指标总览'!$B$3 -> 福建公司 | C58: 损益总表 | D58: 55

Sheet 月度利润表
A1: ← 返回目录 | AF1: 待定
A2: 大区 | B2: 公司 | C2: 项目 | D2: 行号 | E2: 科目名称 | F2: 2026年预算 | S2: 2025年实际数 | AF2: 2025年实际数
F3: 1 | G3: 2 | H3: 3 | I3: 4 | J3: 5 | K3: 6 | L3: 7 | M3: 8 | N3: 9 | O3: 10 | P3: 11 | Q3: 12 | R3: 合计 | S3: 1 | T3: 2 | U3: 3 | V3: 4 | W3: 5 | X3: 6 | Y3: 7 | Z3: 8 | AA3: 9 | AB3: 10 | AC3: 11 | AD3: 12 | AE3: 合计 | AF3: 1 | AG3: 2 | AH3: 3 | AI3: 4 | AJ3: 5 | AK3: 6 | AL3: 7 | AM3: 8 | AN3: 9 | AO3: 10 | AP3: 11 | AQ3: 12 | AR3: 合计
A4: ='[3]A1 预算指标总览'!$A$3 -> 华东一区 | B4: ='[3]A1 预算指标总览'!$B$3 -> 福建公司 | C4: 损益总表 | D4: 1 | E4: 销售量 | F4: 标题 | G4: 标题 | H4: 标题 | I4: 标题 | J4: 标题 | K4: 标题 | L4: 标题 | M4: 标题 | N4: 标题 | O4: 标题 | P4: 标题 | Q4: 标题 | R4: 本表计算 | S4: 标题 | T4: 标题 | U4: 标题 | V4: 标题 | W4: 标题 | X4: 标题 | Y4: 标题 | Z4: 标题 | AA4: 标题 | AB4: 标题 | AC4: 标题 | AD4: 标题 | AE4: 本表计算 | AF4: 标题 | AG4: 标题 | AH4: 标题 | AI4: 标题 | AJ4: 标题 | AK4: 标题 | AL4: 标题 | AM4: 标题 | AN4: 标题 | AO4: 标题 | AP4: 标题 | AQ4: 标题 | AR4: 本表计算
A5: ='[3]A1 预算指标总览'!$A$3 -> 华东一区 | B5: ='[3]A1 预算指标总览'!$B$3 -> 福建公司 | C5: 损益总表 | D5: 2 | E5: 普通膨化鱼料 | F5: 计算 | G5: 计算 | H5: 计算 | I5: 计算 | J5: 计算 | K5: 计算 | L5: 计算 | M5: 计算 | N5: 计算 | O5: 计算 | P5: 计算 | Q5: 计算 | R5: 本表计算 | S5: 计算 | T5: 计算 | U5: 计算 | V5: 计算 | W5: 计算 | X5: 计算 | Y5: 计算 | Z5: 计算 | AA5: 计算 | AB5: 计算 | AC5: 计算 | AD5: 计算 | AE5: 本表计算 | AF5: 计算 | AG5: 计算 | AH5: 计算 | AI5: 计算 | AJ5: 计算 | AK5: 计算 | AL5: 计算 | AM5: 计算 | AN5: 计算 | AO5: 计算 | AP5: 计算 | AQ5: 计算 | AR5: 本表计算
A6: ='[3]A1 预算指标总览'!$A$3 -> 华东一区 | B6: ='[3]A1 预算指标总览'!$B$3 -> 福建公司 | C6: 损益总表 | D6: 3 | E6: 海特料 | F6: 计算 | G6: 计算 | H6: 计算 | I6: 计算 | J6: 计算 | K6: 计算 | L6: 计算 | M6: 计算 | N6: 计算 | O6: 计算 | P6: 计算 | Q6: 计算 | R6: 本表计算 | S6: 计算 | T6: 计算 | U6: 计算 | V6: 计算 | W6: 计算 | X6: 计算 | Y6: 计算 | Z6: 计算 | AA6: 计算 | AB6: 计算 | AC6: 计算 | AD6: 计算 | AE6: 本表计算 | AF6: 计算 | AG6: 计算 | AH6: 计算 | AI6: 计算 | AJ6: 计算 | AK6: 计算 | AL6: 计算 | AM6: 计算 | AN6: 计算 | AO6: 计算 | AP6: 计算 | AQ6: 计算 | AR6: 本表计算
A7: ='[3]A1 预算指标总览'!$A$3 -> 华东一区 | B7: ='[3]A1 预算指标总览'!$B$3 -> 福建公司 | C7: 损益总表 | D7: 4 | E7: 沉水鱼料 | F7: 计算 | G7: 计算 | H7: 计算 | I7: 计算 | J7: 计算 | K7: 计算 | L7: 计算 | M7: 计算 | N7: 计算 | O7: 计算 | P7: 计算 | Q7: 计算 | R7: 本表计算 | S7: 计算 | T7: 计算 | U7: 计算 | V7: 计算 | W7: 计算 | X7: 计算 | Y7: 计算 | Z7: 计算 | AA7: 计算 | AB7: 计算 | AC7: 计算 | AD7: 计算 | AE7: 本表计算 | AF7: 计算 | AG7: 计算 | AH7: 计算 | AI7: 计算 | AJ7: 计算 | AK7: 计算 | AL7: 计算 | AM7: 计算 | AN7: 计算 | AO7: 计算 | AP7: 计算 | AQ7: 计算 | AR7: 本表计算
A8: ='[3]A1 预算指标总览'!$A$3 -> 华东一区 | B8: ='[3]A1 预算指标总览'!$B$3 -> 福建公司 | C8: 损益总表 | D8: 5 | E8: 虾料 | F8: 计算 | G8: 计算 | H8: 计算 | I8: 计算 | J8: 计算 | K8: 计算 | L8: 计算 | M8: 计算 | N8: 计算 | O8: 计算 | P8: 计算 | Q8: 计算 | R8: 本表计算 | S8: 计算 | T8: 计算 | U8: 计算 | V8: 计算 | W8: 计算 | X8: 计算 | Y8: 计算 | Z8: 计算 | AA8: 计算 | AB8: 计算 | AC8: 计算 | AD8: 计算 | AE8: 本表计算 | AF8: 计算 | AG8: 计算 | AH8: 计算 | AI8: 计算 | AJ8: 计算 | AK8: 计算 | AL8: 计算 | AM8: 计算 | AN8: 计算 | AO8: 计算 | AP8: 计算 | AQ8: 计算 | AR8: 本表计算
A9: ='[3]A1 预算指标总览'!$A$3 -> 华东一区 | B9: ='[3]A1 预算指标总览'!$B$3 -> 福建公司 | C9: 损益总表 | D9: A1 | E9: 龙虾料 | F9: 计算 | G9: 计算 | H9: 计算 | I9: 计算 | J9: 计算 | K9: 计算 | L9: 计算 | M9: 计算 | N9: 计算 | O9: 计算 | P9: 计算 | Q9: 计算 | R9: 本表计算 | S9: 计算 | T9: 计算 | U9: 计算 | V9: 计算 | W9: 计算 | X9: 计算 | Y9: 计算 | Z9: 计算 | AA9: 计算 | AB9: 计算 | AC9: 计算 | AD9: 计算 | AE9: 本表计算 | AF9: 计算 | AG9: 计算 | AH9: 计算 | AI9: 计算 | AJ9: 计算 | AK9: 计算 | AL9: 计算 | AM9: 计算 | AN9: 计算 | AO9: 计算 | AP9: 计算 | AQ9: 计算 | AR9: 本表计算
A10: ='[3]A1 预算指标总览'!$A$3 -> 华东一区 | B10: ='[3]A1 预算指标总览'!$B$3 -> 福建公司 | C10: 损益总表 | D10: 6 | E10: 蟹料 | F10: 计算 | G10: 计算 | H10: 计算 | I10: 计算 | J10: 计算 | K10: 计算 | L10: 计算 | M10: 计算 | N10: 计算 | O10: 计算 | P10: 计算 | Q10: 计算 | R10: 本表计算 | S10: 计算 | T10: 计算 | U10: 计算 | V10: 计算 | W10: 计算 | X10: 计算 | Y10: 计算 | Z10: 计算 | AA10: 计算 | AB10: 计算 | AC10: 计算 | AD10: 计算 | AE10: 本表计算 | AF10: 计算 | AG10: 计算 | AH10: 计算 | AI10: 计算 | AJ10: 计算 | AK10: 计算 | AL10: 计算 | AM10: 计算 | AN10: 计算 | AO10: 计算 | AP10: 计算 | AQ10: 计算 | AR10: 本表计算
A11: ='[3]A1 预算指标总览'!$A$3 -> 华东一区 | B11: ='[3]A1 预算指标总览'!$B$3 -> 福建公司 | C11: 损益总表 | D11: 7 | E11: 浓缩/预混料 | F11: 计算 | G11: 计算 | H11: 计算 | I11: 计算 | J11: 计算 | K11: 计算 | L11: 计算 | M11: 计算 | N11: 计算 | O11: 计算 | P11: 计算 | Q11: 计算 | R11: 本表计算 | S11: 计算 | T11: 计算 | U11: 计算 | V11: 计算 | W11: 计算 | X11: 计算 | Y11: 计算 | Z11: 计算 | AA11: 计算 | AB11: 计算 | AC11: 计算 | AD11: 计算 | AE11: 本表计算 | AF11: 计算 | AG11: 计算 | AH11: 计算 | AI11: 计算 | AJ11: 计算 | AK11: 计算 | AL11: 计算 | AM11: 计算 | AN11: 计算 | AO11: 计算 | AP11: 计算 | AQ11: 计算 | AR11: 本表计算
A12: ='[3]A1 预算指标总览'!$A$3 -> 华东一区 | B12: ='[3]A1 预算指标总览'!$B$3 -> 福建公司 | C12: 损益总表 | D12: 8 | E12: 猪饲料 | F12: 计算 | G12: 计算 | H12: 计算 | I12: 计算 | J12: 计算 | K12: 计算 | L12: 计算 | M12: 计算 | N12: 计算 | O12: 计算 | P12: 计算 | Q12: 计算 | R12: 本表计算 | S12: 计算 | T12: 计算 | U12: 计算 | V12: 计算 | W12: 计算 | X12: 计算 | Y12: 计算 | Z12: 计算 | AA12: 计算 | AB12: 计算 | AC12: 计算 | AD12: 计算 | AE12: 本表计算 | AF12: 计算 | AG12: 计算 | AH12: 计算 | AI12: 计算 | AJ12: 计算 | AK12: 计算 | AL12: 计算 | AM12: 计算 | AN12: 计算 | AO12: 计算 | AP12: 计算 | AQ12: 计算 | AR12: 本表计算
A13: ='[3]A1 预算指标总览'!$A$3 -> 华东一区 | B13: ='[3]A1 预算指标总览'!$B$3 -> 福建公司 | C13: 损益总表 | D13: 9 | E13: 禽料 | F13: 计算 | G13: 计算 | H13: 计算 | I13: 计算 | J13: 计算 | K13: 计算 | L13: 计算 | M13: 计算 | N13: 计算 | O13: 计算 | P13: 计算 | Q13: 计算 | R13: 本表计算 | S13: 计算 | T13: 计算 | U13: 计算 | V13: 计算 | W13: 计算 | X13: 计算 | Y13: 计算 | Z13: 计算 | AA13: 计算 | AB13: 计算 | AC13: 计算 | AD13: 计算 | AE13: 本表计算 | AF13: 计算 | AG13: 计算 | AH13: 计算 | AI13: 计算 | AJ13: 计算 | AK13: 计算 | AL13: 计算 | AM13: 计算 | AN13: 计算 | AO13: 计算 | AP13: 计算 | AQ13: 计算 | AR13: 本表计算
A14: ='[3]A1 预算指标总览'!$A$3 -> 华东一区 | B14: ='[3]A1 预算指标总览'!$B$3 -> 福建公司 | C14: 损益总表 | D14: 10 | E14: 反刍料 | F14: 计算 | G14: 计算 | H14: 计算 | I14: 计算 | J14: 计算 | K14: 计算 | L14: 计算 | M14: 计算 | N14: 计算 | O14: 计算 | P14: 计算 | Q14: 计算 | R14: 本表计算 | S14: 计算 | T14: 计算 | U14: 计算 | V14: 计算 | W14: 计算 | X14: 计算 | Y14: 计算 | Z14: 计算 | AA14: 计算 | AB14: 计算 | AC14: 计算 | AD14: 计算 | AE14: 本表计算 | AF14: 计算 | AG14: 计算 | AH14: 计算 | AI14: 计算 | AJ14: 计算 | AK14: 计算 | AL14: 计算 | AM14: 计算 | AN14: 计算 | AO14: 计算 | AP14: 计算 | AQ14: 计算 | AR14: 本表计算
A15: ='[3]A1 预算指标总览'!$A$3 -> 华东一区 | B15: ='[3]A1 预算指标总览'!$B$3 -> 福建公司 | C15: 损益总表 | D15: 11 | E15: 销售量合计(吨) | F15: 本表计算 | G15: 本表计算 | H15: 本表计算 | I15: 本表计算 | J15: 本表计算 | K15: 本表计算 | L15: 本表计算 | M15: 本表计算 | N15: 本表计算 | O15: 本表计算 | P15: 本表计算 | Q15: 本表计算 | R15: 本表计算 | S15: 本表计算 | T15: 本表计算 | U15: 本表计算 | V15: 本表计算 | W15: 本表计算 | X15: 本表计算 | Y15: 本表计算 | Z15: 本表计算 | AA15: 本表计算 | AB15: 本表计算 | AC15: 本表计算 | AD15: 本表计算 | AE15: 本表计算 | AF15: 本表计算 | AG15: 本表计算 | AH15: 本表计算 | AI15: 本表计算 | AJ15: 本表计算 | AK15: 本表计算 | AL15: 本表计算 | AM15: 本表计算 | AN15: 本表计算 | AO15: 本表计算 | AP15: 本表计算 | AQ15: 本表计算 | AR15: 本表计算
A16: ='[3]A1 预算指标总览'!$A$3 -> 华东一区 | B16: ='[3]A1 预算指标总览'!$B$3 -> 福建公司 | C16: 损益总表 | D16: 12 | E16: 一、主营业务收入 | F16: 计算 | G16: 计算 | H16: 计算 | I16: 计算 | J16: 计算 | K16: 计算 | L16: 计算 | M16: 计算 | N16: 计算 | O16: 计算 | P16: 计算 | Q16: 计算 | R16: 本表计算 | S16: 计算 | T16: 计算 | U16: 计算 | V16: 计算 | W16: 计算 | X16: 计算 | Y16: 计算 | Z16: 计算 | AA16: 计算 | AB16: 计算 | AC16: 计算 | AD16: 计算 | AE16: 本表计算 | AF16: 计算 | AG16: 计算 | AH16: 计算 | AI16: 计算 | AJ16: 计算 | AK16: 计算 | AL16: 计算 | AM16: 计算 | AN16: 计算 | AO16: 计算 | AP16: 计算 | AQ16: 计算 | AR16: 本表计算
A17: ='[3]A1 预算指标总览'!$A$3 -> 华东一区 | B17: ='[3]A1 预算指标总览'!$B$3 -> 福建公司 | C17: 损益总表 | D17: 13 | E17: 减：主营业务成本 | F17: 计算 | G17: 计算 | H17: 计算 | I17: 计算 | J17: 计算 | K17: 计算 | L17: 计算 | M17: 计算 | N17: 计算 | O17: 计算 | P17: 计算 | Q17: 计算 | R17: 本表计算 | S17: 计算 | T17: 计算 | U17: 计算 | V17: 计算 | W17: 计算 | X17: 计算 | Y17: 计算 | Z17: 计算 | AA17: 计算 | AB17: 计算 | AC17: 计算 | AD17: 计算 | AE17: 本表计算 | AF17: 计算 | AG17: 计算 | AH17: 计算 | AI17: 计算 | AJ17: 计算 | AK17: 计算 | AL17: 计算 | AM17: 计算 | AN17: 计算 | AO17: 计算 | AP17: 计算 | AQ17: 计算 | AR17: 本表计算
A18: ='[3]A1 预算指标总览'!$A$3 -> 华东一区 | B18: ='[3]A1 预算指标总览'!$B$3 -> 福建公司 | C18: 损益总表 | D18: 14 | E18: 二、毛利 | F18: 本表计算 | G18: 本表计算 | H18: 本表计算 | I18: 本表计算 | J18: 本表计算 | K18: 本表计算 | L18: 本表计算 | M18: 本表计算 | N18: 本表计算 | O18: 本表计算 | P18: 本表计算 | Q18: 本表计算 | R18: 本表计算 | S18: 本表计算 | T18: 本表计算 | U18: 本表计算 | V18: 本表计算 | W18: 本表计算 | X18: 本表计算 | Y18: 本表计算 | Z18: 本表计算 | AA18: 本表计算 | AB18: 本表计算 | AC18: 本表计算 | AD18: 本表计算 | AE18: 本表计算 | AF18: 本表计算 | AG18: 本表计算 | AH18: 本表计算 | AI18: 本表计算 | AJ18: 本表计算 | AK18: 本表计算 | AL18: 本表计算 | AM18: 本表计算 | AN18: 本表计算 | AO18: 本表计算 | AP18: 本表计算 | AQ18: 本表计算 | AR18: 本表计算
A19: ='[3]A1 预算指标总览'!$A$3 -> 华东一区 | B19: ='[3]A1 预算指标总览'!$B$3 -> 福建公司 | C19: 损益总表 | D19: 15 | E19: 加：其它业务收入（代加工收入净额） | F19: 计算 | G19: 计算 | H19: 计算 | I19: 计算 | J19: 计算 | K19: 计算 | L19: 计算 | M19: 计算 | N19: 计算 | O19: 计算 | P19: 计算 | Q19: 计算 | R19: 本表计算 | S19: 计算 | T19: 计算 | U19: 计算 | V19: 计算 | W19: 计算 | X19: 计算 | Y19: 计算 | Z19: 计算 | AA19: 计算 | AB19: 计算 | AC19: 计算 | AD19: 计算 | AE19: 本表计算 | AF19: 计算 | AG19: 计算 | AH19: 计算 | AI19: 计算 | AJ19: 计算 | AK19: 计算 | AL19: 计算 | AM19: 计算 | AN19: 计算 | AO19: 计算 | AP19: 计算 | AQ19: 计算 | AR19: 本表计算
A20: ='[3]A1 预算指标总览'!$A$3 -> 华东一区 | B20: ='[3]A1 预算指标总览'!$B$3 -> 福建公司 | C20: 损益总表 | D20: 16 | E20: 减：其它业务成本（代加工成本） | F20: 计算 | G20: 计算 | H20: 计算 | I20: 计算 | J20: 计算 | K20: 计算 | L20: 计算 | M20: 计算 | N20: 计算 | O20: 计算 | P20: 计算 | Q20: 计算 | R20: 本表计算 | S20: 计算 | T20: 计算 | U20: 计算 | V20: 计算 | W20: 计算 | X20: 计算 | Y20: 计算 | Z20: 计算 | AA20: 计算 | AB20: 计算 | AC20: 计算 | AD20: 计算 | AE20: 本表计算 | AF20: 计算 | AG20: 计算 | AH20: 计算 | AI20: 计算 | AJ20: 计算 | AK20: 计算 | AL20: 计算 | AM20: 计算 | AN20: 计算 | AO20: 计算 | AP20: 计算 | AQ20: 计算 | AR20: 本表计算
A21: ='[3]A1 预算指标总览'!$A$3 -> 华东一区 | B21: ='[3]A1 预算指标总览'!$B$3 -> 福建公司 | C21: 损益总表 | D21: 17 | E21: 加：其它业务收入（外卖原料收益） | F21: 计算 | G21: 计算 | H21: 计算 | I21: 计算 | J21: 计算 | K21: 计算 | L21: 计算 | M21: 计算 | N21: 计算 | O21: 计算 | P21: 计算 | Q21: 计算 | R21: 本表计算 | S21: 计算 | T21: 计算 | U21: 计算 | V21: 计算 | W21: 计算 | X21: 计算 | Y21: 计算 | Z21: 计算 | AA21: 计算 | AB21: 计算 | AC21: 计算 | AD21: 计算 | AE21: 本表计算 | AF21: 计算 | AG21: 计算 | AH21: 计算 | AI21: 计算 | AJ21: 计算 | AK21: 计算 | AL21: 计算 | AM21: 计算 | AN21: 计算 | AO21: 计算 | AP21: 计算 | AQ21: 计算 | AR21: 本表计算
... A44: ='[3]A1 预算指标总览'!$A$3 -> 华东一区 | B44: ='[3]A1 预算指标总览'!$B$3 -> 福建公司 | C44: 损益总表 | D44: 40 | E44: 五、净利润 | F44: 本表计算 | G44: 本表计算 | H44: 本表计算 | I44: 本表计算 | J44: 本表计算 | K44: 本表计算 | L44: 本表计算 | M44: 本表计算 | N44: 本表计算 | O44: 本表计算 | P44: 本表计算 | Q44: 本表计算 | R44: 本表计算 | S44: 本表计算 | T44: 本表计算 | U44: 本表计算 | V44: 本表计算 | W44: 本表计算 | X44: 本表计算 | Y44: 本表计算 | Z44: 本表计算 | AA44: 本表计算 | AB44: 本表计算 | AC44: 本表计算 | AD44: 本表计算 | AE44: 本表计算 | AF44: 本表计算 | AG44: 本表计算 | AH44: 本表计算 | AI44: 本表计算 | AJ44: 本表计算 | AK44: 本表计算 | AL44: 本表计算 | AM44: 本表计算 | AN44: 本表计算 | AO44: 本表计算 | AP44: 本表计算 | AQ44: 本表计算 | AR44: 本表计算
A45: ='[3]A1 预算指标总览'!$A$3 -> 华东一区 | B45: ='[3]A1 预算指标总览'!$B$3 -> 福建公司 | C45: 损益总表 | D45: 41
A46: ='[3]A1 预算指标总览'!$A$3 -> 华东一区 | B46: ='[3]A1 预算指标总览'!$B$3 -> 福建公司 | C46: 损益总表 | D46: 42 | E46: 科目名称 | F46: 2026年预算 | S46: 2025年实际数 | AF46: 2024年实际数
A47: ='[3]A1 预算指标总览'!$A$3 -> 华东一区 | B47: ='[3]A1 预算指标总览'!$B$3 -> 福建公司 | C47: 损益总表 | D47: 43 | F47: 1 | G47: 2 | H47: 3 | I47: 4 | J47: 5 | K47: 6 | L47: 7 | M47: 8 | N47: 9 | O47: 10 | P47: 11 | Q47: 12 | R47: 合计 | S47: 1 | T47: 2 | U47: 3 | V47: 4 | W47: 5 | X47: 6 | Y47: 7 | Z47: 8 | AA47: 9 | AB47: 10 | AC47: 11 | AD47: 12 | AE47: 合计 | AF47: 1 | AG47: 2 | AH47: 3 | AI47: 4 | AJ47: 5 | AK47: 6 | AL47: 7 | AM47: 8 | AN47: 9 | AO47: 10 | AP47: 11 | AQ47: 12 | AR47: 合计
A48: ='[3]A1 预算指标总览'!$A$3 -> 华东一区 | B48: ='[3]A1 预算指标总览'!$B$3 -> 福建公司 | C48: 损益总表 | D48: 44 | E48: 服务中心费用 | F48: 计算 | G48: 计算 | H48: 计算 | I48: 计算 | J48: 计算 | K48: 计算 | L48: 计算 | M48: 计算 | N48: 计算 | O48: 计算 | P48: 计算 | Q48: 计算 | R48: 本表计算 | S48: 计算 | T48: 计算 | U48: 计算 | V48: 计算 | W48: 计算 | X48: 计算 | Y48: 计算 | Z48: 计算 | AA48: 计算 | AB48: 计算 | AC48: 计算 | AD48: 计算 | AE48: 本表计算 | AF48: 计算 | AG48: 计算 | AH48: 计算 | AI48: 计算 | AJ48: 计算 | AK48: 计算 | AL48: 计算 | AM48: 计算 | AN48: 计算 | AO48: 计算 | AP48: 计算 | AQ48: 计算 | AR48: 本表计算
A49: ='[3]A1 预算指标总览'!$A$3 -> 华东一区 | B49: ='[3]A1 预算指标总览'!$B$3 -> 福建公司 | C49: 损益总表 | D49: 45 | E49: 服务中心费用NC入账额对冲 | F49: 计算 | G49: 计算 | H49: 计算 | I49: 计算 | J49: 计算 | K49: 计算 | L49: 计算 | M49: 计算 | N49: 计算 | O49: 计算 | P49: 计算 | Q49: 计算 | R49: 本表计算 | S49: 计算 | T49: 计算 | U49: 计算 | V49: 计算 | W49: 计算 | X49: 计算 | Y49: 计算 | Z49: 计算 | AA49: 计算 | AB49: 计算 | AC49: 计算 | AD49: 计算 | AE49: 本表计算 | AF49: 计算 | AG49: 计算 | AH49: 计算 | AI49: 计算 | AJ49: 计算 | AK49: 计算 | AL49: 计算 | AM49: 计算 | AN49: 计算 | AO49: 计算 | AP49: 计算 | AQ49: 计算 | AR49: 本表计算
A50: ='[3]A1 预算指标总览'!$A$3 -> 华东一区 | B50: ='[3]A1 预算指标总览'!$B$3 -> 福建公司 | C50: 损益总表 | D50: 46 | E50: 资金占用费-应收 | F50: 计算 | G50: 计算 | H50: 计算 | I50: 计算 | J50: 计算 | K50: 计算 | L50: 计算 | M50: 计算 | N50: 计算 | O50: 计算 | P50: 计算 | Q50: 计算 | R50: 本表计算 | S50: 计算 | T50: 计算 | U50: 计算 | V50: 计算 | W50: 计算 | X50: 计算 | Y50: 计算 | Z50: 计算 | AA50: 计算 | AB50: 计算 | AC50: 计算 | AD50: 计算 | AE50: 本表计算 | AF50: 计算 | AG50: 计算 | AH50: 计算 | AI50: 计算 | AJ50: 计算 | AK50: 计算 | AL50: 计算 | AM50: 计算 | AN50: 计算 | AO50: 计算 | AP50: 计算 | AQ50: 计算 | AR50: 本表计算
A51: ='[3]A1 预算指标总览'!$A$3 -> 华东一区 | B51: ='[3]A1 预算指标总览'!$B$3 -> 福建公司 | C51: 损益总表 | D51: 47 | E51: 资金占用费-应付 | F51: 计算 | G51: 计算 | H51: 计算 | I51: 计算 | J51: 计算 | K51: 计算 | L51: 计算 | M51: 计算 | N51: 计算 | O51: 计算 | P51: 计算 | Q51: 计算 | R51: 本表计算 | S51: 计算 | T51: 计算 | U51: 计算 | V51: 计算 | W51: 计算 | X51: 计算 | Y51: 计算 | Z51: 计算 | AA51: 计算 | AB51: 计算 | AC51: 计算 | AD51: 计算 | AE51: 本表计算 | AF51: 计算 | AG51: 计算 | AH51: 计算 | AI51: 计算 | AJ51: 计算 | AK51: 计算 | AL51: 计算 | AM51: 计算 | AN51: 计算 | AO51: 计算 | AP51: 计算 | AQ51: 计算 | AR51: 本表计算
A52: ='[3]A1 预算指标总览'!$A$3 -> 华东一区 | B52: ='[3]A1 预算指标总览'!$B$3 -> 福建公司 | C52: 损益总表 | D52: 48 | E52: 大区费用分摊 | F52: 计算 | G52: 计算 | H52: 计算 | I52: 计算 | J52: 计算 | K52: 计算 | L52: 计算 | M52: 计算 | N52: 计算 | O52: 计算 | P52: 计算 | Q52: 计算 | R52: 本表计算 | S52: 计算 | T52: 计算 | U52: 计算 | V52: 计算 | W52: 计算 | X52: 计算 | Y52: 计算 | Z52: 计算 | AA52: 计算 | AB52: 计算 | AC52: 计算 | AD52: 计算 | AE52: 本表计算 | AF52: 计算 | AG52: 计算 | AH52: 计算 | AI52: 计算 | AJ52: 计算 | AK52: 计算 | AL52: 计算 | AM52: 计算 | AN52: 计算 | AO52: 计算 | AP52: 计算 | AQ52: 计算 | AR52: 本表计算
A53: ='[3]A1 预算指标总览'!$A$3 -> 华东一区 | B53: ='[3]A1 预算指标总览'!$B$3 -> 福建公司 | C53: 损益总表 | D53: 49 | E53: 大区费用NC入账额对冲 | F53: 计算 | G53: 计算 | H53: 计算 | I53: 计算 | J53: 计算 | K53: 计算 | L53: 计算 | M53: 计算 | N53: 计算 | O53: 计算 | P53: 计算 | Q53: 计算 | R53: 本表计算 | S53: 计算 | T53: 计算 | U53: 计算 | V53: 计算 | W53: 计算 | X53: 计算 | Y53: 计算 | Z53: 计算 | AA53: 计算 | AB53: 计算 | AC53: 计算 | AD53: 计算 | AE53: 本表计算 | AF53: 计算 | AG53: 计算 | AH53: 计算 | AI53: 计算 | AJ53: 计算 | AK53: 计算 | AL53: 计算 | AM53: 计算 | AN53: 计算 | AO53: 计算 | AP53: 计算 | AQ53: 计算 | AR53: 本表计算
A54: ='[3]A1 预算指标总览'!$A$3 -> 华东一区 | B54: ='[3]A1 预算指标总览'!$B$3 -> 福建公司 | C54: 损益总表 | D54: 50 | E54: 代偿逾期费用 | F54: 计算 | G54: 计算 | H54: 计算 | I54: 计算 | J54: 计算 | K54: 计算 | L54: 计算 | M54: 计算 | N54: 计算 | O54: 计算 | P54: 计算 | Q54: 计算 | R54: 本表计算 | S54: 计算 | T54: 计算 | U54: 计算 | V54: 计算 | W54: 计算 | X54: 计算 | Y54: 计算 | Z54: 计算 | AA54: 计算 | AB54: 计算 | AC54: 计算 | AD54: 计算 | AE54: 本表计算 | AF54: 计算 | AG54: 计算 | AH54: 计算 | AI54: 计算 | AJ54: 计算 | AK54: 计算 | AL54: 计算 | AM54: 计算 | AN54: 计算 | AO54: 计算 | AP54: 计算 | AQ54: 计算 | AR54: 本表计算
A55: ='[3]A1 预算指标总览'!$A$3 -> 华东一区 | B55: ='[3]A1 预算指标总览'!$B$3 -> 福建公司 | C55: 损益总表 | D55: 51 | E55: 兄弟公司间的原料买卖收益 | F55: 计算 | G55: 计算 | H55: 计算 | I55: 计算 | J55: 计算 | K55: 计算 | L55: 计算 | M55: 计算 | N55: 计算 | O55: 计算 | P55: 计算 | Q55: 计算 | R55: 本表计算 | S55: 计算 | T55: 计算 | U55: 计算 | V55: 计算 | W55: 计算 | X55: 计算 | Y55: 计算 | Z55: 计算 | AA55: 计算 | AB55: 计算 | AC55: 计算 | AD55: 计算 | AE55: 本表计算 | AF55: 计算 | AG55: 计算 | AH55: 计算 | AI55: 计算 | AJ55: 计算 | AK55: 计算 | AL55: 计算 | AM55: 计算 | AN55: 计算 | AO55: 计算 | AP55: 计算 | AQ55: 计算 | AR55: 本表计算
A56: ='[3]A1 预算指标总览'!$A$3 -> 华东一区 | B56: ='[3]A1 预算指标总览'!$B$3 -> 福建公司 | C56: 损益总表 | D56: 52 | E56: 合计 | F56: 本表计算 | G56: 本表计算 | H56: 本表计算 | I56: 本表计算 | J56: 本表计算 | K56: 本表计算 | L56: 本表计算 | M56: 本表计算 | N56: 本表计算 | O56: 本表计算 | P56: 本表计算 | Q56: 本表计算 | R56: 本表计算 | S56: 本表计算 | T56: 本表计算 | U56: 本表计算 | V56: 本表计算 | W56: 本表计算 | X56: 本表计算 | Y56: 本表计算 | Z56: 本表计算 | AA56: 本表计算 | AB56: 本表计算 | AC56: 本表计算 | AD56: 本表计算 | AE56: 本表计算 | AF56: 本表计算 | AG56: 本表计算 | AH56: 本表计算 | AI56: 本表计算 | AJ56: 本表计算 | AK56: 本表计算 | AL56: 本表计算 | AM56: 本表计算 | AN56: 本表计算 | AO56: 本表计算 | AP56: 本表计算 | AQ56: 本表计算 | AR56: 本表计算
A57: ='[3]A1 预算指标总览'!$A$3 -> 华东一区 | B57: ='[3]A1 预算指标总览'!$B$3 -> 福建公司 | C57: 损益总表 | D57: 53 | R57: 本表计算 | AE57: 本表计算 | AR57: 本表计算
A58: ='[3]A1 预算指标总览'!$A$3 -> 华东一区 | B58: ='[3]A1 预算指标总览'!$B$3 -> 福建公司 | C58: 损益总表 | D58: 54 | E58: NC利润 | F58: 本表计算 | G58: 本表计算 | H58: 本表计算 | I58: 本表计算 | J58: 本表计算 | K58: 本表计算 | L58: 本表计算 | M58: 本表计算 | N58: 本表计算 | O58: 本表计算 | P58: 本表计算 | Q58: 本表计算 | R58: 本表计算 | S58: 本表计算 | T58: 本表计算 | U58: 本表计算 | V58: 本表计算 | W58: 本表计算 | X58: 本表计算 | Y58: 本表计算 | Z58: 本表计算 | AA58: 本表计算 | AB58: 本表计算 | AC58: 本表计算 | AD58: 本表计算 | AE58: 本表计算 | AF58: 本表计算 | AG58: 本表计算 | AH58: 本表计算 | AI58: 本表计算 | AJ58: 本表计算 | AK58: 本表计算 | AL58: 本表计算 | AM58: 本表计算 | AN58: 本表计算 | AO58: 本表计算 | AP58: 本表计算 | AQ58: 本表计算 | AR58: 本表计算

Sheet 产线贡献表
A1: ← 返回目录
E2: 定规则
A3: 公司 | B3: 产品线 | C3: 26年预算值 | M3: 同比 | W3: 25年实际值
C4: 销量 | D4: 毛利 | E4: 销售人数 | F4: 人员费用 | G4: 非人员费用 | H4: 总销售费用 | I4: 销售贡献 | J4: 人均贡献 | K4: 人均销量 | L4: 人均毛利 | M4: 销量 | N4: 毛利 | O4: 销售人数 | P4: 人员费用 | Q4: 非人员费用 | R4: 总销售费用 | S4: 销售贡献 | T4: 人均贡献 | U4: 人均销量 | V4: 人均毛利 | W4: 销量 | X4: 毛利 | Y4: 销售人数 | Z4: 人员费用 | AA4: 非人员费用 | AB4: 总销售费用 | AC4: 销售贡献 | AD4: 人均贡献 | AE4: 人均销量 | AF4: 人均毛利
B5: 虾蟹线 | C5: 计算 | D5: 计算 | E5: 计算 | F5: 计算 | G5: 计算 | H5: 计算 | I5: 本表计算 | J5: 本表计算 | K5: 本表计算 | L5: 本表计算 | M5: 本表计算 | N5: 本表计算 | O5: 本表计算 | P5: 本表计算 | Q5: 本表计算 | R5: 本表计算 | S5: 本表计算 | T5: 本表计算 | U5: 本表计算 | V5: 本表计算 | W5: 计算 | X5: 计算 | Y5: 计算 | Z5: 计算 | AA5: 计算 | AB5: 计算 | AC5: 本表计算 | AD5: 本表计算 | AE5: 本表计算 | AF5: 本表计算
B6: 海特线 | C6: 计算 | D6: 计算 | E6: 计算 | F6: 计算 | G6: 计算 | H6: 计算 | I6: 本表计算 | J6: 本表计算 | K6: 本表计算 | L6: 本表计算 | M6: 本表计算 | N6: 本表计算 | O6: 本表计算 | P6: 本表计算 | Q6: 本表计算 | R6: 本表计算 | S6: 本表计算 | T6: 本表计算 | U6: 本表计算 | V6: 本表计算 | W6: 计算 | X6: 计算 | Y6: 计算 | Z6: 计算 | AA6: 计算 | AB6: 计算 | AC6: 本表计算 | AD6: 本表计算 | AE6: 本表计算 | AF6: 本表计算
B7: 鱼料线 | C7: 计算 | D7: 计算 | E7: 计算 | F7: 计算 | G7: 计算 | H7: 计算 | I7: 本表计算 | J7: 本表计算 | K7: 本表计算 | L7: 本表计算 | M7: 本表计算 | N7: 本表计算 | O7: 本表计算 | P7: 本表计算 | Q7: 本表计算 | R7: 本表计算 | S7: 本表计算 | T7: 本表计算 | U7: 本表计算 | V7: 本表计算 | W7: 计算 | X7: 计算 | Y7: 计算 | Z7: 计算 | AA7: 计算 | AB7: 计算 | AC7: 本表计算 | AD7: 本表计算 | AE7: 本表计算 | AF7: 本表计算
B8: 畜禽线 | C8: 计算 | D8: 计算 | E8: 计算 | F8: 计算 | G8: 计算 | H8: 计算 | I8: 本表计算 | J8: 本表计算 | K8: 本表计算 | L8: 本表计算 | M8: 本表计算 | N8: 本表计算 | O8: 本表计算 | P8: 本表计算 | Q8: 本表计算 | R8: 本表计算 | S8: 本表计算 | T8: 本表计算 | U8: 本表计算 | V8: 本表计算 | W8: 计算 | X8: 计算 | Y8: 计算 | Z8: 计算 | AA8: 计算 | AB8: 计算 | AC8: 本表计算 | AD8: 本表计算 | AE8: 本表计算 | AF8: 本表计算
B9: 合计 | C9: 本表计算 | D9: 本表计算 | E9: 本表计算 | F9: 本表计算 | G9: 本表计算 | H9: 本表计算 | I9: 本表计算 | J9: 本表计算 | K9: 本表计算 | L9: 本表计算 | M9: 本表计算 | N9: 本表计算 | O9: 本表计算 | P9: 本表计算 | Q9: 本表计算 | R9: 本表计算 | S9: 本表计算 | T9: 本表计算 | U9: 本表计算 | V9: 本表计算 | W9: 本表计算 | X9: 本表计算 | Y9: 本表计算 | Z9: 本表计算 | AA9: 本表计算 | AB9: 本表计算 | AC9: 本表计算 | AD9: 本表计算 | AE9: 本表计算 | AF9: 本表计算

Sheet 人效表
A1: ← 返回目录 | B1: 公司 | C1: 产线 | D1: 人均销量 | S1: 人数 | AG1: 销量
D2: 25年 | E2: 26年 | F2: 同比 | G2: 1月 | H2: 2月 | I2: 3月 | J2: 4月 | K2: 5月 | L2: 6月 | M2: 7月 | N2: 8月 | O2: 9月 | P2: 10月 | Q2: 11月 | R2: 12月 | S2: 25年 | T2: 26年 | U2: 1月 | V2: 2月 | W2: 3月 | X2: 4月 | Y2: 5月 | Z2: 6月 | AA2: 7月 | AB2: 8月 | AC2: 9月 | AD2: 10月 | AE2: 11月 | AF2: 12月 | AG2: 25年 | AH2: 26年 | AI2: 1月 | AJ2: 2月 | AK2: 3月 | AL2: 4月 | AM2: 5月 | AN2: 6月 | AO2: 7月 | AP2: 8月 | AQ2: 9月 | AR2: 10月 | AS2: 11月 | AT2: 12月
C3: 整体
C4: 虾蟹线
C5: 海特线
C6: 普鱼线
C7: 畜禽线
C8: 反刍线

Sheet 基础档案
A1: ← 返回目录 | C1: 返回目录 | E1: 销售费用 | H1: 研发费用 | I1: 还原 | K1: 大区 | L1: 序号 | M1: 子公司 | N1: 财务对接人 | O1: 性质 | P1: 客户性质 | Q1: 产品大类 | S1: 华东区 | T1: 华南区 | U1: 华中区 | V1: 其他区 | X1: 月份 | AA1: 客户性质 | AB1: 客户类别 | AC1: 主营料种 | AD1: 产线
A2: 科目名称 | E2: 科目 | F2: 科目说明 | H2: 科目名称 | I2: 费用类别 | J2: 明细类别 | K2: 华南区 | L2: 1 | M2: 福建 | N2: 毕昌 | O2: 基地公司 | P2: 老客户 | Q2: 虾料 | R2: 目录!A1 | S2: 福建 | T2: 江门生物 | U2: 武汉 | V2: 原本 | X2: 1 | Y2: 1 | AA2: 新客户 | AB2: 经销商 | AC2: 虾料 | AD2: 虾蟹线
B3: 分类 | C3: 分解科目 | H3: 530104\研发支出\租赁费 | I3: 管理费用 | J3: 折旧费 | K3: 华东区 | L3: 2 | M3: 浙江 | N3: 高海菊 | O3: 基地公司 | P3: 新客户 | Q3: 蟹料 | S3: 浙江 | T3: 四会 | U3: 汉南 | V3: 越南 | X3: 2 | Y3: 2 | AA3: 老客户 | AB3: 直销户 | AC3: 龙虾料 | AD3: 海特线
A4: 销售吨数 | E4: 变动成本 | H4: 53010201\研发支出\人员人工\工资 | I4: 管理费用 | J4: 人工薪酬（工资、五险一金） | K4: 华中区 | L4: 3 | M4: 唐山 | N4: 梁文雅 | O4: 基地公司 | Q4: 普通膨化鱼料 | S4: 唐山 | T4: 玉林 | U4: 荆州 | V4: 澳保 | X4: 3 | Y4: 3 | AB4: 代工客户 | AC4: 蟹料 | AD4: 普鱼线
A5: 销售标准吨数 | E5: 提成奖励 | H5: 53010202\研发支出\人员人工\绩效工资 | I5: 管理费用 | J5: 人工薪酬（工资、五险一金） | K5: 其他区 | L5: 4 | M5: 惠州 | N5: 王虎伟 | O5: 基地公司 | Q5: 沉水鱼料 | S5: 惠州 | T5: 广西 | U5: 江西 | V5: 伟凝 | X5: 4 | Y5: 4 | AC5: 海特料 | AD5: 畜禽线
A6: 销售人数 | E6: 年终提成 | H6: 530124\研发支出\水电物业费 | I6: 制造费用 | J6: 能耗 | L6: 5 | M6: 淮安 | N6: 曹杰 | O6: 基地公司 | Q6: 高档膨化鱼料 | S6: 澳源 | T6: 贵州 | U6: 池州 | V6: 总部 | X6: 5 | Y6: 5 | AC6: 普通膨化鱼料
A7: 工资和薪金 | B7: 固定 | C7: 人力费用（固定工资、五险一金、职工福利） | E7: 成长分享 | H7: 53010204\研发支出\人员人工\公积金 | I7: 管理费用 | J7: 人工薪酬（工资、五险一金） | L7: 6 | M7: 泰州 | N7: 豆业晶 | O7: 基地公司 | Q7: 浓缩/预混料 | S7: 淮安 | T7: 海南 | U7: 洛阳水产 | X7: 6 | Y7: 6 | AC7: 沉水鱼料
A8: 提成奖励 | B8: 变动 | C8: 提成奖励 | E8: 运输费 | H8: 5301020501\研发支出\人员人工\社保\养老保险 | I8: 管理费用 | J8: 人工薪酬（工资、五险一金） | L8: 7 | M8: 南京 | N8: 郭良 | O8: 基地公司 | Q8: 猪饲料 | S8: 泰州 | T8: 大粤西 | U8: 洛阳陕西 | X8: 7 | Y8: 7 | AC8: 猪饲料
A9: 年终提成 | B9: 变动 | C9: 年终提成 | E9: 技术服务费 | H9: 5301020502\研发支出\人员人工\社保\医疗保险 | I9: 管理费用 | J9: 人工薪酬（工资、五险一金） | L9: 8 | M9: 江门生物 | N9: 邓洪才 | O9: 基地公司 | Q9: 禽料 | S9: 南京 | T9: 湛江 | U9: 洛阳畜禽 | X9: 8 | Y9: 8 | AC9: 禽料
A10: 成长分享 | B10: 变动 | C10: 成长分享 | E10: 固定成本 | H10: 5301020503\研发支出\人员人工\社保\工伤保险 | I10: 管理费用 | J10: 人工薪酬（工资、五险一金） | L10: 9 | M10: 四会 | N10: 张裕华 | O10: 基地公司 | Q10: 反刍料 | S10: 江苏 | T10: 四川 | U10: 湖南 | X10: 9 | Y10: 9 | AC10: 反刍料
A11: 劳务费 | B11: 固定 | C11: 人力费用（固定工资、五险一金、职工福利） | E11: 人力费用（固定工资、五险一金、职工福利） | H11: 5301020504\研发支出\人员人工\社保\失业保险 | I11: 管理费用 | J11: 人工薪酬（工资、五险一金） | L11: 10 | M11: 广西 | N11: 龙玉杰 | O11: 基地公司 | T11: 云南 | U11: 湖南澳源 | X11: 10 | Y11: 10 | AC11: 浓缩预混料
A12: 社保费 | B12: 固定 | C12: 人力费用（固定工资、五险一金、职工福利） | E12: 差旅费 | H12: 5301020505\研发支出\人员人工\社保\生育医疗 | I12: 管理费用 | J12: 人工薪酬（工资、五险一金） | L12: 11 | M12: 云南 | N12: 李小婷 | O12: 销售公司 | U12: 岳阳 | X12: 11 | Y12: 11 | AC12: 动保
A13: 住房公积金 | B13: 固定 | C13: 人力费用（固定工资、五险一金、职工福利） | E13: 车辆使用费 | H13: 530125\研发支出\成长分享 | I13: 管理费用 | J13: 成长分享 | L13: 12 | M13: 贵州 | N13: 蒙鸿娟 | O13: 销售公司 | U13: 益阳 | X13: 12 | Y13: 12
A14: 职工福利金 | B14: 固定 | C14: 人力费用（固定工资、五险一金、职工福利） | E14: 应酬费 | H14: 530103\研发支出\折旧费 | I14: 制造费用 | J14: 折旧费 | L14: 13 | M14: 四川 | N14: 石玉琴 | O14: 销售公司 | U14: 衡阳 | X14: 全年 | Y14: 13
A15: 差旅补助 | B15: 固定 | C15: 差旅费 | E15: 推广、会务 | H15: 530101\研发支出\直接材料及燃动力 | I15: 管理费用 | J15: 办公费用 | L15: 14 | M15: 湛江 | N15: 曾君 | O15: 基地公司
A16: 差旅费 | B16: 固定 | C16: 差旅费 | E16: 固定资产折旧费 | H16: 530111\研发支出\车辆使用费 | I16: 管理费用 | J16: 办公费用 | L16: 15 | M16: 海南 | N16: 何栩童 | O16: 事业部
A17: 车辆使用费 | B17: 固定 | C17: 人力费用（固定工资、五险一金、职工福利） | E17: 诉讼费 | H17: 53010203\研发支出\人员人工\奖金 | I17: 管理费用 | J17: 人工薪酬（工资、五险一金） | L17: 16 | M17: 武汉 | N17: 蒋晓玲 | O17: 基地公司
A18: 应酬费 | B18: 固定 | C18: 应酬费 | H18: 530122\研发支出\办公费 | I18: 管理费用 | J18: 办公费用 | L18: 17 | M18: 汉南 | N18: 余俊 | O18: 基地公司
A19: 销售推广费 | B19: 固定 | C19: 推广、会务 | H19: 530109\研发支出\技术服务费 | I19: 管理费用 | J19: 办公费用 | L19: 18 | M19: 荆州 | N19: 孙子明 | O19: 销售公司
A20: 会务费 | B20: 固定 | C20: 推广、会务 | E20: 管理费用 | H20: 530108\研发支出\差旅费 | I20: 管理费用 | J20: 人工薪酬（工资、五险一金） | L20: 19 | M20: 江西 | N20: 卞淑芬 | O20: 基地公司
A21: 运输费 | B21: 变动 | C21: 运输费 | E21: 科目 | H21: 530121\研发支出\业务招待费 | I21: 管理费用 | J21: 应酬费 | L21: 20 | M21: 洛阳水产 | N21: 韩玉可 | O21: 事业部
A22: 中转仓储费 | B22: 固定 | C22: 固定资产折旧费 | H22: 530119\研发支出\职工福利费 | I22: 管理费用 | J22: 人工薪酬（工资、五险一金） | L22: 22 | M22: 洛阳畜禽 | N22: 韩玉可 | O22: 基地公司
A23: 诉讼费 | B23: 固定 | C23: 诉讼费 | E23: 变动费用 | H23: 530123\研发支出\维护费 | I23: 制造费用 | J23: 维修费 | L23: 23 | M23: 湖南 | N23: 郭佳 | O23: 基地公司
A24: 其他 | B24: 固定 | C24: 固定资产折旧费 | E24: 成长分享 | H24: 530116\研发支出\外聘劳务费 | I24: 管理费用 | J24: 人工薪酬（工资、五险一金） | L24: 24 | M24: 益阳 | N24: 罗燕红 | O24: 销售公司
A25: 运输费（对内） | B25: 变动 | C25: 运输费 | E25: 股份支付 | H25: 530117\研发支出\购置费及检验费 | I25: 制造费用 | J25: 维修费 | L25: 26 | M25: 越南 | N25: 肖阿林 | O25: 基地公司
A26: 办公费 | B26: 固定 | C26: 推广、会务 | E26: 固定费用 | H26: 530112\研发支出\会务费 | I26: 管理费用 | J26: 会务费 | L26: 27 | M26: 澳保 | N26: 路鑫 | O26: 基地公司
A27: 技术服务费 | B27: 变动 | C27: 技术服务费 | E27: 人工薪酬（工资、五险一金） | H27: 530126\研发支出\运输费 | I27: 管理费用 | J27: 办公费用 | L27: 28 | M27: 伟凝 | N27: 陈小冰 | O27: 销售公司
A28: 使用权资产折旧费 | B28: 固定 | C28: 固定资产折旧费 | E28: 应酬费 | H28: 530120\研发支出\使用权资产折旧费 | I28: 管理费用 | J28: 折旧费 | L28: 29 | M28: 总部 | N28: 陈晓佳 | O28: 总部
A29: 固定资产折旧费 | B29: 固定 | C29: 固定资产折旧费 | E29: 办公费用 | H29: 530113\研发支出\知识产权费 | I29: 管理费用 | J29: 折旧费
A30: 无形资产摊销费 | B30: 固定 | C30: 固定资产折旧费 | E30: 培训招聘费 | H30: 530115\研发支出\长期待摊费用摊销 | I30: 管理费用 | J30: 折旧费
A31: 长期待摊费用摊销 | B31: 固定 | C31: 固定资产折旧费 | E31: 水电费 | H31: 530118\研发支出\设计制定费及试验费 | I31: 制造费用 | J31: 维修费

Sheet 物料档案
A1: ← 返回目录
A2: 所属公司 | B2: 启用状态 | C2: 物料编码 | D2: 物料名称 | E2: 物料编码 | F2: 大类 | G2: 小类 | H2: 5+2分类 | I2: 助记码 | J2: 产品系列
A3: 湖南澳华农牧科技有限公司 | B3: 已启用 | C3: 2201020561 | D3: 花鲢1号Φ1.0 | E3: 2201020561 | F3: 普通膨化鱼料 | G3: 鳙鱼料 | I3: WUH1-HL1-1.0 | J3: 花鲢1号 | K3: Φ | N3: 大类 | O3: 产线
A4: 湖南澳华农牧科技有限公司 | B4: 已启用 | C4: 2201020564 | D4: 贵妃宝Φ5.0 | E4: 2201020564 | F4: 普通膨化鱼料 | G4: 草鱼料 | H4: 鱼安康系列-草鱼安康 | I4: WUH1-GFB-5.0 | J4: 贵妃宝 | N4: 龙虾料 | O4: 虾蟹线
A5: 湖南澳华农牧科技有限公司 | B5: 已启用 | C5: 2201020566 | D5: 草鱼安康Φ2.0 | E5: 2201020566 | F5: 普通膨化鱼料 | G5: 草鱼料 | H5: 鱼安康系列-草鱼安康 | I5: WUH1-CYAK-2.0 | J5: 草鱼安康 | N5: 虾料 | O5: 虾蟹线
A6: 湖南澳华农牧科技有限公司 | B6: 已启用 | C6: 2201020567 | D6: 草鱼安康Φ3.0 | E6: 2201020567 | F6: 普通膨化鱼料 | G6: 草鱼料 | H6: 鱼安康系列-草鱼安康 | I6: WUH1-CYAK-3.0 | J6: 草鱼安康 | N6: 蟹料 | O6: 虾蟹线
A7: 湖南澳华农牧科技有限公司 | B7: 已启用 | C7: 2201020569 | D7: 淡水鱼1号料Φ2.0 | E7: 2201020569 | F7: 普通膨化鱼料 | G7: 草鱼料 | I7: WUH1-DSY1-2.0 | J7: 淡水鱼1号料 | N7: 海特料 | O7: 海特线
A8: 湖南澳华农牧科技有限公司 | B8: 已启用 | C8: 2201020570 | D8: 淡水鱼1号料Φ3.0 | E8: 2201020570 | F8: 普通膨化鱼料 | G8: 草鱼料 | I8: WUH1-DSY1-3.0 | J8: 淡水鱼1号料 | N8: 沉水鱼料 | O8: 鱼料线
A9: 湖南澳华农牧科技有限公司 | B9: 已停用 | C9: 2201020571 | D9: 淡水鱼1号料Φ5.0 | E9: 2201020571 | F9: 普通膨化鱼料 | G9: 草鱼料 | I9: WUH1-DSY1-5.0 | J9: 淡水鱼1号料 | N9: 普通膨化鱼料 | O9: 鱼料线
A10: 湖南澳华农牧科技有限公司 | B10: 已停用 | C10: 2201020576 | D10: 冬藏宝Φ3.0 | E10: 2201020576 | F10: 普通膨化鱼料 | G10: 四季料 | I10: WUH1-DSDCB-3.0 | J10: 冬藏宝 | N10: 反刍料 | O10: 畜禽线
A11: 湖南澳华农牧科技有限公司 | B11: 已启用 | C11: 2201020582 | D11: 混养2号Φ3.0 | E11: 2201020582 | F11: 普通膨化鱼料 | G11: 草鱼料 | I11: WUH1-HY2-3.0 | J11: 混养2号 | N11: 浓缩/预混料 | O11: 畜禽线
A12: 湖南澳华农牧科技有限公司 | B12: 已启用 | C12: 2201020316 | D12: 驯化宝Φ2.0 | E12: 2201020316 | F12: 普通膨化鱼料 | G12: 四季料 | H12: 无 | I12: HUN1-XHB-2.0 | J12: 驯化宝 | N12: 禽料 | O12: 畜禽线
A13: 湖南澳华农牧科技有限公司 | B13: 已启用 | C13: 2201020317 | D13: 驯化宝Φ3.0 | E13: 2201020317 | F13: 普通膨化鱼料 | G13: 四季料 | H13: 无 | I13: HUN1-XHB-3.0 | J13: 驯化宝 | N13: 猪饲料 | O13: 畜禽线
A14: 湖南澳华农牧科技有限公司 | B14: 已启用 | C14: 2201020322 | D14: 冬藏宝Φ3.0 | E14: 2201020322 | F14: 普通膨化鱼料 | G14: 四季料 | H14: 无 | I14: HUN1-DCB-3.0 | J14: 冬藏宝
A15: 湖南澳华农牧科技有限公司 | B15: 已启用 | C15: 2201020327 | D15: 膨化混养1号Φ3.0 | E15: 2201020327 | F15: 普通膨化鱼料 | G15: 草鱼料 | H15: 无 | I15: HUN1-PHHY1-3.0 | J15: 膨化混养1号
A16: 湖南澳华农牧科技有限公司 | B16: 已启用 | C16: 2201050001 | D16: 叉尾鮰2号Φ2.0 | E16: 2201050001 | F16: 普通膨化鱼料 | G16: 叉尾鮰料 | I16: ZJ1-CWH2-2.0 | J16: 叉尾鮰2号
A17: 湖南澳华农牧科技有限公司 | B17: 已启用 | C17: 2201050002 | D17: 叉尾鮰2号Φ3.0 | E17: 2201050002 | F17: 普通膨化鱼料 | G17: 叉尾鮰料 | I17: ZJ1-CWH2-3.0 | J17: 叉尾鮰2号
A18: 湖南澳华农牧科技有限公司 | B18: 已启用 | C18: 2201050008 | D18: 特种鱼苗料Φ1.0 | E18: 2201050008 | F18: 高档膨化鱼料 | G18: 鱼苗料 | I18: WUH1-TZYML-1.0 | J18: 特种鱼苗料
A19: 湖南澳华农牧科技有限公司 | B19: 已启用 | C19: 2201050009 | D19: 翘嘴安康Φ2.0 | E19: 2201050009 | F19: 高档膨化鱼料 | G19: 翘嘴料 | H19: 海特料-翘嘴安康 | I19: WUH1-QZAK-2.0 | J19: 翘嘴安康
A20: 湖南澳华农牧科技有限公司 | B20: 已启用 | C20: 2201050010 | D20: 翘嘴安康Φ3.0 | E20: 2201050010 | F20: 高档膨化鱼料 | G20: 翘嘴料 | H20: 海特料-翘嘴安康 | I20: WUH1-QZAK-3.0 | J20: 翘嘴安康
A21: 湖南澳华农牧科技有限公司 | B21: 已启用 | C21: 2201050011 | D21: 翘嘴安康Φ5.0 | E21: 2201050011 | F21: 高档膨化鱼料 | G21: 翘嘴料 | H21: 海特料-翘嘴安康 | I21: WUH1-QZAK-5.0 | J21: 翘嘴安康
A22: 湖南澳华农牧科技有限公司 | B22: 已启用 | C22: 2201050012 | D22: 鲌鱼2号Φ2.0 | E22: 2201050012 | F22: 高档膨化鱼料 | G22: 翘嘴料 | I22: WUH1-BY2H-2.0 | J22: 鲌鱼2号
A23: 湖南澳华农牧科技有限公司 | B23: 已启用 | C23: 2201050013 | D23: 鲌鱼2号Φ3.0 | E23: 2201050013 | F23: 高档膨化鱼料 | G23: 翘嘴料 | I23: WUH1-BY2H-3.0 | J23: 鲌鱼2号
A24: 湖南澳华农牧科技有限公司 | B24: 已启用 | C24: 2201050014 | D24: 鲌鱼2号Φ5.0 | E24: 2201050014 | F24: 高档膨化鱼料 | G24: 翘嘴料 | I24: WUH1-BY2H-5.0 | J24: 鲌鱼2号
A25: 湖南澳华农牧科技有限公司 | B25: 已停用 | C25: 2201020584 | D25: 渔家旺Φ2.0 | E25: 2201020584 | F25: 普通膨化鱼料 | G25: 草鱼料 | I25: WUH1-YJW-2.0 | J25: 渔家旺
A26: 湖南澳华农牧科技有限公司 | B26: 已启用 | C26: 2201020585 | D26: 渔家旺Φ3.0 | E26: 2201020585 | F26: 普通膨化鱼料 | G26: 草鱼料 | I26: WUH1-YJW-3.0 | J26: 渔家旺
A27: 湖南澳华农牧科技有限公司 | B27: 已停用 | C27: 2201020587 | D27: 驯化宝Φ2.0 | E27: 2201020587 | F27: 普通膨化鱼料 | G27: 四季料 | I27: WUH1-XHB-2.0 | J27: 驯化宝
A28: 湖南澳华农牧科技有限公司 | B28: 已停用 | C28: 2201020588 | D28: 驯化宝Φ3.0 | E28: 2201020588 | F28: 普通膨化鱼料 | G28: 四季料 | I28: WUH1-XHB-3.0 | J28: 驯化宝
A29: 湖南澳华农牧科技有限公司 | B29: 已停用 | C29: 2201020596 | D29: 淡水肝肠安康Ⅱ型Φ2.0 | E29: 2201020596 | F29: 普通膨化鱼料 | G29: 功能料 | H29: 功能料系列-肝肠安康 | I29: WUH1-DSGCAKⅡ-2.0 | J29: 淡水肝肠安康Ⅱ型
A30: 湖南澳华农牧科技有限公司 | B30: 已启用 | C30: 2201020698 | D30: 贵妃宝Φ3.0 | E30: 2201020698 | F30: 普通膨化鱼料 | G30: 草鱼料 | H30: 鱼安康系列-草鱼安康 | I30: WUH1-GFB-3.0 | J30: 贵妃宝
A31: 湖南澳华农牧科技有限公司 | B31: 已启用 | C31: 2201020722 | D31: 贵妃宝Φ2.0 | E31: 2201020722 | F31: 普通膨化鱼料 | G31: 草鱼料 | H31: 无 | I31: WUH1-GFB-2.0 | J31: 贵妃宝
A32: 湖南澳华农牧科技有限公司 | B32: 已启用 | C32: 2201100091 | D32: 叉尾鮰3号Φ2.0 | E32: 2201100091 | F32: 普通膨化鱼料 | G32: 叉尾鮰料 | I32: WUH1-CWH3-2.0 | J32: 叉尾鮰3号
A33: 湖南澳华农牧科技有限公司 | B33: 已启用 | C33: 2201100092 | D33: 叉尾鮰3号Φ3.0 | E33: 2201100092 | F33: 普通膨化鱼料 | G33: 叉尾鮰料 | I33: WUH1-CWH3-3.0 | J33: 叉尾鮰3号
A34: 湖南澳华农牧科技有限公司 | B34: 已启用 | C34: 2201100093 | D34: 叉尾鮰3号Φ5.0 | E34: 2201100093 | F34: 普通膨化鱼料 | G34: 叉尾鮰料 | I34: WUH1-CWH3-5.0 | J34: 叉尾鮰3号
A35: 湖南澳华农牧科技有限公司 | B35: 已启用 | C35: 2201100097 | D35: 叉尾安康Φ2.0 | E35: 2201100097 | F35: 普通膨化鱼料 | G35: 叉尾鮰料 | H35: 鱼安康系列-叉尾安康 | I35: WUH1-CWAK-2.0 | J35: 叉尾安康
A36: 湖南澳华农牧科技有限公司 | B36: 已启用 | C36: 2201100098 | D36: 叉尾安康Φ3.0 | E36: 2201100098 | F36: 普通膨化鱼料 | G36: 叉尾鮰料 | H36: 鱼安康系列-叉尾安康 | I36: WUH1-CWAK-3.0 | J36: 叉尾安康
A37: 湖南澳华农牧科技有限公司 | B37: 已启用 | C37: 2201100099 | D37: 叉尾安康Φ5.0 | E37: 2201100099 | F37: 普通膨化鱼料 | G37: 叉尾鮰料 | H37: 鱼安康系列-叉尾安康 | I37: WUH1-CWAK-5.0 | J37: 叉尾安康
A38: 湖南澳华农牧科技有限公司 | B38: 已启用 | C38: 2202010176 | D38: 青蛙1号AΦ1.5 | E38: 2202010176 | F38: 高档膨化鱼料 | G38: 蛙料 | H38: 无 | I38: WUH1-QW1A-1.5 | J38: 青蛙1号A
A39: 湖南澳华农牧科技有限公司 | B39: 已启用 | C39: 2202010179 | D39: 蛙粉A料Φ粉 | E39: 2202010179 | F39: 高档膨化鱼料 | G39: 蛙料 | H39: 无 | I39: WUH18-WFA-F | J39: 蛙粉A料
A40: 湖南澳华农牧科技有限公司 | B40: 已启用 | C40: 2202010183 | D40: 青蛙1号Φ1.5 | E40: 2202010183 | F40: 高档膨化鱼料 | G40: 蛙料 | H40: 无 | I40: WUH18-QW1-1.5 | J40: 青蛙1号
...

Sheet A5 表样-聚焦镇量利（查阅）
A1: ← 返回目录
A2: 大区 | B2: 公司 | C2: 聚焦镇名称 | D2: 聚焦镇类型 | E2: 销量 | U2: 毛利额
E3: 2025年销量 | F3: 2026年销量 | G3: 同比增加额 | H3: 同比增长率 | I3: 2026年月度销量 | U3: 2025年毛利额 | V3: 2026年毛利额 | W3: 同比增加额 | X3: 同比增长率 | Y3: 2026年月度毛利额
I4: 1月 | J4: 2月 | K4: 3月 | L4: 4月 | M4: 5月 | N4: 6月 | O4: 7月 | P4: 8月 | Q4: 9月 | R4: 10月 | S4: 11月 | T4: 12月 | Y4: 1月 | Z4: 2月 | AA4: 3月 | AB4: 4月 | AC4: 5月 | AD4: 6月 | AE4: 7月 | AF4: 8月 | AG4: 9月 | AH4: 10月 | AI4: 11月 | AJ4: 12月
A5: ='[3]A1 预算指标总览'!$A$3 -> 华东一区 | B5: ='[3]A1 预算指标总览'!$B$3 -> 福建公司 | E5: 本表计算 | F5: 计算 | G5: 本表计算 | H5: 本表计算 | I5: 计算 | J5: 计算 | K5: 计算 | L5: 计算 | M5: 计算 | N5: 计算 | O5: 计算 | P5: 计算 | Q5: 计算 | R5: 计算 | S5: 计算 | T5: 计算 | U5: 本表计算 | V5: 计算 | W5: 本表计算 | X5: 本表计算 | Y5: 计算 | Z5: 计算 | AA5: 计算 | AB5: 计算 | AC5: 计算 | AD5: 计算 | AE5: 计算 | AF5: 计算 | AG5: 计算 | AH5: 计算 | AI5: 计算 | AJ5: 计算
A6: ='[3]A1 预算指标总览'!$A$3 -> 华东一区 | B6: ='[3]A1 预算指标总览'!$B$3 -> 福建公司 | E6: 本表计算 | F6: 计算 | G6: 本表计算 | H6: 本表计算 | I6: 计算 | J6: 计算 | K6: 计算 | L6: 计算 | M6: 计算 | N6: 计算 | O6: 计算 | P6: 计算 | Q6: 计算 | R6: 计算 | S6: 计算 | T6: 计算 | U6: 本表计算 | V6: 计算 | W6: 本表计算 | X6: 本表计算 | Y6: 计算 | Z6: 计算 | AA6: 计算 | AB6: 计算 | AC6: 计算 | AD6: 计算 | AE6: 计算 | AF6: 计算 | AG6: 计算 | AH6: 计算 | AI6: 计算 | AJ6: 计算
A7: ='[3]A1 预算指标总览'!$A$3 -> 华东一区 | B7: ='[3]A1 预算指标总览'!$B$3 -> 福建公司 | E7: 本表计算 | F7: 计算 | G7: 本表计算 | H7: 本表计算 | I7: 计算 | J7: 计算 | K7: 计算 | L7: 计算 | M7: 计算 | N7: 计算 | O7: 计算 | P7: 计算 | Q7: 计算 | R7: 计算 | S7: 计算 | T7: 计算 | U7: 本表计算 | V7: 计算 | W7: 本表计算 | X7: 本表计算 | Y7: 计算 | Z7: 计算 | AA7: 计算 | AB7: 计算 | AC7: 计算 | AD7: 计算 | AE7: 计算 | AF7: 计算 | AG7: 计算 | AH7: 计算 | AI7: 计算 | AJ7: 计算
A8: ='[3]A1 预算指标总览'!$A$3 -> 华东一区 | B8: ='[3]A1 预算指标总览'!$B$3 -> 福建公司 | E8: 本表计算 | F8: 计算 | G8: 本表计算 | H8: 本表计算 | I8: 计算 | J8: 计算 | K8: 计算 | L8: 计算 | M8: 计算 | N8: 计算 | O8: 计算 | P8: 计算 | Q8: 计算 | R8: 计算 | S8: 计算 | T8: 计算 | U8: 本表计算 | V8: 计算 | W8: 本表计算 | X8: 本表计算 | Y8: 计算 | Z8: 计算 | AA8: 计算 | AB8: 计算 | AC8: 计算 | AD8: 计算 | AE8: 计算 | AF8: 计算 | AG8: 计算 | AH8: 计算 | AI8: 计算 | AJ8: 计算
A9: ='[3]A1 预算指标总览'!$A$3 -> 华东一区 | B9: ='[3]A1 预算指标总览'!$B$3 -> 福建公司 | E9: 本表计算 | F9: 计算 | G9: 本表计算 | H9: 本表计算 | I9: 计算 | J9: 计算 | K9: 计算 | L9: 计算 | M9: 计算 | N9: 计算 | O9: 计算 | P9: 计算 | Q9: 计算 | R9: 计算 | S9: 计算 | T9: 计算 | U9: 本表计算 | V9: 计算 | W9: 本表计算 | X9: 本表计算 | Y9: 计算 | Z9: 计算 | AA9: 计算 | AB9: 计算 | AC9: 计算 | AD9: 计算 | AE9: 计算 | AF9: 计算 | AG9: 计算 | AH9: 计算 | AI9: 计算 | AJ9: 计算
A10: ='[3]A1 预算指标总览'!$A$3 -> 华东一区 | B10: ='[3]A1 预算指标总览'!$B$3 -> 福建公司 | E10: 本表计算 | F10: 计算 | G10: 本表计算 | H10: 本表计算 | I10: 计算 | J10: 计算 | K10: 计算 | L10: 计算 | M10: 计算 | N10: 计算 | O10: 计算 | P10: 计算 | Q10: 计算 | R10: 计算 | S10: 计算 | T10: 计算 | U10: 本表计算 | V10: 计算 | W10: 本表计算 | X10: 本表计算 | Y10: 计算 | Z10: 计算 | AA10: 计算 | AB10: 计算 | AC10: 计算 | AD10: 计算 | AE10: 计算 | AF10: 计算 | AG10: 计算 | AH10: 计算 | AI10: 计算 | AJ10: 计算
A11: ='[3]A1 预算指标总览'!$A$3 -> 华东一区 | B11: ='[3]A1 预算指标总览'!$B$3 -> 福建公司 | E11: 本表计算 | F11: 计算 | G11: 本表计算 | H11: 本表计算 | I11: 计算 | J11: 计算 | K11: 计算 | L11: 计算 | M11: 计算 | N11: 计算 | O11: 计算 | P11: 计算 | Q11: 计算 | R11: 计算 | S11: 计算 | T11: 计算 | U11: 本表计算 | V11: 计算 | W11: 本表计算 | X11: 本表计算 | Y11: 计算 | Z11: 计算 | AA11: 计算 | AB11: 计算 | AC11: 计算 | AD11: 计算 | AE11: 计算 | AF11: 计算 | AG11: 计算 | AH11: 计算 | AI11: 计算 | AJ11: 计算
A12: ='[3]A1 预算指标总览'!$A$3 -> 华东一区 | B12: ='[3]A1 预算指标总览'!$B$3 -> 福建公司 | E12: 本表计算 | F12: 计算 | G12: 本表计算 | H12: 本表计算 | I12: 计算 | J12: 计算 | K12: 计算 | L12: 计算 | M12: 计算 | N12: 计算 | O12: 计算 | P12: 计算 | Q12: 计算 | R12: 计算 | S12: 计算 | T12: 计算 | U12: 本表计算 | V12: 计算 | W12: 本表计算 | X12: 本表计算 | Y12: 计算 | Z12: 计算 | AA12: 计算 | AB12: 计算 | AC12: 计算 | AD12: 计算 | AE12: 计算 | AF12: 计算 | AG12: 计算 | AH12: 计算 | AI12: 计算 | AJ12: 计算
A13: ='[3]A1 预算指标总览'!$A$3 -> 华东一区 | B13: ='[3]A1 预算指标总览'!$B$3 -> 福建公司 | E13: 本表计算 | F13: 计算 | G13: 本表计算 | H13: 本表计算 | I13: 计算 | J13: 计算 | K13: 计算 | L13: 计算 | M13: 计算 | N13: 计算 | O13: 计算 | P13: 计算 | Q13: 计算 | R13: 计算 | S13: 计算 | T13: 计算 | U13: 本表计算 | V13: 计算 | W13: 本表计算 | X13: 本表计算 | Y13: 计算 | Z13: 计算 | AA13: 计算 | AB13: 计算 | AC13: 计算 | AD13: 计算 | AE13: 计算 | AF13: 计算 | AG13: 计算 | AH13: 计算 | AI13: 计算 | AJ13: 计算
A14: ='[3]A1 预算指标总览'!$A$3 -> 华东一区 | B14: ='[3]A1 预算指标总览'!$B$3 -> 福建公司 | E14: 本表计算 | F14: 计算 | G14: 本表计算 | H14: 本表计算 | I14: 计算 | J14: 计算 | K14: 计算 | L14: 计算 | M14: 计算 | N14: 计算 | O14: 计算 | P14: 计算 | Q14: 计算 | R14: 计算 | S14: 计算 | T14: 计算 | U14: 本表计算 | V14: 计算 | W14: 本表计算 | X14: 本表计算 | Y14: 计算 | Z14: 计算 | AA14: 计算 | AB14: 计算 | AC14: 计算 | AD14: 计算 | AE14: 计算 | AF14: 计算 | AG14: 计算 | AH14: 计算 | AI14: 计算 | AJ14: 计算
A15: ='[3]A1 预算指标总览'!$A$3 -> 华东一区 | B15: ='[3]A1 预算指标总览'!$B$3 -> 福建公司 | E15: 本表计算 | F15: 计算 | G15: 本表计算 | H15: 本表计算 | I15: 计算 | J15: 计算 | K15: 计算 | L15: 计算 | M15: 计算 | N15: 计算 | O15: 计算 | P15: 计算 | Q15: 计算 | R15: 计算 | S15: 计算 | T15: 计算 | U15: 本表计算 | V15: 计算 | W15: 本表计算 | X15: 本表计算 | Y15: 计算 | Z15: 计算 | AA15: 计算 | AB15: 计算 | AC15: 计算 | AD15: 计算 | AE15: 计算 | AF15: 计算 | AG15: 计算 | AH15: 计算 | AI15: 计算 | AJ15: 计算
A16: ='[3]A1 预算指标总览'!$A$3 -> 华东一区 | B16: ='[3]A1 预算指标总览'!$B$3 -> 福建公司 | E16: 本表计算 | F16: 计算 | G16: 本表计算 | H16: 本表计算 | I16: 计算 | J16: 计算 | K16: 计算 | L16: 计算 | M16: 计算 | N16: 计算 | O16: 计算 | P16: 计算 | Q16: 计算 | R16: 计算 | S16: 计算 | T16: 计算 | U16: 本表计算 | V16: 计算 | W16: 本表计算 | X16: 本表计算 | Y16: 计算 | Z16: 计算 | AA16: 计算 | AB16: 计算 | AC16: 计算 | AD16: 计算 | AE16: 计算 | AF16: 计算 | AG16: 计算 | AH16: 计算 | AI16: 计算 | AJ16: 计算
... A34: ='[3]A1 预算指标总览'!$A$3 -> 华东一区 | B34: ='[3]A1 预算指标总览'!$B$3 -> 福建公司 | E34: 本表计算 | F34: 计算 | G34: 本表计算 | H34: 本表计算 | I34: 计算 | J34: 计算 | K34: 计算 | L34: 计算 | M34: 计算 | N34: 计算 | O34: 计算 | P34: 计算 | Q34: 计算 | R34: 计算 | S34: 计算 | T34: 计算 | U34: 本表计算 | V34: 计算 | W34: 本表计算 | X34: 本表计算 | Y34: 计算 | Z34: 计算 | AA34: 计算 | AB34: 计算 | AC34: 计算 | AD34: 计算 | AE34: 计算 | AF34: 计算 | AG34: 计算 | AH34: 计算 | AI34: 计算 | AJ34: 计算
A35: ='[3]A1 预算指标总览'!$A$3 -> 华东一区 | B35: ='[3]A1 预算指标总览'!$B$3 -> 福建公司 | C35: 合计 | E35: 本表计算 | F35: 本表计算 | G35: 本表计算 | H35: 本表计算 | I35: 本表计算 | J35: 本表计算 | K35: 本表计算 | L35: 本表计算 | M35: 本表计算 | N35: 本表计算 | O35: 本表计算 | P35: 本表计算 | Q35: 本表计算 | R35: 本表计算 | S35: 本表计算 | T35: 本表计算 | U35: 本表计算 | V35: 本表计算 | W35: 本表计算 | X35: 本表计算 | Y35: 本表计算 | Z35: 本表计算 | AA35: 本表计算 | AB35: 本表计算 | AC35: 本表计算 | AD35: 本表计算 | AE35: 本表计算 | AF35: 本表计算 | AG35: 本表计算 | AH35: 本表计算 | AI35: 本表计算 | AJ35: 本表计算

Sheet A6 表样-大类量利（查阅）
A1: ← 返回目录
A2: 大区 | B2: 公司 | C2: 大类 | D2: 2026年全年预算值 | K2: 2025年实际值 | R2: 同比增长（预算-同比）
D3: 销量 | E3: 主营业务收入 | F3: 毛利额 | G3: 吨毛利 | H3: 毛利率 | I3: 配销差额 | J3: 吨配销差 | K3: 销量 | L3: 主营业务收入 | M3: 毛利额 | N3: 吨毛利 | O3: 毛利率 | P3: 配销差额 | Q3: 吨配销差 | R3: 销量 | S3: 主营业务收入 | T3: 毛利额 | U3: 吨毛利 | V3: 毛利率 | W3: 配销差额 | X3: 吨配销差
C4: 虾料 | D4: 计算 | E4: 计算 | F4: 计算 | G4: 本表计算 | H4: 本表计算 | K4: 计算 | L4: 计算 | M4: 计算 | N4: 本表计算 | O4: 本表计算 | R4: 本表计算 | S4: 本表计算 | T4: 本表计算 | U4: 本表计算 | V4: 本表计算
C5: 龙虾料 | D5: 计算 | E5: 计算 | F5: 计算 | G5: 本表计算 | H5: 本表计算 | K5: 计算 | L5: 计算 | M5: 计算 | N5: 本表计算 | O5: 本表计算 | R5: 本表计算 | S5: 本表计算 | T5: 本表计算 | U5: 本表计算 | V5: 本表计算
C6: 蟹料 | D6: 计算 | E6: 计算 | F6: 计算 | G6: 本表计算 | H6: 本表计算 | K6: 计算 | L6: 计算 | M6: 计算 | N6: 本表计算 | O6: 本表计算 | R6: 本表计算 | S6: 本表计算 | T6: 本表计算 | U6: 本表计算 | V6: 本表计算
C7: 其中：高价值虾蟹 | D7: 计算 | E7: 计算 | F7: 计算 | G7: 本表计算 | H7: 本表计算 | K7: 计算 | L7: 计算 | M7: 计算 | N7: 本表计算 | O7: 本表计算 | R7: 本表计算 | S7: 本表计算 | T7: 本表计算 | U7: 本表计算 | V7: 本表计算
C8: 普通膨化鱼料 | D8: 计算 | E8: 计算 | F8: 计算 | G8: 本表计算 | H8: 本表计算 | K8: 计算 | L8: 计算 | M8: 计算 | N8: 本表计算 | O8: 本表计算 | R8: 本表计算 | S8: 本表计算 | T8: 本表计算 | U8: 本表计算 | V8: 本表计算
C9: 沉水鱼料 | D9: 计算 | E9: 计算 | F9: 计算 | G9: 本表计算 | H9: 本表计算 | K9: 计算 | L9: 计算 | M9: 计算 | N9: 本表计算 | O9: 本表计算 | R9: 本表计算 | S9: 本表计算 | T9: 本表计算 | U9: 本表计算 | V9: 本表计算
C10: 其中：高价值鱼料 | D10: 计算 | E10: 计算 | F10: 计算 | G10: 本表计算 | H10: 本表计算 | K10: 计算 | L10: 计算 | M10: 计算 | N10: 本表计算 | O10: 本表计算 | R10: 本表计算 | S10: 本表计算 | T10: 本表计算 | U10: 本表计算 | V10: 本表计算
C11: 海特料 | D11: 计算 | E11: 计算 | F11: 计算 | G11: 本表计算 | H11: 本表计算 | K11: 计算 | L11: 计算 | M11: 计算 | N11: 本表计算 | O11: 本表计算 | R11: 本表计算 | S11: 本表计算 | T11: 本表计算 | U11: 本表计算 | V11: 本表计算
C12: 其中：高价值产品 | D12: 计算 | E12: 计算 | F12: 计算 | G12: 本表计算 | H12: 本表计算 | K12: 计算 | L12: 计算 | M12: 计算 | N12: 本表计算 | O12: 本表计算 | R12: 本表计算 | S12: 本表计算 | T12: 本表计算 | U12: 本表计算 | V12: 本表计算
C13: 水产小计 | D13: 本表计算 | E13: 本表计算 | F13: 本表计算 | G13: 本表计算 | H13: 本表计算 | K13: 本表计算 | L13: 本表计算 | M13: 本表计算 | N13: 本表计算 | O13: 本表计算 | R13: 本表计算 | S13: 本表计算 | T13: 本表计算 | U13: 本表计算 | V13: 本表计算
C14: 猪饲料 | D14: 计算 | E14: 计算 | F14: 计算 | G14: 本表计算 | H14: 本表计算 | K14: 计算 | L14: 计算 | M14: 计算 | N14: 本表计算 | O14: 本表计算 | R14: 本表计算 | S14: 本表计算 | T14: 本表计算 | U14: 本表计算 | V14: 本表计算
C15: 浓缩/预混料 | D15: 计算 | E15: 计算 | F15: 计算 | G15: 本表计算 | H15: 本表计算 | K15: 计算 | L15: 计算 | M15: 计算 | N15: 本表计算 | O15: 本表计算 | R15: 本表计算 | S15: 本表计算 | T15: 本表计算 | U15: 本表计算 | V15: 本表计算
... C23: 其中：高价值占比 | D23: 本表计算 | E23: 本表计算 | F23: 本表计算 | G23: 本表计算 | H23: 本表计算 | K23: 本表计算 | L23: 本表计算 | M23: 本表计算 | N23: 本表计算 | O23: 本表计算 | R23: 本表计算 | S23: 本表计算 | T23: 本表计算 | U23: 本表计算 | V23: 本表计算

Sheet A7 大类小类量利（查阅）
A1: ← 返回目录
B2: 大区 | C2: 公司 | D2: 大类 | E2: 小类 | F2: 2026年预算 | K2: 2025年实际值 | P2: 同比增长（预测-同比）
F3: 销量 | G3: 毛利额 | H3: 吨毛利 | I3: 配销差额 | J3: 吨配销差 | K3: 销量 | L3: 毛利额 | M3: 吨毛利 | N3: 配销差额 | O3: 吨配销差 | P3: 销量 | Q3: 毛利额 | R3: 吨毛利 | S3: 配销差额 | T3: 吨配销差
D4: 海特料 | E4: 大黄鱼料 | F4: 计算 | G4: 计算 | H4: 本表计算 | K4: 计算 | L4: 计算 | M4: 本表计算 | P4: 本表计算 | Q4: 本表计算 | R4: 本表计算
E5: 石斑鱼料 | F5: 计算 | G5: 计算 | H5: 本表计算 | K5: 计算 | L5: 计算 | M5: 本表计算 | P5: 本表计算 | Q5: 本表计算 | R5: 本表计算
F6: 计算 | G6: 计算 | H6: 本表计算 | K6: 计算 | L6: 计算 | M6: 本表计算 | P6: 本表计算 | Q6: 本表计算 | R6: 本表计算 | U6: =D6&E6
F7: 计算 | G7: 计算 | H7: 本表计算 | K7: 计算 | L7: 计算 | M7: 本表计算 | P7: 本表计算 | Q7: 本表计算 | R7: 本表计算 | U7: =D7&E7
F8: 计算 | G8: 计算 | H8: 本表计算 | K8: 计算 | L8: 计算 | M8: 本表计算 | P8: 本表计算 | Q8: 本表计算 | R8: 本表计算 | U8: =D8&E8
F9: 计算 | G9: 计算 | H9: 本表计算 | K9: 计算 | L9: 计算 | M9: 本表计算 | P9: 本表计算 | Q9: 本表计算 | R9: 本表计算 | U9: =D9&E9
F10: 计算 | G10: 计算 | H10: 本表计算 | K10: 计算 | L10: 计算 | M10: 本表计算 | P10: 本表计算 | Q10: 本表计算 | R10: 本表计算 | U10: =D10&E10
F11: 计算 | G11: 计算 | H11: 本表计算 | K11: 计算 | L11: 计算 | M11: 本表计算 | P11: 本表计算 | Q11: 本表计算 | R11: 本表计算 | U11: =D11&E11
F12: 计算 | G12: 计算 | H12: 本表计算 | K12: 计算 | L12: 计算 | M12: 本表计算 | P12: 本表计算 | Q12: 本表计算 | R12: 本表计算 | U12: =D12&E12
F13: 计算 | G13: 计算 | H13: 本表计算 | K13: 计算 | L13: 计算 | M13: 本表计算 | P13: 本表计算 | Q13: 本表计算 | R13: 本表计算 | U13: =D13&E13
F14: 计算 | G14: 计算 | H14: 本表计算 | K14: 计算 | L14: 计算 | M14: 本表计算 | P14: 本表计算 | Q14: 本表计算 | R14: 本表计算 | U14: =D14&E14
F15: 计算 | G15: 计算 | H15: 本表计算 | K15: 计算 | L15: 计算 | M15: 本表计算 | P15: 本表计算 | Q15: 本表计算 | R15: 本表计算 | U15: =D15&E15
F16: 计算 | G16: 计算 | H16: 本表计算 | K16: 计算 | L16: 计算 | M16: 本表计算 | P16: 本表计算 | Q16: 本表计算 | R16: 本表计算 | U16: =D16&E16
F17: 计算 | G17: 计算 | H17: 本表计算 | K17: 计算 | L17: 计算 | M17: 本表计算 | P17: 本表计算 | Q17: 本表计算 | R17: 本表计算 | U17: =D17&E17
... F19: 计算 | G19: 计算 | H19: 本表计算 | K19: 计算 | L19: 计算 | M19: 本表计算 | P19: 本表计算 | Q19: 本表计算 | R19: 本表计算 | U19: =D19&E19
F20: 计算 | G20: 计算 | H20: 本表计算 | K20: 计算 | L20: 计算 | M20: 本表计算 | P20: 本表计算 | Q20: 本表计算 | R20: 本表计算
F21: 计算 | G21: 计算 | H21: 本表计算 | K21: 计算 | L21: 计算 | M21: 本表计算 | P21: 本表计算 | Q21: 本表计算 | R21: 本表计算
F22: 计算 | G22: 计算 | H22: 本表计算 | K22: 计算 | L22: 计算 | M22: 本表计算 | P22: 本表计算 | Q22: 本表计算 | R22: 本表计算
F23: 计算 | G23: 计算 | H23: 本表计算 | K23: 计算 | L23: 计算 | M23: 本表计算 | P23: 本表计算 | Q23: 本表计算 | R23: 本表计算 | U23: =D23&E23
F24: 计算 | G24: 计算 | H24: 本表计算 | K24: 计算 | L24: 计算 | M24: 本表计算 | P24: 本表计算 | Q24: 本表计算 | R24: 本表计算 | U24: =D24&E24

Sheet 新增-产品系列配销差及吨毛利（查阅）
A1: ← 返回目录 | B1: 大类 | C1: 小类 | D1: 产品系列 | E1: 单吨配销差 | AE1: 单吨毛利
E2: 2026年预算值 | R2: 同比 | AE2: 2026年预算值 | AR2: 同比
E3: 1月 | F3: 2月 | G3: 3月 | H3: 4月 | I3: 5月 | J3: 6月 | K3: 7月 | L3: 8月 | M3: 9月 | N3: 10月 | O3: 11月 | P3: 12月 | Q3: 合计 | R3: 1月 | S3: 2月 | T3: 3月 | U3: 4月 | V3: 5月 | W3: 6月 | X3: 7月 | Y3: 8月 | Z3: 9月 | AA3: 10月 | AB3: 11月 | AC3: 12月 | AD3: 合计 | AE3: 1月 | AF3: 2月 | AG3: 3月 | AH3: 4月 | AI3: 5月 | AJ3: 6月 | AK3: 7月 | AL3: 8月 | AM3: 9月 | AN3: 10月 | AO3: 11月 | AP3: 12月 | AQ3: 合计 | AR3: 1月 | AS3: 2月 | AT3: 3月 | AU3: 4月 | AV3: 5月 | AW3: 6月 | AX3: 7月 | AY3: 8月 | AZ3: 9月 | BA3: 10月 | BB3: 11月 | BC3: 12月 | BD3: 合计
B4: 虾料 | C4: 虾安康 | D4: 铂金版虾安康
D5: 金刚安康
D6: 虾奶粉
D7: 虾安康

Sheet A9-表样-客户产品毛利表（外销）
A1: ← 返回目录 | B1: 任务名称： | C1: 1.1销量预算表_编制
B2: 年份： | C2: 2026 | D2: 月份： | E2: 01,02,03
B3: 版本类型： | C3: 年度
B4: 版本： | C4: v1
B5: 业务单元： | C5: 江门澳华
A7: 版本 | B7: 大区 | C7: 公司 | D7: 区域/聚焦镇 | E7: 客户编码 | F7: 客户 | G7: 是否大客户 | H7: 产品系列编码 | I7: 产品系列名称 | J7: 大类 | K7: 小类 | L7: 战略产品 | M7: 销售吨位 | N7: 赠送吨位 | O7: 单吨售价 | P7: 售价总额 | Q7: 单吨折扣 | R7: 折扣总额 | S7: 单吨净收 | T7: 销售净收入额 | U7: 销售成本 | V7: 单吨销售成本 | W7: 赠送成本 | X7: 单吨配方成本 | Y7: 单吨包装物 | Z7: 单吨燃动 | AA7: 单吨人工 | AB7: 单吨变动制造费用 | AC7: 单吨固定制造费用 | AD7: 单吨制造费用 | AE7: 单吨配销差 | AF7: 配销差总额 | AG7: 单吨边际贡献 | AH7: 总边际贡献 | AI7: 单吨毛利 | AJ7: 销售总毛利 | AK7: 销售费用额 | AL7: 销售净贡献
A8: V1 | B8: 华南大区 | C8: 江门澳华 | H8: JK001 | I8: 虾安康 | J8: 虾蟹线 | K8: 虾料 | L8: 高价值

Sheet A9-表样-客户产品毛利表（内销）
A1: ← 返回目录 | B1: 任务名称： | C1: 1.1销量预算表_编制
B2: 年份： | C2: 2026 | D2: 月份： | E2: 01,02,03
B3: 版本类型： | C3: 年度
B4: 版本： | C4: v1
B5: 业务单元： | C5: 江门澳华
A7: 版本 | B7: 大区 | C7: 公司 | D7: 区域/聚焦镇 | E7: 客户编码 | F7: 客户 | G7: 是否大客户 | H7: 产品系列编码 | I7: 产品系列名称 | J7: 大类 | K7: 小类 | L7: 战略产品 | M7: 销售吨位 | N7: 赠送吨位 | O7: 单吨售价 | P7: 售价总额 | Q7: 单吨净收 | R7: 销售净收入额 | S7: 销售成本 | T7: 单吨销售成本 | U7: 单吨配方成本 | V7: 单吨包装物 | W7: 单吨燃动 | X7: 单吨人工 | Y7: 单吨变动制造费用 | Z7: 单吨固定制造费用 | AA7: 单吨制造费用 | AB7: 单吨配销差 | AC7: 配销差总额 | AD7: 单吨毛利 | AE7: 销售总毛利
A8: V1 | B8: 华南大区 | C8: 江门澳华 | H8: JK001 | I8: 虾安康 | J8: 虾蟹线 | K8: 虾料 | L8: 高价值

Sheet 查阅-产品生产成本
A1: ← 返回目录 | B1: 公司 | C1: 大类 | D1: 小类 | E1: 2026年预算 | L1: 2025年实际值 | S1: 同比增长（预测-同比）
E2: 单吨配方成本 | F2: 单吨包装物 | G2: 单吨制造费用 | H2: 其中：单吨燃动 | I2: 其中：单吨人工 | J2: 其中：单吨其他变动费用 | K2: 其中：单吨固定制造费用 | L2: 单吨配方成本 | M2: 单吨包装物 | N2: 单吨制造费用 | O2: 其中：单吨燃动 | P2: 其中：单吨人工 | Q2: 其中：单吨其他变动费用 | R2: 其中：单吨固定制造费用 | S2: 单吨配方成本 | T2: 单吨包装物 | U2: 单吨制造费用 | V2: 其中：单吨燃动 | W2: 其中：单吨人工 | X2: 其中：单吨其他变动费用 | Y2: 其中：单吨固定制造费用
C3: 海特料 | D3: 大黄鱼料 | L3: 计算 | M3: 计算 | N3: 本表计算 | S3: 本表计算 | T3: 本表计算 | U3: 本表计算
D4: 石斑鱼料 | L4: 计算 | M4: 计算 | N4: 本表计算 | S4: 本表计算 | T4: 本表计算 | U4: 本表计算
L5: 计算 | M5: 计算 | N5: 本表计算 | S5: 本表计算 | T5: 本表计算 | U5: 本表计算
L6: 计算 | M6: 计算 | N6: 本表计算 | S6: 本表计算 | T6: 本表计算 | U6: 本表计算
L7: 计算 | M7: 计算 | N7: 本表计算 | S7: 本表计算 | T7: 本表计算 | U7: 本表计算
L8: 计算 | M8: 计算 | N8: 本表计算 | S8: 本表计算 | T8: 本表计算 | U8: 本表计算
L9: 计算 | M9: 计算 | N9: 本表计算 | S9: 本表计算 | T9: 本表计算 | U9: 本表计算
L10: 计算 | M10: 计算 | N10: 本表计算 | S10: 本表计算 | T10: 本表计算 | U10: 本表计算
L11: 计算 | M11: 计算 | N11: 本表计算 | S11: 本表计算 | T11: 本表计算 | U11: 本表计算
L12: 计算 | M12: 计算 | N12: 本表计算 | S12: 本表计算 | T12: 本表计算 | U12: 本表计算
L13: 计算 | M13: 计算 | N13: 本表计算 | S13: 本表计算 | T13: 本表计算 | U13: 本表计算
L14: 计算 | M14: 计算 | N14: 本表计算 | S14: 本表计算 | T14: 本表计算 | U14: 本表计算
L15: 计算 | M15: 计算 | N15: 本表计算 | S15: 本表计算 | T15: 本表计算 | U15: 本表计算
L16: 计算 | M16: 计算 | N16: 本表计算 | S16: 本表计算 | T16: 本表计算 | U16: 本表计算
... L23: 计算 | M23: 计算 | N23: 本表计算 | S23: 本表计算 | T23: 本表计算 | U23: 本表计算

Sheet  单吨制造费用-生产、财务-查阅
A1: ← 返回目录 | E1: 填录说明： | F1: 第一步，选择年、公司、版本、场景；
F2: 第二步，下拉选择产品系列；
F3: 第四步，系统将根据生产预算表自动计算产品系列的单吨制造费用数据。
F4: 第四步，填制数据完成后，单击【提交】按钮，将数据提交至系统。
A5: 责任部门：生产部、财务部 | E5: 单位：元/吨
A7: 年 | B7: 2026年 | C7: 公司 | D7: xx澳华 | E7: 版本 | F7: V1 | G7: 场景
A9: 大类 | B9: 小类 | C9: 产品系列编码 | D9: 产品系列 | E9: 25年平均单吨制造费用 | F9: 26年平均单吨制造费用 | G9: 平均单吨制造费用同比增减额 | H9: 2026年单吨制造费用 | T9: 2025年单吨制造费用 | AF9: 单吨制造费用同比
H10: 1月 | I10: 2月 | J10: 3月 | K10: 4月 | L10: 5月 | M10: 6月 | N10: 7月 | O10: 8月 | P10: 9月 | Q10: 10月 | R10: 11月 | S10: 12月 | T10: 1月 | U10: 2月 | V10: 3月 | W10: 4月 | X10: 5月 | Y10: 6月 | Z10: 7月 | AA10: 8月 | AB10: 9月 | AC10: 10月 | AD10: 11月 | AE10: 12月 | AF10: 1月 | AG10: 2月 | AH10: 3月 | AI10: 4月 | AJ10: 5月 | AK10: 6月 | AL10: 7月 | AM10: 8月 | AN10: 9月 | AO10: 10月 | AP10: 11月 | AQ10: 12月
A11: 自动生成 | B11: 自动生成 | C11: 自动生成 | D11: 自动生成 | E11: 自动生成 | F11: 计算 | G11: 计算 | H11: 自动生成 | I11: 自动生成 | J11: 自动生成 | K11: 自动生成 | L11: 自动生成 | M11: 自动生成 | N11: 自动生成 | O11: 自动生成 | P11: 自动生成 | Q11: 自动生成 | R11: 自动生成 | S11: 自动生成 | T11: 自动生成 | U11: 自动生成 | V11: 自动生成 | W11: 自动生成 | X11: 自动生成 | Y11: 自动生成 | Z11: 自动生成 | AA11: 自动生成 | AB11: 自动生成 | AC11: 自动生成 | AD11: 自动生成 | AE11: 自动生成 | AF11: 自动生成 | AG11: 自动生成 | AH11: 自动生成 | AI11: 自动生成 | AJ11: 自动生成 | AK11: 自动生成 | AL11: 自动生成 | AM11: 自动生成 | AN11: 自动生成 | AO11: 自动生成 | AP11: 自动生成 | AQ11: 自动生成

Sheet 查阅-动保产品大类毛利
A1: ← 返回目录
A3: 大类 | B3: 产品系列 | C3: 2026年预算 | G3: 2025年实际值 | K3: 同比增长（预算-同比）
C5: 销售额 | D5: 生产成本 | E5: 毛利额 | F5: 毛利率 | G5: 销售额 | H5: 生产成本 | I5: 毛利额 | J5: 毛利率 | K5: 销售额 | L5: 生产生产 | M5: 毛利额 | N5: 毛利率
A6: 软颗粒 | B6: 肽康宝
B7: 虾酸奶

Sheet 查阅-动保产品大类毛利 (分月)
A1: ← 返回目录
A3: 大类 | B3: 产品系列 | C3: 销售额 | AC3: 2026年毛利额
C4: 2026年预算数 | P4: 同比 | AC4: 2026年预算数 | AP4: 同比
C5: 合计 | D5: 1月 | E5: 2月 | F5: 3月 | G5: 4月 | H5: 5月 | I5: 6月 | J5: 7月 | K5: 8月 | L5: 9月 | M5: 10月 | N5: 11月 | O5: 12月 | P5: 合计 | Q5: 1月 | R5: 2月 | S5: 3月 | T5: 4月 | U5: 5月 | V5: 6月 | W5: 7月 | X5: 8月 | Y5: 9月 | Z5: 10月 | AA5: 11月 | AB5: 12月 | AC5: 合计 | AD5: 1月 | AE5: 2月 | AF5: 3月 | AG5: 4月 | AH5: 5月 | AI5: 6月 | AJ5: 7月 | AK5: 8月 | AL5: 9月 | AM5: 10月 | AN5: 11月 | AO5: 12月 | AP5: 合计 | AQ5: 1月 | AR5: 2月 | AS5: 3月 | AT5: 4月 | AU5: 5月 | AV5: 6月 | AW5: 7月 | AX5: 8月 | AY5: 9月 | AZ5: 10月 | BA5: 11月 | BB5: 12月
A6: 软颗粒 | B6: 肽康宝
B7: 虾酸奶

Sheet 查阅-动保产品公司毛利（分月）
A1: ← 返回目录
C2: 注：销售额取饲料公司填报数据；动保仅填毛利率/吨毛利数据
A3: 公司 | B3: 大类 | C3: 销售额 | AC3: 2026年毛利额
C4: 2026年预算数 | P4: 同比 | AC4: 2026年预算数 | AP4: 同比
