Workbook
Name _B471721: #REF!
Name _B471721: #REF!
Name A: #REF!
Name A: #REF!
Name A: #REF!
Name A: #REF!
Name A: #REF!
Name A: #REF!
Name A: #REF!
Name A: #REF!
Name A: #REF!
Name A: #REF!
Name combo_1_1_data: #REF!
Name combo_1_1_data: #REF!
Name CompanyType: #REF!
Name CompanyType: #REF!
Name dadadadadad: #REF!
Name dadadadadad: #REF!
Name date: #REF!
Name date: #REF!
Name didi: #REF!
Name didi: #REF!
Name didi: #REF!
Name didi: #REF!
Name didi: #REF!
Name didi: #REF!
Name didi: #REF!
Name didi: #REF!
Name DSFD: #REF!
Name DSFD: #REF!
Name Kemu1: INDIRECT("目录!$B$2:$B$"&COUNTA(#REF!))
Name Kemu1: INDIRECT("目录!$B$2:$B$"&COUNTA(#REF!))
Name Print_Area_MI: #REF!
Name Print_Area_MI: #REF!
Name Print_Area_MI: #REF!
Name Print_Area_MI: #REF!
Name Print_Area_MI: #REF!
Name Print_Area_MI: #REF!
Name Print_Area_MI: #REF!
Name Print_Area_MI: #REF!
Name select: #REF!
Name select: #REF!
Name select: #REF!
Name select: #REF!
Name select: #REF!
Name select: #REF!
Name select: #REF!
Name select: #REF!
Name Sheet_ConTrialbal: #REF!
Name Sheet_ConTrialbal: #REF!
Name TM1REBUILDOPTION: 1
Name 啊: #REF!
Name 啊: #REF!
Name 啊: #REF!
Name 啊: #REF!
Name 啊: #REF!
Name 啊: #REF!
Name 啊: #REF!
Name 啊: #REF!
Name 澳保: #REF!

Sheet 目录
C1: 序号 | D1: 预算模块 | E1: 工作表名称 | F1: 报表内容 | G1: 报表类型 | H1: 部门 | I1: 填写依赖
A2: 同预算-自动取数 | C2: 1 | D2: 预算主数据 | E2: 基础档案 | F2: 基础资料 | G2: 填写 | H2: 财务
A3: 同预算-自动取数 | C3: 2 | D3: 预算主数据 | E3: 物料档案 | F3: 基础资料 | G3: 填写 | H3: 财务
A4: 同预算-自动取数 | C4: 3 | D4: 经营指标 | E4: 总体指标 | F4: 总体指标 | G4: 查阅 | I4: 从年度利润表取数
A5: 同预算-自动取数 | C5: 4 | D5: 利润表 | E5: 年度利润表 | F5: 年度指标 | G5: 查阅 | I5: 从客户产品毛利表（序号8）、序号22~32取数
A6: 同预算-自动取数 | C6: 5 | D6: 销量毛利 | E6: A6 表样-大类量利（查阅） | F6: 大类指标 | G6: 查阅 | I6: 从客户产品毛利表（序号8）取数
A7: 同预算-自动取数 | C7: 6 | D7: 销量毛利 | E7: A7 大类小类量利（查阅） | F7: 小类指标 | G7: 查阅 | I7: 从客户产品毛利表（序号8）取数
A8: 同预算-自动取数 | C8: 7 | D8: =F8 -> 毛利表（外销） | E8: A9-表样-客户产品毛利表（外销） | F8: 毛利表（外销） | G8: 查阅 | I8: 从15~17取销量，18取价格折扣，10取配方成本，12取包材成本，13取单吨制费计算表
A9: 同预算-自动取数 | C9: 8 | D9: =F9 -> 动保毛利 | E9: 查阅-动保产品大类毛利 | F9: 动保毛利 | G9: 查阅
A10: 同预算-自动取数 | C10: 9 | D10: 类别成本查询 | E10: 查阅-产品生产成本（类别） | F10: 类别成本查询 | G10: 查阅 | I10: 从表11汇总取数
A11: 同预算-自动取数 | C11: 10 | D11: 品系成本查询 | E11: 查阅-产品生产成本（品系） | F11: 品系成本查询 | G11: 查阅 | I11: 10取配方成本，12取包材成本，13取单吨制费计算表
A12: 改成查询表-包材单吨成本=预算单吨 | C12: 11 | D12: 包材成本 | E12: 填写-包材成本-采购、财务 | F12: 采购包材成本 | G12: 查阅 | H12: 财务 | I12: 依赖销量（评审后）1
A13: 同预算-自动取数 | C13: 12 | D13: 制造费用 | E13: 查阅- 制造费用-生产、财务 | F13: 制造费用 | G13: 查阅 | I13: 依赖产量（评审后）2
A14: 同预算-自动取数 | C14: 13 | D14: =F14 -> 制造费用 | E14: 单吨制费计算表 | F14: 制造费用 | G14: 查阅
A15: 修改-按小类汇总填写 | B15: √ | C15: 14 | D15: 销量 | E15: 填写-饲料销量-营销部 | F15: 饲料销量 | G15: 填写 | H15: 营销部（填）/营业部（审）
A16: 修改-按类别汇总填写 | B16: √ | C16: 15 | D16: 动保销售额 | E16: 填写-动保销售额-营销部 | F16: 动保销售额 | G16: 填写 | H16: 营销部（填）/营业部（审）
A17: 修改-按类别汇总填写 | B17: √ | C17: 16 | D17: 销量 | E17: 填写-动保发酵料-营销部 | F17: 动保销售额 | G17: 填写 | H17: 营销部（填）/营业部（审）
A18: 修改-按小类加权均价填写 | B18: √ | C18: 17 | D18: 产品价格折扣 | E18: 填写-产品价目折扣表-财务部 | F18: 产品价目表 | G18: 填写 | H18: 财务 | I18: 依赖销量1（销量评审后）
A19: 同预算-优化 | B19: √ | C19: 18 | D19: 产量 | E19: 产量-生产产量填报表 | F19: 产量 | G19: 填写 | H19: 生产部
A20: 修改-配方师填写品种配方成本，财务按照销量加权小类平均配方成本 | B20: √ | C20: 19 | D20: 配方成本 | E20: 填写-配方成本-配方师 | F20: 配方成本 | G20: 填写 | H20: 产品线（填）/财务（审）或（代） | I20: 依赖销量（评审后）1
A21: 同预算 | B21: √ | C21: 20 | D21: 制造费用 | E21: 制造费用-填报生产部 | F21: 制造费用 | G21: 填写 | H21: 生产 | I21: 依赖产量（评审后）2
A22: 同预算-优化 | B22: √ | C22: 21 | D22: 人员费用 | E22: 人工成本明细-人资 | F22: 人资报表 | G22: 填写 | H22: 人资 | I22: 依赖销量产量（评审后）1、2/依赖人员定编表
A23: 同预算-优化 | B23: √ | C23: 22 | D23: =F23 -> 销售费用 | E23: 销售费用-填报营销部 | F23: 销售费用 | G23: 填写 | H23: 营销部
A24: 同预算-优化 | B24: √ | C24: 23 | D24: =F24 -> 管理费用 | E24: 管理费用-各部门 | F24: 管理费用 | G24: 查阅 | H24: 财务部组织，各部门填写
A25: 同预算-优化 | B25: √ | C25: 24 | D25: =F25 -> 财务费用 | E25: 财务费用-财务部 | F25: 财务费用 | G25: 查阅 | H25: 财务
A26: 同预算-优化 | B26: √ | C26: 25 | D26: 税金 | E26: 营业税金及附加-财务 | F26: 税金 | G26: 填写 | H26: 财务 | I26: 依赖销量（评审后）1
A27: 同预算-优化 | B27: √ | C27: 26 | D27: 其他业务收支 | E27: 其他业务收支 | F27: 其他业务收支 | G27: 填写 | H27: 财务
A28: 同预算-优化 | B28: √ | C28: 27 | D28: 营业外收支 | E28: 营业外收支 | F28: 营业外收支 | G28: 填写 | H28: 财务
A29: 同预算-优化 | B29: √ | C29: 28 | D29: 税金 | E29: 所得税-财务 | F29: 所得税 | G29: 填写 | H29: 财务
A30: 同预算-优化 | B30: √ | C30: 29 | D30: 研发费用 | E30: 填写-养殖基地-明细 | F30: 养殖预算 | G30: 填写 | H30: 研究院
A31: 同预算-优化 | B31: √ | C31: 30 | D31: 考核调整 | E31: 利润调整明细（填写） | F31: 考核调整 | G31: 填写 | H31: 财务

Sheet 1基础档案
A1: ← 返回目录 | C1: 返回目录 | E1: 销售费用 | H1: 研发费用 | I1: 还原 | K1: 大区 | L1: 序号 | M1: 子公司 | N1: 财务对接人 | O1: 性质 | P1: 客户性质 | Q1: 产品大类 | S1: 华东区 | T1: 华南区 | U1: 华中区 | V1: 其他区 | X1: 月份 | AA1: 客户性质 | AB1: 客户类别 | AC1: 主营料种 | AD1: 产线
A2: 科目名称 | E2: 科目 | F2: 科目说明 | H2: 科目名称 | I2: 费用类别 | J2: 明细类别 | K2: 华南区 | L2: 1 | M2: 福建 | N2: 毕昌 | O2: 基地公司 | P2: 老客户 | Q2: 虾料 | R2: 目录!A1 | S2: 福建 | T2: 江门生物 | U2: 武汉 | V2: 原本 | X2: 1 | Y2: 1 | AA2: 新客户 | AB2: 经销商 | AC2: 虾料 | AD2: 虾蟹线
B3: 分类 | C3: 分解科目 | H3: 530104\研发支出\租赁费 | I3: 管理费用 | J3: 折旧费 | K3: 华东区 | L3: 2 | M3: 浙江 | N3: 高海菊 | O3: 基地公司 | P3: 新客户 | Q3: 蟹料 | S3: 浙江 | T3: 四会 | U3: 汉南 | V3: 越南 | X3: 2 | Y3: 2 | AA3: 老客户 | AB3: 直销户 | AC3: 龙虾料 | AD3: 海特线
A4: 销售吨数 | E4: 变动成本 | H4: 53010201\研发支出\人员人工\工资 | I4: 管理费用 | J4: 人工薪酬（工资、五险一金） | K4: 华中区 | L4: 3 | M4: 唐山 | N4: 梁文雅 | O4: 基地公司 | Q4: 普通膨化鱼料 | S4: 唐山 | T4: 玉林 | U4: 荆州 | V4: 澳保 | X4: 3 | Y4: 3 | AB4: 代工客户 | AC4: 蟹料 | AD4: 普鱼线
A5: 销售标准吨数 | E5: 提成奖励 | H5: 53010202\研发支出\人员人工\绩效工资 | I5: 管理费用 | J5: 人工薪酬（工资、五险一金） | K5: 其他区 | L5: 4 | M5: 惠州 | N5: 王虎伟 | O5: 基地公司 | Q5: 沉水鱼料 | S5: 惠州 | T5: 广西 | U5: 江西 | V5: 伟凝 | X5: 4 | Y5: 4 | AC5: 海特料 | AD5: 畜禽线
A6: 销售人数 | E6: 年终提成 | H6: 530124\研发支出\水电物业费 | I6: 制造费用 | J6: 能耗 | L6: 5 | M6: 淮安 | N6: 曹杰 | O6: 基地公司 | Q6: 高档膨化鱼料 | S6: 澳源 | T6: 贵州 | U6: 池州 | V6: 总部 | X6: 5 | Y6: 5 | AC6: 普通膨化鱼料
A7: 工资和薪金 | B7: 固定 | C7: 人力费用（固定工资、五险一金、职工福利） | E7: 成长分享 | H7: 53010204\研发支出\人员人工\公积金 | I7: 管理费用 | J7: 人工薪酬（工资、五险一金） | L7: 6 | M7: 泰州 | N7: 豆业晶 | O7: 基地公司 | Q7: 浓缩/预混料 | S7: 淮安 | T7: 海南 | U7: 洛阳水产 | X7: 6 | Y7: 6 | AC7: 沉水鱼料
A8: 提成奖励 | B8: 变动 | C8: 提成奖励 | E8: 运输费 | H8: 5301020501\研发支出\人员人工\社保\养老保险 | I8: 管理费用 | J8: 人工薪酬（工资、五险一金） | L8: 7 | M8: 南京 | N8: 郭良 | O8: 基地公司 | Q8: 猪饲料 | S8: 泰州 | T8: 大粤西 | U8: 洛阳陕西 | X8: 7 | Y8: 7 | AC8: 猪饲料
A9: 年终提成 | B9: 变动 | C9: 年终提成 | E9: 技术服务费 | H9: 5301020502\研发支出\人员人工\社保\医疗保险 | I9: 管理费用 | J9: 人工薪酬（工资、五险一金） | L9: 8 | M9: 江门生物 | N9: 邓洪才 | O9: 基地公司 | Q9: 禽料 | S9: 南京 | T9: 湛江 | U9: 洛阳畜禽 | X9: 8 | Y9: 8 | AC9: 禽料
A10: 成长分享 | B10: 变动 | C10: 成长分享 | E10: 固定成本 | H10: 5301020503\研发支出\人员人工\社保\工伤保险 | I10: 管理费用 | J10: 人工薪酬（工资、五险一金） | L10: 9 | M10: 四会 | N10: 张裕华 | O10: 基地公司 | Q10: 反刍料 | S10: 江苏 | T10: 四川 | U10: 湖南 | X10: 9 | Y10: 9 | AC10: 反刍料
A11: 劳务费 | B11: 固定 | C11: 人力费用（固定工资、五险一金、职工福利） | E11: 人力费用（固定工资、五险一金、职工福利） | H11: 5301020504\研发支出\人员人工\社保\失业保险 | I11: 管理费用 | J11: 人工薪酬（工资、五险一金） | L11: 10 | M11: 广西 | N11: 龙玉杰 | O11: 基地公司 | T11: 云南 | U11: 湖南澳源 | X11: 10 | Y11: 10 | AC11: 浓缩预混料
A12: 社保费 | B12: 固定 | C12: 人力费用（固定工资、五险一金、职工福利） | E12: 差旅费 | H12: 5301020505\研发支出\人员人工\社保\生育医疗 | I12: 管理费用 | J12: 人工薪酬（工资、五险一金） | L12: 11 | M12: 云南 | N12: 李小婷 | O12: 销售公司 | U12: 岳阳 | X12: 11 | Y12: 11 | AC12: 动保
A13: 住房公积金 | B13: 固定 | C13: 人力费用（固定工资、五险一金、职工福利） | E13: 车辆使用费 | H13: 530125\研发支出\成长分享 | I13: 管理费用 | J13: 成长分享 | L13: 12 | M13: 贵州 | N13: 蒙鸿娟 | O13: 销售公司 | U13: 益阳 | X13: 12 | Y13: 12
A14: 职工福利金 | B14: 固定 | C14: 人力费用（固定工资、五险一金、职工福利） | E14: 应酬费 | H14: 530103\研发支出\折旧费 | I14: 制造费用 | J14: 折旧费 | L14: 13 | M14: 四川 | N14: 石玉琴 | O14: 销售公司 | U14: 衡阳 | X14: 全年 | Y14: 13
A15: 差旅补助 | B15: 固定 | C15: 差旅费 | E15: 推广、会务 | H15: 530101\研发支出\直接材料及燃动力 | I15: 管理费用 | J15: 办公费用 | L15: 14 | M15: 湛江 | N15: 曾君 | O15: 基地公司
A16: 差旅费 | B16: 固定 | C16: 差旅费 | E16: 固定资产折旧费 | H16: 530111\研发支出\车辆使用费 | I16: 管理费用 | J16: 办公费用 | L16: 15 | M16: 海南 | N16: 何栩童 | O16: 事业部
A17: 车辆使用费 | B17: 固定 | C17: 人力费用（固定工资、五险一金、职工福利） | E17: 诉讼费 | H17: 53010203\研发支出\人员人工\奖金 | I17: 管理费用 | J17: 人工薪酬（工资、五险一金） | L17: 16 | M17: 武汉 | N17: 蒋晓玲 | O17: 基地公司
A18: 应酬费 | B18: 固定 | C18: 应酬费 | H18: 530122\研发支出\办公费 | I18: 管理费用 | J18: 办公费用 | L18: 17 | M18: 汉南 | N18: 余俊 | O18: 基地公司
A19: 销售推广费 | B19: 固定 | C19: 推广、会务 | H19: 530109\研发支出\技术服务费 | I19: 管理费用 | J19: 办公费用 | L19: 18 | M19: 荆州 | N19: 孙子明 | O19: 销售公司
A20: 会务费 | B20: 固定 | C20: 推广、会务 | E20: 管理费用 | H20: 530108\研发支出\差旅费 | I20: 管理费用 | J20: 人工薪酬（工资、五险一金） | L20: 19 | M20: 江西 | N20: 卞淑芬 | O20: 基地公司
A21: 运输费 | B21: 变动 | C21: 运输费 | E21: 科目 | H21: 530121\研发支出\业务招待费 | I21: 管理费用 | J21: 应酬费 | L21: 20 | M21: 洛阳水产 | N21: 韩玉可 | O21: 事业部
A22: 中转仓储费 | B22: 固定 | C22: 固定资产折旧费 | H22: 530119\研发支出\职工福利费 | I22: 管理费用 | J22: 人工薪酬（工资、五险一金） | L22: 22 | M22: 洛阳畜禽 | N22: 韩玉可 | O22: 基地公司
A23: 诉讼费 | B23: 固定 | C23: 诉讼费 | E23: 变动费用 | H23: 530123\研发支出\维护费 | I23: 制造费用 | J23: 维修费 | L23: 23 | M23: 湖南 | N23: 郭佳 | O23: 基地公司
A24: 其他 | B24: 固定 | C24: 固定资产折旧费 | E24: 成长分享 | H24: 530116\研发支出\外聘劳务费 | I24: 管理费用 | J24: 人工薪酬（工资、五险一金） | L24: 24 | M24: 益阳 | N24: 罗燕红 | O24: 销售公司
A25: 运输费（对内） | B25: 变动 | C25: 运输费 | E25: 股份支付 | H25: 530117\研发支出\购置费及检验费 | I25: 制造费用 | J25: 维修费 | L25: 26 | M25: 越南 | N25: 肖阿林 | O25: 基地公司
A26: 办公费 | B26: 固定 | C26: 推广、会务 | E26: 固定费用 | H26: 530112\研发支出\会务费 | I26: 管理费用 | J26: 会务费 | L26: 27 | M26: 澳保 | N26: 路鑫 | O26: 基地公司
A27: 技术服务费 | B27: 变动 | C27: 技术服务费 | E27: 人工薪酬（工资、五险一金） | H27: 530126\研发支出\运输费 | I27: 管理费用 | J27: 办公费用 | L27: 28 | M27: 伟凝 | N27: 陈小冰 | O27: 销售公司
A28: 使用权资产折旧费 | B28: 固定 | C28: 固定资产折旧费 | E28: 应酬费 | H28: 530120\研发支出\使用权资产折旧费 | I28: 管理费用 | J28: 折旧费 | L28: 29 | M28: 总部 | N28: 陈晓佳 | O28: 总部
A29: 固定资产折旧费 | B29: 固定 | C29: 固定资产折旧费 | E29: 办公费用 | H29: 530113\研发支出\知识产权费 | I29: 管理费用 | J29: 折旧费
A30: 无形资产摊销费 | B30: 固定 | C30: 固定资产折旧费 | E30: 培训招聘费 | H30: 530115\研发支出\长期待摊费用摊销 | I30: 管理费用 | J30: 折旧费
A31: 长期待摊费用摊销 | B31: 固定 | C31: 固定资产折旧费 | E31: 水电费 | H31: 530118\研发支出\设计制定费及试验费 | I31: 制造费用 | J31: 维修费

Sheet 2物料档案
A1: ← 返回目录
A2: 所属公司 | B2: 启用状态 | C2: 物料编码 | D2: 物料名称 | E2: 物料编码 | F2: 大类 | G2: 小类 | H2: 5+2分类 | I2: 助记码 | J2: 产品系列
A3: 湖南澳华农牧科技有限公司 | B3: 已启用 | C3: 2201020561 | D3: 花鲢1号Φ1.0 | E3: 2201020561 | F3: 普通膨化鱼料 | G3: 鳙鱼料 | I3: WUH1-HL1-1.0 | J3: 花鲢1号 | K3: Φ | N3: 大类 | O3: 产线
A4: 湖南澳华农牧科技有限公司 | B4: 已启用 | C4: 2201020564 | D4: 贵妃宝Φ5.0 | E4: 2201020564 | F4: 普通膨化鱼料 | G4: 草鱼料 | H4: 鱼安康系列-草鱼安康 | I4: WUH1-GFB-5.0 | J4: 贵妃宝 | N4: 龙虾料 | O4: 虾蟹线
A5: 湖南澳华农牧科技有限公司 | B5: 已启用 | C5: 2201020566 | D5: 草鱼安康Φ2.0 | E5: 2201020566 | F5: 普通膨化鱼料 | G5: 草鱼料 | H5: 鱼安康系列-草鱼安康 | I5: WUH1-CYAK-2.0 | J5: 草鱼安康 | N5: 虾料 | O5: 虾蟹线
A6: 湖南澳华农牧科技有限公司 | B6: 已启用 | C6: 2201020567 | D6: 草鱼安康Φ3.0 | E6: 2201020567 | F6: 普通膨化鱼料 | G6: 草鱼料 | H6: 鱼安康系列-草鱼安康 | I6: WUH1-CYAK-3.0 | J6: 草鱼安康 | N6: 蟹料 | O6: 虾蟹线
A7: 湖南澳华农牧科技有限公司 | B7: 已启用 | C7: 2201020569 | D7: 淡水鱼1号料Φ2.0 | E7: 2201020569 | F7: 普通膨化鱼料 | G7: 草鱼料 | I7: WUH1-DSY1-2.0 | J7: 淡水鱼1号料 | N7: 海特料 | O7: 海特线
A8: 湖南澳华农牧科技有限公司 | B8: 已启用 | C8: 2201020570 | D8: 淡水鱼1号料Φ3.0 | E8: 2201020570 | F8: 普通膨化鱼料 | G8: 草鱼料 | I8: WUH1-DSY1-3.0 | J8: 淡水鱼1号料 | N8: 沉水鱼料 | O8: 鱼料线
A9: 湖南澳华农牧科技有限公司 | B9: 已停用 | C9: 2201020571 | D9: 淡水鱼1号料Φ5.0 | E9: 2201020571 | F9: 普通膨化鱼料 | G9: 草鱼料 | I9: WUH1-DSY1-5.0 | J9: 淡水鱼1号料 | N9: 普通膨化鱼料 | O9: 鱼料线
A10: 湖南澳华农牧科技有限公司 | B10: 已停用 | C10: 2201020576 | D10: 冬藏宝Φ3.0 | E10: 2201020576 | F10: 普通膨化鱼料 | G10: 四季料 | I10: WUH1-DSDCB-3.0 | J10: 冬藏宝 | N10: 反刍料 | O10: 畜禽线
A11: 湖南澳华农牧科技有限公司 | B11: 已启用 | C11: 2201020582 | D11: 混养2号Φ3.0 | E11: 2201020582 | F11: 普通膨化鱼料 | G11: 草鱼料 | I11: WUH1-HY2-3.0 | J11: 混养2号 | N11: 浓缩/预混料 | O11: 畜禽线
A12: 湖南澳华农牧科技有限公司 | B12: 已启用 | C12: 2201020316 | D12: 驯化宝Φ2.0 | E12: 2201020316 | F12: 普通膨化鱼料 | G12: 四季料 | H12: 无 | I12: HUN1-XHB-2.0 | J12: 驯化宝 | N12: 禽料 | O12: 畜禽线
A13: 湖南澳华农牧科技有限公司 | B13: 已启用 | C13: 2201020317 | D13: 驯化宝Φ3.0 | E13: 2201020317 | F13: 普通膨化鱼料 | G13: 四季料 | H13: 无 | I13: HUN1-XHB-3.0 | J13: 驯化宝 | N13: 猪饲料 | O13: 畜禽线
A14: 湖南澳华农牧科技有限公司 | B14: 已启用 | C14: 2201020322 | D14: 冬藏宝Φ3.0 | E14: 2201020322 | F14: 普通膨化鱼料 | G14: 四季料 | H14: 无 | I14: HUN1-DCB-3.0 | J14: 冬藏宝
A15: 湖南澳华农牧科技有限公司 | B15: 已启用 | C15: 2201020327 | D15: 膨化混养1号Φ3.0 | E15: 2201020327 | F15: 普通膨化鱼料 | G15: 草鱼料 | H15: 无 | I15: HUN1-PHHY1-3.0 | J15: 膨化混养1号
A16: 湖南澳华农牧科技有限公司 | B16: 已启用 | C16: 2201050001 | D16: 叉尾鮰2号Φ2.0 | E16: 2201050001 | F16: 普通膨化鱼料 | G16: 叉尾鮰料 | I16: ZJ1-CWH2-2.0 | J16: 叉尾鮰2号
A17: 湖南澳华农牧科技有限公司 | B17: 已启用 | C17: 2201050002 | D17: 叉尾鮰2号Φ3.0 | E17: 2201050002 | F17: 普通膨化鱼料 | G17: 叉尾鮰料 | I17: ZJ1-CWH2-3.0 | J17: 叉尾鮰2号
A18: 湖南澳华农牧科技有限公司 | B18: 已启用 | C18: 2201050008 | D18: 特种鱼苗料Φ1.0 | E18: 2201050008 | F18: 高档膨化鱼料 | G18: 鱼苗料 | I18: WUH1-TZYML-1.0 | J18: 特种鱼苗料
A19: 湖南澳华农牧科技有限公司 | B19: 已启用 | C19: 2201050009 | D19: 翘嘴安康Φ2.0 | E19: 2201050009 | F19: 高档膨化鱼料 | G19: 翘嘴料 | H19: 海特料-翘嘴安康 | I19: WUH1-QZAK-2.0 | J19: 翘嘴安康
A20: 湖南澳华农牧科技有限公司 | B20: 已启用 | C20: 2201050010 | D20: 翘嘴安康Φ3.0 | E20: 2201050010 | F20: 高档膨化鱼料 | G20: 翘嘴料 | H20: 海特料-翘嘴安康 | I20: WUH1-QZAK-3.0 | J20: 翘嘴安康
A21: 湖南澳华农牧科技有限公司 | B21: 已启用 | C21: 2201050011 | D21: 翘嘴安康Φ5.0 | E21: 2201050011 | F21: 高档膨化鱼料 | G21: 翘嘴料 | H21: 海特料-翘嘴安康 | I21: WUH1-QZAK-5.0 | J21: 翘嘴安康
A22: 湖南澳华农牧科技有限公司 | B22: 已启用 | C22: 2201050012 | D22: 鲌鱼2号Φ2.0 | E22: 2201050012 | F22: 高档膨化鱼料 | G22: 翘嘴料 | I22: WUH1-BY2H-2.0 | J22: 鲌鱼2号
A23: 湖南澳华农牧科技有限公司 | B23: 已启用 | C23: 2201050013 | D23: 鲌鱼2号Φ3.0 | E23: 2201050013 | F23: 高档膨化鱼料 | G23: 翘嘴料 | I23: WUH1-BY2H-3.0 | J23: 鲌鱼2号
A24: 湖南澳华农牧科技有限公司 | B24: 已启用 | C24: 2201050014 | D24: 鲌鱼2号Φ5.0 | E24: 2201050014 | F24: 高档膨化鱼料 | G24: 翘嘴料 | I24: WUH1-BY2H-5.0 | J24: 鲌鱼2号
A25: 湖南澳华农牧科技有限公司 | B25: 已停用 | C25: 2201020584 | D25: 渔家旺Φ2.0 | E25: 2201020584 | F25: 普通膨化鱼料 | G25: 草鱼料 | I25: WUH1-YJW-2.0 | J25: 渔家旺
A26: 湖南澳华农牧科技有限公司 | B26: 已启用 | C26: 2201020585 | D26: 渔家旺Φ3.0 | E26: 2201020585 | F26: 普通膨化鱼料 | G26: 草鱼料 | I26: WUH1-YJW-3.0 | J26: 渔家旺
A27: 湖南澳华农牧科技有限公司 | B27: 已停用 | C27: 2201020587 | D27: 驯化宝Φ2.0 | E27: 2201020587 | F27: 普通膨化鱼料 | G27: 四季料 | I27: WUH1-XHB-2.0 | J27: 驯化宝
A28: 湖南澳华农牧科技有限公司 | B28: 已停用 | C28: 2201020588 | D28: 驯化宝Φ3.0 | E28: 2201020588 | F28: 普通膨化鱼料 | G28: 四季料 | I28: WUH1-XHB-3.0 | J28: 驯化宝
A29: 湖南澳华农牧科技有限公司 | B29: 已停用 | C29: 2201020596 | D29: 淡水肝肠安康Ⅱ型Φ2.0 | E29: 2201020596 | F29: 普通膨化鱼料 | G29: 功能料 | H29: 功能料系列-肝肠安康 | I29: WUH1-DSGCAKⅡ-2.0 | J29: 淡水肝肠安康Ⅱ型
A30: 湖南澳华农牧科技有限公司 | B30: 已启用 | C30: 2201020698 | D30: 贵妃宝Φ3.0 | E30: 2201020698 | F30: 普通膨化鱼料 | G30: 草鱼料 | H30: 鱼安康系列-草鱼安康 | I30: WUH1-GFB-3.0 | J30: 贵妃宝
A31: 湖南澳华农牧科技有限公司 | B31: 已启用 | C31: 2201020722 | D31: 贵妃宝Φ2.0 | E31: 2201020722 | F31: 普通膨化鱼料 | G31: 草鱼料 | H31: 无 | I31: WUH1-GFB-2.0 | J31: 贵妃宝
A32: 湖南澳华农牧科技有限公司 | B32: 已启用 | C32: 2201100091 | D32: 叉尾鮰3号Φ2.0 | E32: 2201100091 | F32: 普通膨化鱼料 | G32: 叉尾鮰料 | I32: WUH1-CWH3-2.0 | J32: 叉尾鮰3号
A33: 湖南澳华农牧科技有限公司 | B33: 已启用 | C33: 2201100092 | D33: 叉尾鮰3号Φ3.0 | E33: 2201100092 | F33: 普通膨化鱼料 | G33: 叉尾鮰料 | I33: WUH1-CWH3-3.0 | J33: 叉尾鮰3号
A34: 湖南澳华农牧科技有限公司 | B34: 已启用 | C34: 2201100093 | D34: 叉尾鮰3号Φ5.0 | E34: 2201100093 | F34: 普通膨化鱼料 | G34: 叉尾鮰料 | I34: WUH1-CWH3-5.0 | J34: 叉尾鮰3号
A35: 湖南澳华农牧科技有限公司 | B35: 已启用 | C35: 2201100097 | D35: 叉尾安康Φ2.0 | E35: 2201100097 | F35: 普通膨化鱼料 | G35: 叉尾鮰料 | H35: 鱼安康系列-叉尾安康 | I35: WUH1-CWAK-2.0 | J35: 叉尾安康
A36: 湖南澳华农牧科技有限公司 | B36: 已启用 | C36: 2201100098 | D36: 叉尾安康Φ3.0 | E36: 2201100098 | F36: 普通膨化鱼料 | G36: 叉尾鮰料 | H36: 鱼安康系列-叉尾安康 | I36: WUH1-CWAK-3.0 | J36: 叉尾安康
A37: 湖南澳华农牧科技有限公司 | B37: 已启用 | C37: 2201100099 | D37: 叉尾安康Φ5.0 | E37: 2201100099 | F37: 普通膨化鱼料 | G37: 叉尾鮰料 | H37: 鱼安康系列-叉尾安康 | I37: WUH1-CWAK-5.0 | J37: 叉尾安康
A38: 湖南澳华农牧科技有限公司 | B38: 已启用 | C38: 2202010176 | D38: 青蛙1号AΦ1.5 | E38: 2202010176 | F38: 高档膨化鱼料 | G38: 蛙料 | H38: 无 | I38: WUH1-QW1A-1.5 | J38: 青蛙1号A
A39: 湖南澳华农牧科技有限公司 | B39: 已启用 | C39: 2202010179 | D39: 蛙粉A料Φ粉 | E39: 2202010179 | F39: 高档膨化鱼料 | G39: 蛙料 | H39: 无 | I39: WUH18-WFA-F | J39: 蛙粉A料
A40: 湖南澳华农牧科技有限公司 | B40: 已启用 | C40: 2202010183 | D40: 青蛙1号Φ1.5 | E40: 2202010183 | F40: 高档膨化鱼料 | G40: 蛙料 | H40: 无 | I40: WUH18-QW1-1.5 | J40: 青蛙1号
...

Sheet 3总体指标
A1: ← 返回目录 | L1: 报表内容 | M1: 报表类型
A2: 财务指标审核表 | L2: 总体指标 | M2: 查阅
A3: 大区 | B3: 公司 | C3: 指标 | D3: 2026年预测 | E3: 2025年全年 | F3: 2026年预算 | G3: 预算增长额 | H3: 预算增长率 | I3: 异常数据说明 | L3: 年度指标 | M3: 查阅
A4: 华东一区 | B4: 福建公司 | C4: 外销销量(万吨） | D4: 取<年度利润表-销售量合计(吨)(序号11）>F列 | E4: 取<年度利润表-销售量合计(吨)(序号11）>G列 | F4: 取<年度利润表-销售量合计(吨)(序号11）>H列 | G4: 本行D列-本行E列 | H4: 本行G列/本行E列 | I4: 单位手工填写 | L4: 月度指标 | M4: 查阅
A5: =A4 -> 华东一区 | B5: 福建公司 | C5: 主营业务收入(万元） | D5: 取<年度利润表-一、主营业务收入(序号12）>F列 | E5: 取<年度利润表-一、主营业务收入(序号12）>G列 | F5: 取<年度利润表-一、主营业务收入(序号12）>H列 | G5: 本行D列-本行E列 | H5: 本行G列/本行E列 | I5: 单位手工填写 | L5: 产线贡献 | M5: 查阅
A6: =A5 -> 华东一区 | B6: 福建公司 | C6: 毛利(万元） | D6: 取<年度利润表-二、毛利(序号14）>F列 | E6: 取<年度利润表-二、毛利(序号14）>G列 | F6: 取<年度利润表-二、毛利(序号14）>H列 | G6: 本行D列-本行E列 | H6: 本行G列/本行E列 | I6: 单位手工填写 | L6: 人效 | M6: 查阅
A7: =A6 -> 华东一区 | B7: 福建公司 | C7: 毛利率 | D7: =D6/D5 | E7: =E6/E5 | F7: =F6/F5 | G7: 本行D列-本行E列 | H7: 本行G列/本行E列 | I7: 单位手工填写 | L7: 基础资料 | M7: 填写
A8: =A7 -> 华东一区 | B8: 福建公司 | C8: NC利润 | D8: 取<年度利润表-五、净利润(序号40）>F列 | E8: 取<年度利润表-五、净利润(序号40）>G列 | F8: 取<年度利润表-五、净利润(序号40）>H列 | G8: 本行D列-本行E列 | H8: 本行G列/本行E列 | I8: 单位手工填写 | L8: 基础资料 | M8: 填写
A9: =A8 -> 华东一区 | B9: 福建公司 | C9: 特殊考核调整 | D9: 取<年度利润表-考核调整-合计(序号52）>F列 | E9: 取<年度利润表-考核调整-合计(序号52）>G列 | F9: 取<年度利润表-考核调整-合计(序号52）>H列 | G9: 本行D列-本行E列 | H9: 本行G列/本行E列 | I9: 单位手工填写 | L9: 聚焦镇指标 | M9: 查阅
A10: =A9 -> 华东一区 | B10: 福建公司 | C10: 考核利润(万元） | D10: 取<年度利润表-NC利润(序号54）>F列 | E10: 取<年度利润表-NC利润(序号54）>G列 | F10: 取<年度利润表-NC利润(序号54）>H列 | G10: 本行D列-本行E列 | H10: 本行G列/本行E列 | I10: 单位手工填写 | L10: 大类指标 | M10: 查阅
A11: =A10 -> 华东一区 | B11: 福建公司 | C11: 其他业务利润(万元） | D11: 取<年度利润表-F列对应序号15~20计算>，计算公司：15-16+17-18+19+20 | E11: 取<年度利润表-G列对应序号15~20计算>，计算公司：15-16+17-18+19+20 | F11: 取<年度利润表-H列对应序号15~20计算>，计算公司：15-16+17-18+19+20 | G11: 本行D列-本行E列 | H11: 本行G列/本行E列 | I11: 单位手工填写 | L11: 小类指标 | M11: 查阅
A12: =A11 -> 华东一区 | B12: 福建公司 | C12: 销售费用 | D12: 取<年度利润表-销售费用(序号22）>F列 | E12: 取<年度利润表-销售费用(序号22）>G列 | F12: 取<年度利润表-销售费用(序号22）>H列 | G12: 本行D列-本行E列 | H12: 本行G列/本行E列 | I12: 单位手工填写 | L12: 配销差吨毛利 | M12: 查阅
A13: =A12 -> 华东一区 | B13: 福建公司 | C13: 管理费用 | D13: 取<年度利润表-管理费用(序号23）>F列 | E13: 取<年度利润表-管理费用(序号23）>G列 | F13: 取<年度利润表-管理费用(序号23）>H列 | G13: 本行D列-本行E列 | H13: 本行G列/本行E列 | I13: 单位手工填写 | L13: 毛利表（外销） | M13: 查阅
A14: =A13 -> 华东一区 | B14: 福建公司 | C14: 财务费用 | D14: 取<年度利润表-财务费用(序号25）>F列 | E14: 取<年度利润表-财务费用(序号25）>G列 | F14: 取<年度利润表-财务费用(序号25）>H列 | G14: 本行D列-本行E列 | H14: 本行G列/本行E列 | I14: 单位手工填写 | L14: 毛利表（内销） | M14: 查阅
A15: =A14 -> 华东一区 | B15: 福建公司 | C15: 销售E值(万元） | D15: 取<人工成本明细-人资-销售费用-E值>G列 | E15: 取<人工成本明细-人资-销售费用-E值>F列 | G15: 本行D列-本行E列 | H15: 本行G列/本行E列 | I15: 单位手工填写 | L15: 生产成本 | M15: 查阅
A16: =A15 -> 华东一区 | B16: 福建公司 | C16: 管理E值(万元） | D16: 取<人工成本明细-人资-管理费用-E值>G列 | E16: 取<人工成本明细-人资-管理费用-E值>F列 | G16: 本行D列-本行E列 | H16: 本行G列/本行E列 | I16: 单位手工填写 | L16: 制造费用 | M16: 查阅
A17: =A16 -> 华东一区 | B17: 福建公司 | C17: 销售人数 | D17: 取<表7.1 表样-销费科目明细-销售人数(序号61）>E列 | E17: 取<表7.1 表样-销费科目明细-销售人数(序号61）>H列 | G17: 本行D列-本行E列 | H17: 本行G列/本行E列 | I17: 单位手工填写 | L17: 动保毛利 | M17: 查阅
A18: =A17 -> 华东一区 | B18: 福建公司 | C18: 管理人数 | G18: 本行D列-本行E列 | H18: 本行G列/本行E列 | I18: 单位手工填写 | L18: 动保大类毛利 | M18: 查阅
A19: =A18 -> 华东一区 | B19: 福建公司 | C19: 生产人数 | D19: 取<制造费用-填报生产部-生产人数>D列 | E19: 取<制造费用-填报生产部-生产人数>E列 | G19: 本行D列-本行E列 | H19: 本行G列/本行E列 | I19: 单位手工填写 | L19: 动保公司毛利 | M19: 查阅
A20: =A19 -> 华东一区 | B20: 福建公司 | C20: 人均销量(吨/人) | D20: 本表D4/D17 | E20: 本表E4/E17 | F20: 本表F4/F17 | G20: 本行D列-本行E列 | H20: 本行G列/本行E列 | I20: 单位手工填写 | L20: 动保产品毛利 | M20: 查阅
A21: =A20 -> 华东一区 | B21: 福建公司 | C21: 单吨销售费用(元/吨） | D21: 本表D12/D4 | E21: 本表E12/E4 | F21: 本表F12/F4 | G21: 本行D列-本行E列 | H21: 本行G列/本行E列 | I21: 单位手工填写 | L21: 饲料销量 | M21: 填写
A22: =A20 -> 华东一区 | B22: 福建公司 | C22: 销售费用率 | D22: 本表D12/D5 | E22: 本表E12/E5 | F22: 本表F12/F5 | G22: 本行D列-本行E列 | H22: 本行G列/本行E列 | I22: 单位手工填写 | L22: 动保销售额 | M22: 填写
A23: =A22 -> 华东一区 | B23: 福建公司 | C23: 管理费用率 | D23: 本表D13/D5 | E23: 本表E13/E5 | F23: 本表F13/F5 | G23: 本行D列-本行E列 | H23: 本行G列/本行E列 | I23: 单位手工填写 | L23: 动保销售额 | M23: 填写
A24: =A23 -> 华东一区 | B24: 福建公司 | C24: 销售E/M值 | D24: 本表D15/D6 | E24: 本表E15/E6 | F24: 本表F15/F6 | G24: 本行D列-本行E列 | H24: 本行G列/本行E列 | I24: 单位手工填写 | L24: 动保销售额 | M24: 填写
A25: =A24 -> 华东一区 | B25: 福建公司 | C25: 管理E/M值 | D25: 本表D16/D6 | E25: 本表E16/E6 | F25: 本表F16/F6 | G25: 本行D列-本行E列 | H25: 本行G列/本行E列 | I25: 单位手工填写 | L25: 动保销量 | M25: 填写
A26: 说明：所有指标同比偏差±30%以上，请填报人员必须说明原因，财务复核其合理性。 | L26: 动保成本 | M26: 填写
L27: 动保成本 | M27: 填写
L28: 内部代工 | M28: 填写
L29: 内部代工 | M29: 填写
L30: 产品价目表 | M30: 填写
L31: 配方成本 | M31: 填写
L32: 产品折扣 | M32: 填写
L33: 采购包材成本 | M33: 填写
L34: 采购原料价格 | M34: 填写
L35: 生产产量 | M35: 填写
L36: 生产产量 | M36: 填写
L37: 制造费用 | M37: 填写
L38: 制造费用 | M38: 查阅
... L77: 折旧费 | M77: 查阅

Sheet 4利润表
A1: ← 返回目录
A2: 大区 | B2: 公司 | C2: 报表项目 | D2: 序号 | E2: 科目名称 | F2: 当期值 | K2: 累计值 | P2: 异常说明
F3: 预测值 | G3: 预算值 | H3: 同期值 | I3: 同比增减 | J3: 预算差 | K3: 预测值 | L3: 预算值 | M3: 同期值 | N3: 同比增减 | O3: 预算差
A4: ='[3]A1 预算指标总览'!$A$3 -> 华东一区 | B4: ='[3]A1 预算指标总览'!$B$3 -> 福建公司 | C4: 损益总表 | D4: 1 | E4: 销售量 | F4: 标题 | G4: 标题 | H4: 标题 | K4: 标题 | L4: 标题 | M4: 标题
A5: ='[3]A1 预算指标总览'!$A$3 -> 华东一区 | B5: ='[3]A1 预算指标总览'!$B$3 -> 福建公司 | C5: 损益总表 | D5: 2 | E5: 普通膨化鱼料 | F5: 取<月度利润表-(行号2）>R列 | G5: 取<月度利润表-(行号2）>AE列 | H5: 取<月度利润表-(行号2）>AR列 | K5: 取<月度利润表-(行号2）>R列 | L5: 取<月度利润表-(行号2）>AE列 | M5: 取<月度利润表-(行号2）>AR列 | P5: 单位手工填写
A6: ='[3]A1 预算指标总览'!$A$3 -> 华东一区 | B6: ='[3]A1 预算指标总览'!$B$3 -> 福建公司 | C6: 损益总表 | D6: 3 | E6: 高档膨化鱼料 | F6: 取<月度利润表-(行号3）>R列 | G6: 取<月度利润表-(行号3）>AE列 | H6: 取<月度利润表-(行号3）>AR列 | K6: 取<月度利润表-(行号3）>R列 | L6: 取<月度利润表-(行号3）>AE列 | M6: 取<月度利润表-(行号3）>AR列 | P6: 单位手工填写
A7: ='[3]A1 预算指标总览'!$A$3 -> 华东一区 | B7: ='[3]A1 预算指标总览'!$B$3 -> 福建公司 | C7: 损益总表 | D7: 4 | E7: 沉水鱼料 | F7: 取<月度利润表-(行号4）>R列 | G7: 取<月度利润表-(行号4）>AE列 | H7: 取<月度利润表-(行号4）>AR列 | K7: 取<月度利润表-(行号4）>R列 | L7: 取<月度利润表-(行号4）>AE列 | M7: 取<月度利润表-(行号4）>AR列 | P7: 单位手工填写
A8: ='[3]A1 预算指标总览'!$A$3 -> 华东一区 | B8: ='[3]A1 预算指标总览'!$B$3 -> 福建公司 | C8: 损益总表 | D8: 5 | E8: 虾料 | F8: 取<月度利润表-(行号5）>R列 | G8: 取<月度利润表-(行号5）>AE列 | H8: 取<月度利润表-(行号5）>AR列 | K8: 取<月度利润表-(行号5）>R列 | L8: 取<月度利润表-(行号5）>AE列 | M8: 取<月度利润表-(行号5）>AR列 | P8: 单位手工填写
A9: ='[3]A1 预算指标总览'!$A$3 -> 华东一区 | B9: ='[3]A1 预算指标总览'!$B$3 -> 福建公司 | C9: 损益总表 | D9: A1 | E9: 龙虾料 | F9: 取<月度利润表-(行号A1）>R列 | G9: 取<月度利润表-(行号A1）>AE列 | H9: 取<月度利润表-(行号A1）>AR列 | K9: 取<月度利润表-(行号A1）>R列 | L9: 取<月度利润表-(行号A1）>AE列 | M9: 取<月度利润表-(行号A1）>AR列 | P9: 单位手工填写
A10: ='[3]A1 预算指标总览'!$A$3 -> 华东一区 | B10: ='[3]A1 预算指标总览'!$B$3 -> 福建公司 | C10: 损益总表 | D10: 6 | E10: 蟹料 | F10: 取<月度利润表-(行号6）>R列 | G10: 取<月度利润表-(行号6）>AE列 | H10: 取<月度利润表-(行号6）>AR列 | K10: 取<月度利润表-(行号6）>R列 | L10: 取<月度利润表-(行号6）>AE列 | M10: 取<月度利润表-(行号6）>AR列 | P10: 单位手工填写
A11: ='[3]A1 预算指标总览'!$A$3 -> 华东一区 | B11: ='[3]A1 预算指标总览'!$B$3 -> 福建公司 | C11: 损益总表 | D11: 7 | E11: 浓缩/预混料 | F11: 取<月度利润表-(行号7）>R列 | G11: 取<月度利润表-(行号7）>AE列 | H11: 取<月度利润表-(行号7）>AR列 | K11: 取<月度利润表-(行号7）>R列 | L11: 取<月度利润表-(行号7）>AE列 | M11: 取<月度利润表-(行号7）>AR列 | P11: 单位手工填写
A12: ='[3]A1 预算指标总览'!$A$3 -> 华东一区 | B12: ='[3]A1 预算指标总览'!$B$3 -> 福建公司 | C12: 损益总表 | D12: 8 | E12: 猪饲料 | F12: 取<月度利润表-(行号8）>R列 | G12: 取<月度利润表-(行号8）>AE列 | H12: 取<月度利润表-(行号8）>AR列 | K12: 取<月度利润表-(行号8）>R列 | L12: 取<月度利润表-(行号8）>AE列 | M12: 取<月度利润表-(行号8）>AR列 | P12: 单位手工填写
A13: ='[3]A1 预算指标总览'!$A$3 -> 华东一区 | B13: ='[3]A1 预算指标总览'!$B$3 -> 福建公司 | C13: 损益总表 | D13: 9 | E13: 禽料 | F13: 取<月度利润表-(行号9）>R列 | G13: 取<月度利润表-(行号9）>AE列 | H13: 取<月度利润表-(行号9）>AR列 | K13: 取<月度利润表-(行号9）>R列 | L13: 取<月度利润表-(行号9）>AE列 | M13: 取<月度利润表-(行号9）>AR列 | P13: 单位手工填写
A14: ='[3]A1 预算指标总览'!$A$3 -> 华东一区 | B14: ='[3]A1 预算指标总览'!$B$3 -> 福建公司 | C14: 损益总表 | D14: 10 | E14: 反刍料 | F14: 取<月度利润表-(行号10）>R列 | G14: 取<月度利润表-(行号10）>AE列 | H14: 取<月度利润表-(行号10）>AR列 | K14: 取<月度利润表-(行号10）>R列 | L14: 取<月度利润表-(行号10）>AE列 | M14: 取<月度利润表-(行号10）>AR列 | P14: 单位手工填写
A15: ='[3]A1 预算指标总览'!$A$3 -> 华东一区 | B15: ='[3]A1 预算指标总览'!$B$3 -> 福建公司 | C15: 损益总表 | D15: 11 | E15: 销售量合计(吨) | F15: SUM(F4:F13) | G15: SUM(G4:G13) | H15: SUM(H4:H13) | K15: SUM(F4:F13) | L15: SUM(G4:G13) | M15: SUM(H4:H13) | P15: 单位手工填写
A16: ='[3]A1 预算指标总览'!$A$3 -> 华东一区 | B16: ='[3]A1 预算指标总览'!$B$3 -> 福建公司 | C16: 损益总表 | D16: 12 | E16: 一、主营业务收入 | F16: 取<月度利润表-(行号12）>R列 | G16: 计算 | H16: 计算 | K16: 取<月度利润表-(行号12）>R列 | L16: 计算 | M16: 计算 | P16: 单位手工填写
A17: ='[3]A1 预算指标总览'!$A$3 -> 华东一区 | B17: ='[3]A1 预算指标总览'!$B$3 -> 福建公司 | C17: 损益总表 | D17: 13 | E17: 减：主营业务成本 | F17: 取<月度利润表-(行号13）>R列 | G17: 计算 | H17: 计算 | K17: 取<月度利润表-(行号13）>R列 | L17: 计算 | M17: 计算 | P17: 单位手工填写
A18: ='[3]A1 预算指标总览'!$A$3 -> 华东一区 | B18: ='[3]A1 预算指标总览'!$B$3 -> 福建公司 | C18: 损益总表 | D18: 14 | E18: 二、毛利 | F18: =F15-F16 | G18: =G15-G16 | H18: =H15-H16 | K18: =F15-F16 | L18: =G15-G16 | M18: =H15-H16 | P18: 单位手工填写
A19: ='[3]A1 预算指标总览'!$A$3 -> 华东一区 | B19: ='[3]A1 预算指标总览'!$B$3 -> 福建公司 | C19: 损益总表 | D19: 15 | E19: 加：其它业务收入（代加工收入净额） | F19: 取<月度利润表-(行号15）>R列 | G19: 取<月度利润表-(行号15）>AE列 | H19: 取<月度利润表-(行号15）>AR列 | K19: 取<月度利润表-(行号15）>R列 | L19: 取<月度利润表-(行号15）>AE列 | M19: 取<月度利润表-(行号15）>AR列 | P19: 单位手工填写
A20: ='[3]A1 预算指标总览'!$A$3 -> 华东一区 | B20: ='[3]A1 预算指标总览'!$B$3 -> 福建公司 | C20: 损益总表 | D20: 16 | E20: 减：其它业务成本（代加工成本） | F20: 取<月度利润表-(行号16）>R列 | G20: 取<月度利润表-(行号16）>AE列 | H20: 取<月度利润表-(行号16）>AR列 | K20: 取<月度利润表-(行号16）>R列 | L20: 取<月度利润表-(行号16）>AE列 | M20: 取<月度利润表-(行号16）>AR列 | P20: 单位手工填写
A21: ='[3]A1 预算指标总览'!$A$3 -> 华东一区 | B21: ='[3]A1 预算指标总览'!$B$3 -> 福建公司 | C21: 损益总表 | D21: 17 | E21: 加：其它业务收入（外卖原料收益） | F21: 取<月度利润表-(行号17）>R列 | G21: 取<月度利润表-(行号17）>AE列 | H21: 取<月度利润表-(行号17）>AR列 | K21: 取<月度利润表-(行号17）>R列 | L21: 取<月度利润表-(行号17）>AE列 | M21: 取<月度利润表-(行号17）>AR列 | P21: 单位手工填写
... A44: ='[3]A1 预算指标总览'!$A$3 -> 华东一区 | B44: ='[3]A1 预算指标总览'!$B$3 -> 福建公司 | C44: 损益总表 | D44: 40 | E44: 五、净利润 | F44: =F41-F42 | G44: =G41-G42 | H44: =H41-H42 | K44: =F41-F42 | L44: =G41-G42 | M44: =H41-H42 | P44: 单位手工填写
A45: ='[3]A1 预算指标总览'!$A$3 -> 华东一区 | B45: ='[3]A1 预算指标总览'!$B$3 -> 福建公司 | C45: 损益总表 | D45: 41
A46: ='[3]A1 预算指标总览'!$A$3 -> 华东一区 | B46: ='[3]A1 预算指标总览'!$B$3 -> 福建公司 | C46: 损益总表 | D46: 42 | E46: 科目名称
A47: ='[3]A1 预算指标总览'!$A$3 -> 华东一区 | B47: ='[3]A1 预算指标总览'!$B$3 -> 福建公司 | C47: 损益总表 | D47: 43
A48: ='[3]A1 预算指标总览'!$A$3 -> 华东一区 | B48: ='[3]A1 预算指标总览'!$B$3 -> 福建公司 | C48: 损益总表 | D48: 44 | E48: 服务中心费用 | F48: 取<月度利润表-(行号44）>R列 | G48: 取<月度利润表-(行号44）>AE列 | H48: 取<月度利润表-(行号44）>AR列 | K48: 取<月度利润表-(行号44）>R列 | L48: 取<月度利润表-(行号44）>AE列 | M48: 取<月度利润表-(行号44）>AR列 | P48: 单位手工填写 | Q48: 考核调整事项
A49: ='[3]A1 预算指标总览'!$A$3 -> 华东一区 | B49: ='[3]A1 预算指标总览'!$B$3 -> 福建公司 | C49: 损益总表 | D49: 45 | E49: 服务中心费用NC入账额对冲 | F49: 取<月度利润表-(行号45）>R列 | G49: 取<月度利润表-(行号45）>AE列 | H49: 取<月度利润表-(行号45）>AR列 | K49: 取<月度利润表-(行号45）>R列 | L49: 取<月度利润表-(行号45）>AE列 | M49: 取<月度利润表-(行号45）>AR列 | P49: 单位手工填写
A50: ='[3]A1 预算指标总览'!$A$3 -> 华东一区 | B50: ='[3]A1 预算指标总览'!$B$3 -> 福建公司 | C50: 损益总表 | D50: 46 | E50: 资金占用费-应收 | F50: 取<月度利润表-(行号46）>R列 | G50: 取<月度利润表-(行号46）>AE列 | H50: 取<月度利润表-(行号46）>AR列 | K50: 取<月度利润表-(行号46）>R列 | L50: 取<月度利润表-(行号46）>AE列 | M50: 取<月度利润表-(行号46）>AR列 | P50: 单位手工填写
A51: ='[3]A1 预算指标总览'!$A$3 -> 华东一区 | B51: ='[3]A1 预算指标总览'!$B$3 -> 福建公司 | C51: 损益总表 | D51: 47 | E51: 资金占用费-应付 | F51: 取<月度利润表-(行号47）>R列 | G51: 取<月度利润表-(行号47）>AE列 | H51: 取<月度利润表-(行号47）>AR列 | K51: 取<月度利润表-(行号47）>R列 | L51: 取<月度利润表-(行号47）>AE列 | M51: 取<月度利润表-(行号47）>AR列 | P51: 单位手工填写
A52: ='[3]A1 预算指标总览'!$A$3 -> 华东一区 | B52: ='[3]A1 预算指标总览'!$B$3 -> 福建公司 | C52: 损益总表 | D52: 48 | E52: 大区费用分摊 | F52: 取<月度利润表-(行号48）>R列 | G52: 取<月度利润表-(行号48）>AE列 | H52: 取<月度利润表-(行号48）>AR列 | K52: 取<月度利润表-(行号48）>R列 | L52: 取<月度利润表-(行号48）>AE列 | M52: 取<月度利润表-(行号48）>AR列 | P52: 单位手工填写
A53: ='[3]A1 预算指标总览'!$A$3 -> 华东一区 | B53: ='[3]A1 预算指标总览'!$B$3 -> 福建公司 | C53: 损益总表 | D53: 49 | E53: 大区费用NC入账额对冲 | F53: 取<月度利润表-(行号49）>R列 | G53: 取<月度利润表-(行号49）>AE列 | H53: 取<月度利润表-(行号49）>AR列 | K53: 取<月度利润表-(行号49）>R列 | L53: 取<月度利润表-(行号49）>AE列 | M53: 取<月度利润表-(行号49）>AR列 | P53: 单位手工填写
A54: ='[3]A1 预算指标总览'!$A$3 -> 华东一区 | B54: ='[3]A1 预算指标总览'!$B$3 -> 福建公司 | C54: 损益总表 | D54: 50 | E54: 代偿逾期费用 | F54: 取<月度利润表-(行号50）>R列 | G54: 取<月度利润表-(行号50）>AE列 | H54: 取<月度利润表-(行号50）>AR列 | K54: 取<月度利润表-(行号50）>R列 | L54: 取<月度利润表-(行号50）>AE列 | M54: 取<月度利润表-(行号50）>AR列 | P54: 单位手工填写
A55: ='[3]A1 预算指标总览'!$A$3 -> 华东一区 | B55: ='[3]A1 预算指标总览'!$B$3 -> 福建公司 | C55: 损益总表 | D55: 51 | E55: 兄弟公司间的原料买卖收益 | F55: 取<月度利润表-(行号51）>R列 | G55: 取<月度利润表-(行号51）>AE列 | H55: 取<月度利润表-(行号51）>AR列 | K55: 取<月度利润表-(行号51）>R列 | L55: 取<月度利润表-(行号51）>AE列 | M55: 取<月度利润表-(行号51）>AR列 | P55: 单位手工填写
A56: ='[3]A1 预算指标总览'!$A$3 -> 华东一区 | B56: ='[3]A1 预算指标总览'!$B$3 -> 福建公司 | C56: 损益总表 | D56: 52 | E56: 合计 | F56: =F43-F47-F48-F49-F50-F51-F52-F53-F54 | G56: =G43-G47-G48-G49-G50-G51-G52-G53-G54 | H56: =H43-H47-H48-H49-H50-H51-H52-H53-H54 | K56: =F43-F47-F48-F49-F50-F51-F52-F53-F54 | L56: =G43-G47-G48-G49-G50-G51-G52-G53-G54 | M56: =H43-H47-H48-H49-H50-H51-H52-H53-H54 | P56: 单位手工填写
A57: ='[3]A1 预算指标总览'!$A$3 -> 华东一区 | B57: ='[3]A1 预算指标总览'!$B$3 -> 福建公司 | C57: 损益总表 | D57: 53
A58: ='[3]A1 预算指标总览'!$A$3 -> 华东一区 | B58: ='[3]A1 预算指标总览'!$B$3 -> 福建公司 | C58: 损益总表 | D58: 54 | E58: NC利润 | F58: =F55 | G58: =G55 | H58: =H55 | K58: =F55 | L58: =G55 | M58: =H55 | P58: 单位手工填写
A59: ='[3]A1 预算指标总览'!$A$3 -> 华东一区 | B59: ='[3]A1 预算指标总览'!$B$3 -> 福建公司 | C59: 损益总表 | D59: 55

Sheet 5大类量利（查阅）
A1: ← 返回目录
A2: 大区 | B2: 公司 | C2: 大类 | D2: 当月预测值 | K2: 2026年预算值 | R2: 同期值 | Y2: 同比增减 | AF2: 预算差距（预测-预算）
D3: 销量 | E3: 主营业务收入 | F3: 毛利额 | G3: 吨毛利 | H3: 毛利率 | I3: 配销差额 | J3: 吨配销差 | K3: 销量 | L3: 主营业务收入 | M3: 毛利额 | N3: 吨毛利 | O3: 毛利率 | P3: 配销差额 | Q3: 吨配销差 | R3: 销量 | S3: 主营业务收入 | T3: 毛利额 | U3: 吨毛利 | V3: 毛利率 | W3: 配销差额 | X3: 吨配销差 | Y3: 销量 | Z3: 主营业务收入 | AA3: 毛利额 | AB3: 吨毛利 | AC3: 毛利率 | AD3: 配销差额 | AE3: 吨配销差 | AF3: 销量 | AG3: 主营业务收入 | AH3: 毛利额 | AI3: 吨毛利 | AJ3: 毛利率 | AK3: 配销差额 | AL3: 吨配销差
C4: 虾料 | D4: 计算 | E4: 计算 | F4: 计算 | G4: 本表计算 | H4: 本表计算 | K4: 计算 | L4: 计算 | M4: 计算 | N4: 本表计算 | O4: 本表计算 | R4: 计算 | S4: 计算 | T4: 计算 | U4: 本表计算 | V4: 本表计算 | Y4: 本表计算 | Z4: 本表计算 | AA4: 本表计算 | AB4: 本表计算 | AC4: 本表计算 | AF4: 本表计算 | AG4: 本表计算 | AH4: 本表计算 | AI4: 本表计算 | AJ4: 本表计算
C5: 龙虾料 | D5: 计算 | E5: 计算 | F5: 计算 | G5: 本表计算 | H5: 本表计算 | K5: 计算 | L5: 计算 | M5: 计算 | N5: 本表计算 | O5: 本表计算 | R5: 计算 | S5: 计算 | T5: 计算 | U5: 本表计算 | V5: 本表计算 | Y5: 本表计算 | Z5: 本表计算 | AA5: 本表计算 | AB5: 本表计算 | AC5: 本表计算 | AF5: 本表计算 | AG5: 本表计算 | AH5: 本表计算 | AI5: 本表计算 | AJ5: 本表计算
C6: 蟹料 | D6: 计算 | E6: 计算 | F6: 计算 | G6: 本表计算 | H6: 本表计算 | K6: 计算 | L6: 计算 | M6: 计算 | N6: 本表计算 | O6: 本表计算 | R6: 计算 | S6: 计算 | T6: 计算 | U6: 本表计算 | V6: 本表计算 | Y6: 本表计算 | Z6: 本表计算 | AA6: 本表计算 | AB6: 本表计算 | AC6: 本表计算 | AF6: 本表计算 | AG6: 本表计算 | AH6: 本表计算 | AI6: 本表计算 | AJ6: 本表计算
C7: 其中：高价值虾蟹 | D7: 计算 | E7: 计算 | F7: 计算 | G7: 本表计算 | H7: 本表计算 | K7: 计算 | L7: 计算 | M7: 计算 | N7: 本表计算 | O7: 本表计算 | R7: 计算 | S7: 计算 | T7: 计算 | U7: 本表计算 | V7: 本表计算 | Y7: 本表计算 | Z7: 本表计算 | AA7: 本表计算 | AB7: 本表计算 | AC7: 本表计算 | AF7: 本表计算 | AG7: 本表计算 | AH7: 本表计算 | AI7: 本表计算 | AJ7: 本表计算
C8: 普通膨化鱼料 | D8: 计算 | E8: 计算 | F8: 计算 | G8: 本表计算 | H8: 本表计算 | K8: 计算 | L8: 计算 | M8: 计算 | N8: 本表计算 | O8: 本表计算 | R8: 计算 | S8: 计算 | T8: 计算 | U8: 本表计算 | V8: 本表计算 | Y8: 本表计算 | Z8: 本表计算 | AA8: 本表计算 | AB8: 本表计算 | AC8: 本表计算 | AF8: 本表计算 | AG8: 本表计算 | AH8: 本表计算 | AI8: 本表计算 | AJ8: 本表计算
C9: 沉水鱼料 | D9: 计算 | E9: 计算 | F9: 计算 | G9: 本表计算 | H9: 本表计算 | K9: 计算 | L9: 计算 | M9: 计算 | N9: 本表计算 | O9: 本表计算 | R9: 计算 | S9: 计算 | T9: 计算 | U9: 本表计算 | V9: 本表计算 | Y9: 本表计算 | Z9: 本表计算 | AA9: 本表计算 | AB9: 本表计算 | AC9: 本表计算 | AF9: 本表计算 | AG9: 本表计算 | AH9: 本表计算 | AI9: 本表计算 | AJ9: 本表计算
C10: 其中：高价值鱼料 | D10: 计算 | E10: 计算 | F10: 计算 | G10: 本表计算 | H10: 本表计算 | K10: 计算 | L10: 计算 | M10: 计算 | N10: 本表计算 | O10: 本表计算 | R10: 计算 | S10: 计算 | T10: 计算 | U10: 本表计算 | V10: 本表计算 | Y10: 本表计算 | Z10: 本表计算 | AA10: 本表计算 | AB10: 本表计算 | AC10: 本表计算 | AF10: 本表计算 | AG10: 本表计算 | AH10: 本表计算 | AI10: 本表计算 | AJ10: 本表计算
C11: 海特料 | D11: 计算 | E11: 计算 | F11: 计算 | G11: 本表计算 | H11: 本表计算 | K11: 计算 | L11: 计算 | M11: 计算 | N11: 本表计算 | O11: 本表计算 | R11: 计算 | S11: 计算 | T11: 计算 | U11: 本表计算 | V11: 本表计算 | Y11: 本表计算 | Z11: 本表计算 | AA11: 本表计算 | AB11: 本表计算 | AC11: 本表计算 | AF11: 本表计算 | AG11: 本表计算 | AH11: 本表计算 | AI11: 本表计算 | AJ11: 本表计算
C12: 其中：高价值产品 | D12: 计算 | E12: 计算 | F12: 计算 | G12: 本表计算 | H12: 本表计算 | K12: 计算 | L12: 计算 | M12: 计算 | N12: 本表计算 | O12: 本表计算 | R12: 计算 | S12: 计算 | T12: 计算 | U12: 本表计算 | V12: 本表计算 | Y12: 本表计算 | Z12: 本表计算 | AA12: 本表计算 | AB12: 本表计算 | AC12: 本表计算 | AF12: 本表计算 | AG12: 本表计算 | AH12: 本表计算 | AI12: 本表计算 | AJ12: 本表计算
C13: 水产小计 | D13: 本表计算 | E13: 本表计算 | F13: 本表计算 | G13: 本表计算 | H13: 本表计算 | K13: 本表计算 | L13: 本表计算 | M13: 本表计算 | N13: 本表计算 | O13: 本表计算 | R13: 本表计算 | S13: 本表计算 | T13: 本表计算 | U13: 本表计算 | V13: 本表计算 | Y13: 本表计算 | Z13: 本表计算 | AA13: 本表计算 | AB13: 本表计算 | AC13: 本表计算 | AF13: 本表计算 | AG13: 本表计算 | AH13: 本表计算 | AI13: 本表计算 | AJ13: 本表计算
C14: 猪饲料 | D14: 计算 | E14: 计算 | F14: 计算 | G14: 本表计算 | H14: 本表计算 | K14: 计算 | L14: 计算 | M14: 计算 | N14: 本表计算 | O14: 本表计算 | R14: 计算 | S14: 计算 | T14: 计算 | U14: 本表计算 | V14: 本表计算 | Y14: 本表计算 | Z14: 本表计算 | AA14: 本表计算 | AB14: 本表计算 | AC14: 本表计算 | AF14: 本表计算 | AG14: 本表计算 | AH14: 本表计算 | AI14: 本表计算 | AJ14: 本表计算
C15: 浓缩/预混料 | D15: 计算 | E15: 计算 | F15: 计算 | G15: 本表计算 | H15: 本表计算 | K15: 计算 | L15: 计算 | M15: 计算 | N15: 本表计算 | O15: 本表计算 | R15: 计算 | S15: 计算 | T15: 计算 | U15: 本表计算 | V15: 本表计算 | Y15: 本表计算 | Z15: 本表计算 | AA15: 本表计算 | AB15: 本表计算 | AC15: 本表计算 | AF15: 本表计算 | AG15: 本表计算 | AH15: 本表计算 | AI15: 本表计算 | AJ15: 本表计算
... C23: 其中：高价值占比 | D23: 本表计算 | E23: 本表计算 | F23: 本表计算 | G23: 本表计算 | H23: 本表计算 | K23: 本表计算 | L23: 本表计算 | M23: 本表计算 | N23: 本表计算 | O23: 本表计算 | R23: 本表计算 | S23: 本表计算 | T23: 本表计算 | U23: 本表计算 | V23: 本表计算 | Y23: 本表计算 | Z23: 本表计算 | AA23: 本表计算 | AB23: 本表计算 | AC23: 本表计算 | AF23: 本表计算 | AG23: 本表计算 | AH23: 本表计算 | AI23: 本表计算 | AJ23: 本表计算

Sheet 6大类小类量利（查阅）
A1: ← 返回目录
B2: 大区 | C2: 公司 | D2: 大类 | E2: 小类 | F2: 2026年预测 | K2: 2026年预算 | P2: 同期值 | U2: 同比增减 | Z2: 预算差距（预测-预算）
F3: 销量 | G3: 毛利额 | H3: 吨毛利 | I3: 配销差额 | J3: 吨配销差 | K3: 销量 | L3: 毛利额 | M3: 吨毛利 | N3: 配销差额 | O3: 吨配销差 | P3: 销量 | Q3: 毛利额 | R3: 吨毛利 | S3: 配销差额 | T3: 吨配销差 | U3: 销量 | V3: 毛利额 | W3: 吨毛利 | X3: 配销差额 | Y3: 吨配销差 | Z3: 销量 | AA3: 毛利额 | AB3: 吨毛利 | AC3: 配销差额 | AD3: 吨配销差
D4: 海特料 | E4: 大黄鱼料 | F4: 计算 | G4: 计算 | H4: 本表计算 | K4: 计算 | L4: 计算 | M4: 本表计算 | P4: 计算 | Q4: 计算 | R4: 本表计算 | U4: 本表计算 | V4: 本表计算 | W4: 本表计算 | Z4: 本表计算 | AA4: 本表计算 | AB4: 本表计算
E5: 石斑鱼料 | F5: 计算 | G5: 计算 | H5: 本表计算 | K5: 计算 | L5: 计算 | M5: 本表计算 | P5: 计算 | Q5: 计算 | R5: 本表计算 | U5: 本表计算 | V5: 本表计算 | W5: 本表计算 | Z5: 本表计算 | AA5: 本表计算 | AB5: 本表计算
F6: 计算 | G6: 计算 | H6: 本表计算 | K6: 计算 | L6: 计算 | M6: 本表计算 | P6: 计算 | Q6: 计算 | R6: 本表计算 | U6: 本表计算 | V6: 本表计算 | W6: 本表计算 | Z6: 本表计算 | AA6: 本表计算 | AB6: 本表计算 | AE6: =D6&E6
F7: 计算 | G7: 计算 | H7: 本表计算 | K7: 计算 | L7: 计算 | M7: 本表计算 | P7: 计算 | Q7: 计算 | R7: 本表计算 | U7: 本表计算 | V7: 本表计算 | W7: 本表计算 | Z7: 本表计算 | AA7: 本表计算 | AB7: 本表计算 | AE7: =D7&E7
F8: 计算 | G8: 计算 | H8: 本表计算 | K8: 计算 | L8: 计算 | M8: 本表计算 | P8: 计算 | Q8: 计算 | R8: 本表计算 | U8: 本表计算 | V8: 本表计算 | W8: 本表计算 | Z8: 本表计算 | AA8: 本表计算 | AB8: 本表计算 | AE8: =D8&E8
F9: 计算 | G9: 计算 | H9: 本表计算 | K9: 计算 | L9: 计算 | M9: 本表计算 | P9: 计算 | Q9: 计算 | R9: 本表计算 | U9: 本表计算 | V9: 本表计算 | W9: 本表计算 | Z9: 本表计算 | AA9: 本表计算 | AB9: 本表计算 | AE9: =D9&E9
F10: 计算 | G10: 计算 | H10: 本表计算 | K10: 计算 | L10: 计算 | M10: 本表计算 | P10: 计算 | Q10: 计算 | R10: 本表计算 | U10: 本表计算 | V10: 本表计算 | W10: 本表计算 | Z10: 本表计算 | AA10: 本表计算 | AB10: 本表计算 | AE10: =D10&E10
F11: 计算 | G11: 计算 | H11: 本表计算 | K11: 计算 | L11: 计算 | M11: 本表计算 | P11: 计算 | Q11: 计算 | R11: 本表计算 | U11: 本表计算 | V11: 本表计算 | W11: 本表计算 | Z11: 本表计算 | AA11: 本表计算 | AB11: 本表计算 | AE11: =D11&E11
F12: 计算 | G12: 计算 | H12: 本表计算 | K12: 计算 | L12: 计算 | M12: 本表计算 | P12: 计算 | Q12: 计算 | R12: 本表计算 | U12: 本表计算 | V12: 本表计算 | W12: 本表计算 | Z12: 本表计算 | AA12: 本表计算 | AB12: 本表计算 | AE12: =D12&E12
F13: 计算 | G13: 计算 | H13: 本表计算 | K13: 计算 | L13: 计算 | M13: 本表计算 | P13: 计算 | Q13: 计算 | R13: 本表计算 | U13: 本表计算 | V13: 本表计算 | W13: 本表计算 | Z13: 本表计算 | AA13: 本表计算 | AB13: 本表计算 | AE13: =D13&E13
F14: 计算 | G14: 计算 | H14: 本表计算 | K14: 计算 | L14: 计算 | M14: 本表计算 | P14: 计算 | Q14: 计算 | R14: 本表计算 | U14: 本表计算 | V14: 本表计算 | W14: 本表计算 | Z14: 本表计算 | AA14: 本表计算 | AB14: 本表计算 | AE14: =D14&E14
F15: 计算 | G15: 计算 | H15: 本表计算 | K15: 计算 | L15: 计算 | M15: 本表计算 | P15: 计算 | Q15: 计算 | R15: 本表计算 | U15: 本表计算 | V15: 本表计算 | W15: 本表计算 | Z15: 本表计算 | AA15: 本表计算 | AB15: 本表计算 | AE15: =D15&E15
F16: 计算 | G16: 计算 | H16: 本表计算 | K16: 计算 | L16: 计算 | M16: 本表计算 | P16: 计算 | Q16: 计算 | R16: 本表计算 | U16: 本表计算 | V16: 本表计算 | W16: 本表计算 | Z16: 本表计算 | AA16: 本表计算 | AB16: 本表计算 | AE16: =D16&E16
F17: 计算 | G17: 计算 | H17: 本表计算 | K17: 计算 | L17: 计算 | M17: 本表计算 | P17: 计算 | Q17: 计算 | R17: 本表计算 | U17: 本表计算 | V17: 本表计算 | W17: 本表计算 | Z17: 本表计算 | AA17: 本表计算 | AB17: 本表计算 | AE17: =D17&E17
... F19: 计算 | G19: 计算 | H19: 本表计算 | K19: 计算 | L19: 计算 | M19: 本表计算 | P19: 计算 | Q19: 计算 | R19: 本表计算 | U19: 本表计算 | V19: 本表计算 | W19: 本表计算 | Z19: 本表计算 | AA19: 本表计算 | AB19: 本表计算 | AE19: =D19&E19
F20: 计算 | G20: 计算 | H20: 本表计算 | K20: 计算 | L20: 计算 | M20: 本表计算 | P20: 计算 | Q20: 计算 | R20: 本表计算 | U20: 本表计算 | V20: 本表计算 | W20: 本表计算 | Z20: 本表计算 | AA20: 本表计算 | AB20: 本表计算
F21: 计算 | G21: 计算 | H21: 本表计算 | K21: 计算 | L21: 计算 | M21: 本表计算 | P21: 计算 | Q21: 计算 | R21: 本表计算 | U21: 本表计算 | V21: 本表计算 | W21: 本表计算 | Z21: 本表计算 | AA21: 本表计算 | AB21: 本表计算
F22: 计算 | G22: 计算 | H22: 本表计算 | K22: 计算 | L22: 计算 | M22: 本表计算 | P22: 计算 | Q22: 计算 | R22: 本表计算 | U22: 本表计算 | V22: 本表计算 | W22: 本表计算 | Z22: 本表计算 | AA22: 本表计算 | AB22: 本表计算
F23: 计算 | G23: 计算 | H23: 本表计算 | K23: 计算 | L23: 计算 | M23: 本表计算 | P23: 计算 | Q23: 计算 | R23: 本表计算 | U23: 本表计算 | V23: 本表计算 | W23: 本表计算 | Z23: 本表计算 | AA23: 本表计算 | AB23: 本表计算 | AE23: =D23&E23
F24: 计算 | G24: 计算 | H24: 本表计算 | K24: 计算 | L24: 计算 | M24: 本表计算 | P24: 计算 | Q24: 计算 | R24: 本表计算 | U24: 本表计算 | V24: 本表计算 | W24: 本表计算 | Z24: 本表计算 | AA24: 本表计算 | AB24: 本表计算 | AE24: =D24&E24

Sheet 7客户产品毛利表（外销）
A1: ← 返回目录 | B1: 任务名称： | C1: 1.1销量预算表_编制
B2: 年份： | C2: 2026 | D2: 月份： | E2: 01,02,03
B3: 版本类型： | C3: 年度
B4: 版本： | C4: v1
B5: 业务单元： | C5: 江门澳华
A7: 版本 | B7: 大区 | C7: 公司 | D7: 区域/聚焦镇 | E7: 客户编码 | F7: 客户 | G7: 是否大客户 | H7: 产品系列编码 | I7: 产品系列名称 | J7: 大类 | K7: 小类 | L7: 战略产品 | M7: 销售吨位 | N7: 赠送吨位 | O7: 单吨售价 | P7: 售价总额 | Q7: 单吨折扣 | R7: 折扣总额 | S7: 单吨净收 | T7: 销售净收入额 | U7: 销售成本 | V7: 单吨销售成本 | W7: 赠送成本 | X7: 单吨配方成本 | Y7: 单吨配销差 | Z7: 配销差总额 | AA7: 单吨毛利 | AB7: 销售总毛利 | AC7: 销售费用额 | AD7: 销售净贡献
A8: V1 | B8: 华南大区 | C8: 江门澳华 | H8: JK001 | I8: 虾安康 | J8: 虾蟹线 | K8: 虾料 | L8: 高价值
D9: 自动生成 | E9: 自动生成 | F9: 自动生成 | G9: 自动生成 | H9: 自动生成 | I9: 自动生成 | J9: 自动生成 | K9: 自动生成 | L9: 自动生成 | M9: 计算 | N9: 计算 | O9: 计算 | P9: 计算 | Q9: 计算 | R9: 计算 | S9: 计算 | T9: 计算 | U9: 计算 | V9: 计算 | W9: 计算 | X9: 计算 | Y9: 计算 | Z9: 计算 | AA9: 计算 | AB9: 计算 | AC9: 计算 | AD9: 计算

Sheet 8动保产品大类毛利
A1: ← 返回目录
A3: 大类 | B3: 产品系列 | C3: 预测值 | G3: 预算值 | K3: 同期值 | O3: 同比增减 | S3: 预算差额（预测-预算）
C5: 销售额 | D5: 生产成本 | E5: 毛利额 | F5: 毛利率 | G5: 销售额 | H5: 生产成本 | I5: 毛利额 | J5: 毛利率 | K5: 销售额 | L5: 生产成本 | M5: 毛利额 | N5: 毛利率 | O5: 销售额 | P5: 生产成本 | Q5: 毛利额 | R5: 毛利率 | S5: 销售额 | T5: 生产成本 | U5: 毛利额 | V5: 毛利率
A6: 软颗粒 | B6: 肽康宝 | C6: 计算 | D6: 计算 | E6: 计算 | F6: 本表计算 | G6: 自动生成 | H6: 自动生成 | I6: 自动生成 | J6: 自动生成 | K6: 自动生成 | L6: 自动生成 | M6: 自动生成 | N6: 自动生成 | O6: 本表计算 | P6: 本表计算 | Q6: 本表计算 | R6: 本表计算 | S6: 本表计算 | T6: 本表计算 | U6: 本表计算 | V6: 本表计算
B7: 虾酸奶 | C7: 计算 | D7: 计算 | E7: 计算 | F7: 本表计算 | G7: 自动生成 | H7: 自动生成 | I7: 自动生成 | J7: 自动生成 | K7: 自动生成 | L7: 自动生成 | M7: 自动生成 | N7: 自动生成 | O7: 本表计算 | P7: 本表计算 | Q7: 本表计算 | R7: 本表计算 | S7: 本表计算 | T7: 本表计算 | U7: 本表计算 | V7: 本表计算
C8: 计算 | D8: 计算 | E8: 计算 | F8: 本表计算 | G8: 自动生成 | H8: 自动生成 | I8: 自动生成 | J8: 自动生成 | K8: 自动生成 | L8: 自动生成 | M8: 自动生成 | N8: 自动生成 | O8: 本表计算 | P8: 本表计算 | Q8: 本表计算 | R8: 本表计算 | S8: 本表计算 | T8: 本表计算 | U8: 本表计算 | V8: 本表计算
C9: 计算 | D9: 计算 | E9: 计算 | F9: 本表计算 | G9: 自动生成 | H9: 自动生成 | I9: 自动生成 | J9: 自动生成 | K9: 自动生成 | L9: 自动生成 | M9: 自动生成 | N9: 自动生成 | O9: 本表计算 | P9: 本表计算 | Q9: 本表计算 | R9: 本表计算 | S9: 本表计算 | T9: 本表计算 | U9: 本表计算 | V9: 本表计算
C10: 计算 | D10: 计算 | E10: 计算 | F10: 本表计算 | G10: 自动生成 | H10: 自动生成 | I10: 自动生成 | J10: 自动生成 | K10: 自动生成 | L10: 自动生成 | M10: 自动生成 | N10: 自动生成 | O10: 本表计算 | P10: 本表计算 | Q10: 本表计算 | R10: 本表计算 | S10: 本表计算 | T10: 本表计算 | U10: 本表计算 | V10: 本表计算
C11: 计算 | D11: 计算 | E11: 计算 | F11: 本表计算 | G11: 自动生成 | H11: 自动生成 | I11: 自动生成 | J11: 自动生成 | K11: 自动生成 | L11: 自动生成 | M11: 自动生成 | N11: 自动生成 | O11: 本表计算 | P11: 本表计算 | Q11: 本表计算 | R11: 本表计算 | S11: 本表计算 | T11: 本表计算 | U11: 本表计算 | V11: 本表计算
C12: 计算 | D12: 计算 | E12: 计算 | F12: 本表计算 | G12: 自动生成 | H12: 自动生成 | I12: 自动生成 | J12: 自动生成 | K12: 自动生成 | L12: 自动生成 | M12: 自动生成 | N12: 自动生成 | O12: 本表计算 | P12: 本表计算 | Q12: 本表计算 | R12: 本表计算 | S12: 本表计算 | T12: 本表计算 | U12: 本表计算 | V12: 本表计算
C13: 计算 | D13: 计算 | E13: 计算 | F13: 本表计算 | G13: 自动生成 | H13: 自动生成 | I13: 自动生成 | J13: 自动生成 | K13: 自动生成 | L13: 自动生成 | M13: 自动生成 | N13: 自动生成 | O13: 本表计算 | P13: 本表计算 | Q13: 本表计算 | R13: 本表计算 | S13: 本表计算 | T13: 本表计算 | U13: 本表计算 | V13: 本表计算
C14: 计算 | D14: 计算 | E14: 计算 | F14: 本表计算 | G14: 自动生成 | H14: 自动生成 | I14: 自动生成 | J14: 自动生成 | K14: 自动生成 | L14: 自动生成 | M14: 自动生成 | N14: 自动生成 | O14: 本表计算 | P14: 本表计算 | Q14: 本表计算 | R14: 本表计算 | S14: 本表计算 | T14: 本表计算 | U14: 本表计算 | V14: 本表计算
C15: 计算 | D15: 计算 | E15: 计算 | F15: 本表计算 | G15: 自动生成 | H15: 自动生成 | I15: 自动生成 | J15: 自动生成 | K15: 自动生成 | L15: 自动生成 | M15: 自动生成 | N15: 自动生成 | O15: 本表计算 | P15: 本表计算 | Q15: 本表计算 | R15: 本表计算 | S15: 本表计算 | T15: 本表计算 | U15: 本表计算 | V15: 本表计算
C16: 计算 | D16: 计算 | E16: 计算 | F16: 本表计算 | G16: 自动生成 | H16: 自动生成 | I16: 自动生成 | J16: 自动生成 | K16: 自动生成 | L16: 自动生成 | M16: 自动生成 | N16: 自动生成 | O16: 本表计算 | P16: 本表计算 | Q16: 本表计算 | R16: 本表计算 | S16: 本表计算 | T16: 本表计算 | U16: 本表计算 | V16: 本表计算
C17: 计算 | D17: 计算 | E17: 计算 | F17: 本表计算 | G17: 自动生成 | H17: 自动生成 | I17: 自动生成 | J17: 自动生成 | K17: 自动生成 | L17: 自动生成 | M17: 自动生成 | N17: 自动生成 | O17: 本表计算 | P17: 本表计算 | Q17: 本表计算 | R17: 本表计算 | S17: 本表计算 | T17: 本表计算 | U17: 本表计算 | V17: 本表计算
C18: 计算 | D18: 计算 | E18: 计算 | F18: 本表计算 | G18: 自动生成 | H18: 自动生成 | I18: 自动生成 | J18: 自动生成 | K18: 自动生成 | L18: 自动生成 | M18: 自动生成 | N18: 自动生成 | O18: 本表计算 | P18: 本表计算 | Q18: 本表计算 | R18: 本表计算 | S18: 本表计算 | T18: 本表计算 | U18: 本表计算 | V18: 本表计算
C19: 计算 | D19: 计算 | E19: 计算 | F19: 本表计算 | G19: 自动生成 | H19: 自动生成 | I19: 自动生成 | J19: 自动生成 | K19: 自动生成 | L19: 自动生成 | M19: 自动生成 | N19: 自动生成 | O19: 本表计算 | P19: 本表计算 | Q19: 本表计算 | R19: 本表计算 | S19: 本表计算 | T19: 本表计算 | U19: 本表计算 | V19: 本表计算
... C30: 计算 | D30: 计算 | E30: 计算 | F30: 本表计算 | G30: 自动生成 | H30: 自动生成 | I30: 自动生成 | J30: 自动生成 | K30: 自动生成 | L30: 自动生成 | M30: 自动生成 | N30: 自动生成 | O30: 本表计算 | P30: 本表计算 | Q30: 本表计算 | R30: 本表计算 | S30: 本表计算 | T30: 本表计算 | U30: 本表计算 | V30: 本表计算

Sheet 9产品生产成本（类别）
A1: ← 返回目录 | B1: 公司 | C1: 大类 | D1: 小类 | E1: 2026年预测 | L1: 2026年预算值 | S1: 同期值 | Z1: 同比增减 | AG1: 预算差距（预测-预算）
E2: 单吨配方成本 | F2: 单吨包装物 | G2: 单吨制造费用 | H2: 其中：单吨燃动 | I2: 其中：单吨人工 | J2: 其中：单吨其他变动费用 | K2: 其中：单吨固定制造费用 | L2: 单吨配方成本 | M2: 单吨包装物 | N2: 单吨制造费用 | O2: 其中：单吨燃动 | P2: 其中：单吨人工 | Q2: 其中：单吨其他变动费用 | R2: 其中：单吨固定制造费用 | S2: 单吨配方成本 | T2: 单吨包装物 | U2: 单吨制造费用 | V2: 其中：单吨燃动 | W2: 其中：单吨人工 | X2: 其中：单吨其他变动费用 | Y2: 其中：单吨固定制造费用 | Z2: 单吨配方成本 | AA2: 单吨包装物 | AB2: 单吨制造费用 | AC2: 其中：单吨燃动 | AD2: 其中：单吨人工 | AE2: 其中：单吨其他变动费用 | AF2: 其中：单吨固定制造费用 | AG2: 单吨配方成本 | AH2: 单吨包装物 | AI2: 单吨制造费用 | AJ2: 其中：单吨燃动 | AK2: 其中：单吨人工 | AL2: 其中：单吨其他变动费用 | AM2: 其中：单吨固定制造费用
C3: 海特料 | D3: 大黄鱼料 | E3: 计算 | F3: 计算 | G3: 本表计算 | L3: 自动生成 | M3: 自动生成 | N3: 自动生成 | S3: 自动生成 | T3: 自动生成 | U3: 自动生成 | Z3: 本表计算 | AA3: 本表计算 | AB3: 本表计算 | AG3: 本表计算 | AH3: 本表计算 | AI3: 本表计算
D4: 石斑鱼料 | E4: 计算 | F4: 计算 | G4: 本表计算 | L4: 自动生成 | M4: 自动生成 | N4: 自动生成 | S4: 自动生成 | T4: 自动生成 | U4: 自动生成 | Z4: 本表计算 | AA4: 本表计算 | AB4: 本表计算 | AG4: 本表计算 | AH4: 本表计算 | AI4: 本表计算
E5: 计算 | F5: 计算 | G5: 本表计算 | L5: 自动生成 | M5: 自动生成 | N5: 自动生成 | S5: 自动生成 | T5: 自动生成 | U5: 自动生成 | Z5: 本表计算 | AA5: 本表计算 | AB5: 本表计算 | AG5: 本表计算 | AH5: 本表计算 | AI5: 本表计算
E6: 计算 | F6: 计算 | G6: 本表计算 | L6: 自动生成 | M6: 自动生成 | N6: 自动生成 | S6: 自动生成 | T6: 自动生成 | U6: 自动生成 | Z6: 本表计算 | AA6: 本表计算 | AB6: 本表计算 | AG6: 本表计算 | AH6: 本表计算 | AI6: 本表计算
E7: 计算 | F7: 计算 | G7: 本表计算 | L7: 自动生成 | M7: 自动生成 | N7: 自动生成 | S7: 自动生成 | T7: 自动生成 | U7: 自动生成 | Z7: 本表计算 | AA7: 本表计算 | AB7: 本表计算 | AG7: 本表计算 | AH7: 本表计算 | AI7: 本表计算
E8: 计算 | F8: 计算 | G8: 本表计算 | L8: 自动生成 | M8: 自动生成 | N8: 自动生成 | S8: 自动生成 | T8: 自动生成 | U8: 自动生成 | Z8: 本表计算 | AA8: 本表计算 | AB8: 本表计算 | AG8: 本表计算 | AH8: 本表计算 | AI8: 本表计算
E9: 计算 | F9: 计算 | G9: 本表计算 | L9: 自动生成 | M9: 自动生成 | N9: 自动生成 | S9: 自动生成 | T9: 自动生成 | U9: 自动生成 | Z9: 本表计算 | AA9: 本表计算 | AB9: 本表计算 | AG9: 本表计算 | AH9: 本表计算 | AI9: 本表计算
E10: 计算 | F10: 计算 | G10: 本表计算 | L10: 自动生成 | M10: 自动生成 | N10: 自动生成 | S10: 自动生成 | T10: 自动生成 | U10: 自动生成 | Z10: 本表计算 | AA10: 本表计算 | AB10: 本表计算 | AG10: 本表计算 | AH10: 本表计算 | AI10: 本表计算
E11: 计算 | F11: 计算 | G11: 本表计算 | L11: 自动生成 | M11: 自动生成 | N11: 自动生成 | S11: 自动生成 | T11: 自动生成 | U11: 自动生成 | Z11: 本表计算 | AA11: 本表计算 | AB11: 本表计算 | AG11: 本表计算 | AH11: 本表计算 | AI11: 本表计算
E12: 计算 | F12: 计算 | G12: 本表计算 | L12: 自动生成 | M12: 自动生成 | N12: 自动生成 | S12: 自动生成 | T12: 自动生成 | U12: 自动生成 | Z12: 本表计算 | AA12: 本表计算 | AB12: 本表计算 | AG12: 本表计算 | AH12: 本表计算 | AI12: 本表计算
E13: 计算 | F13: 计算 | G13: 本表计算 | L13: 自动生成 | M13: 自动生成 | N13: 自动生成 | S13: 自动生成 | T13: 自动生成 | U13: 自动生成 | Z13: 本表计算 | AA13: 本表计算 | AB13: 本表计算 | AG13: 本表计算 | AH13: 本表计算 | AI13: 本表计算
E14: 计算 | F14: 计算 | G14: 本表计算 | L14: 自动生成 | M14: 自动生成 | N14: 自动生成 | S14: 自动生成 | T14: 自动生成 | U14: 自动生成 | Z14: 本表计算 | AA14: 本表计算 | AB14: 本表计算 | AG14: 本表计算 | AH14: 本表计算 | AI14: 本表计算
E15: 计算 | F15: 计算 | G15: 本表计算 | L15: 自动生成 | M15: 自动生成 | N15: 自动生成 | S15: 自动生成 | T15: 自动生成 | U15: 自动生成 | Z15: 本表计算 | AA15: 本表计算 | AB15: 本表计算 | AG15: 本表计算 | AH15: 本表计算 | AI15: 本表计算
E16: 计算 | F16: 计算 | G16: 本表计算 | L16: 自动生成 | M16: 自动生成 | N16: 自动生成 | S16: 自动生成 | T16: 自动生成 | U16: 自动生成 | Z16: 本表计算 | AA16: 本表计算 | AB16: 本表计算 | AG16: 本表计算 | AH16: 本表计算 | AI16: 本表计算
... E23: 计算 | F23: 计算 | G23: 本表计算 | L23: 自动生成 | M23: 自动生成 | N23: 自动生成 | S23: 自动生成 | T23: 自动生成 | U23: 自动生成 | Z23: 本表计算 | AA23: 本表计算 | AB23: 本表计算 | AG23: 本表计算 | AH23: 本表计算 | AI23: 本表计算

Sheet 10产品生产成本（品系）
A1: ← 返回目录 | B1: 公司 | C1: 大类 | D1: 小类 | E1: 产品系列编码 | F1: 产品系列 | G1: 产量 | H1: 2026年预测 | O1: 2026年预算值 | V1: 同期值 | AC1: 同比增减 | AJ1: 预算差距（预测-预算）
H2: 单吨配方成本 | I2: 单吨包装物 | J2: 单吨制造费用 | K2: 其中：单吨燃动 | L2: 其中：单吨人工 | M2: 其中：单吨其他变动费用 | N2: 其中：单吨固定制造费用 | O2: 单吨配方成本 | P2: 单吨包装物 | Q2: 单吨制造费用 | R2: 其中：单吨燃动 | S2: 其中：单吨人工 | T2: 其中：单吨其他变动费用 | U2: 其中：单吨固定制造费用 | V2: 单吨配方成本 | W2: 单吨包装物 | X2: 单吨制造费用 | Y2: 其中：单吨燃动 | Z2: 其中：单吨人工 | AA2: 其中：单吨其他变动费用 | AB2: 其中：单吨固定制造费用 | AC2: 单吨配方成本 | AD2: 单吨包装物 | AE2: 单吨制造费用 | AF2: 其中：单吨燃动 | AG2: 其中：单吨人工 | AH2: 其中：单吨其他变动费用 | AI2: 其中：单吨固定制造费用 | AJ2: 单吨配方成本 | AK2: 单吨包装物 | AL2: 单吨制造费用 | AM2: 其中：单吨燃动 | AN2: 其中：单吨人工 | AO2: 其中：单吨其他变动费用 | AP2: 其中：单吨固定制造费用
C3: 海特料 | D3: 大黄鱼料 | H3: 计算 | I3: 计算 | J3: 本表计算 | O3: 自动生成 | P3: 自动生成 | Q3: 自动生成 | V3: 自动生成 | W3: 自动生成 | X3: 自动生成 | AC3: 本表计算 | AD3: 本表计算 | AE3: 本表计算 | AJ3: 本表计算 | AK3: 本表计算 | AL3: 本表计算
D4: 石斑鱼料 | H4: 计算 | I4: 计算 | J4: 本表计算 | O4: 自动生成 | P4: 自动生成 | Q4: 自动生成 | V4: 自动生成 | W4: 自动生成 | X4: 自动生成 | AC4: 本表计算 | AD4: 本表计算 | AE4: 本表计算 | AJ4: 本表计算 | AK4: 本表计算 | AL4: 本表计算
H5: 计算 | I5: 计算 | J5: 本表计算 | O5: 自动生成 | P5: 自动生成 | Q5: 自动生成 | V5: 自动生成 | W5: 自动生成 | X5: 自动生成 | AC5: 本表计算 | AD5: 本表计算 | AE5: 本表计算 | AJ5: 本表计算 | AK5: 本表计算 | AL5: 本表计算
H6: 计算 | I6: 计算 | J6: 本表计算 | O6: 自动生成 | P6: 自动生成 | Q6: 自动生成 | V6: 自动生成 | W6: 自动生成 | X6: 自动生成 | AC6: 本表计算 | AD6: 本表计算 | AE6: 本表计算 | AJ6: 本表计算 | AK6: 本表计算 | AL6: 本表计算
H7: 计算 | I7: 计算 | J7: 本表计算 | O7: 自动生成 | P7: 自动生成 | Q7: 自动生成 | V7: 自动生成 | W7: 自动生成 | X7: 自动生成 | AC7: 本表计算 | AD7: 本表计算 | AE7: 本表计算 | AJ7: 本表计算 | AK7: 本表计算 | AL7: 本表计算
H8: 计算 | I8: 计算 | J8: 本表计算 | O8: 自动生成 | P8: 自动生成 | Q8: 自动生成 | V8: 自动生成 | W8: 自动生成 | X8: 自动生成 | AC8: 本表计算 | AD8: 本表计算 | AE8: 本表计算 | AJ8: 本表计算 | AK8: 本表计算 | AL8: 本表计算
H9: 计算 | I9: 计算 | J9: 本表计算 | O9: 自动生成 | P9: 自动生成 | Q9: 自动生成 | V9: 自动生成 | W9: 自动生成 | X9: 自动生成 | AC9: 本表计算 | AD9: 本表计算 | AE9: 本表计算 | AJ9: 本表计算 | AK9: 本表计算 | AL9: 本表计算
H10: 计算 | I10: 计算 | J10: 本表计算 | O10: 自动生成 | P10: 自动生成 | Q10: 自动生成 | V10: 自动生成 | W10: 自动生成 | X10: 自动生成 | AC10: 本表计算 | AD10: 本表计算 | AE10: 本表计算 | AJ10: 本表计算 | AK10: 本表计算 | AL10: 本表计算
H11: 计算 | I11: 计算 | J11: 本表计算 | O11: 自动生成 | P11: 自动生成 | Q11: 自动生成 | V11: 自动生成 | W11: 自动生成 | X11: 自动生成 | AC11: 本表计算 | AD11: 本表计算 | AE11: 本表计算 | AJ11: 本表计算 | AK11: 本表计算 | AL11: 本表计算
H12: 计算 | I12: 计算 | J12: 本表计算 | O12: 自动生成 | P12: 自动生成 | Q12: 自动生成 | V12: 自动生成 | W12: 自动生成 | X12: 自动生成 | AC12: 本表计算 | AD12: 本表计算 | AE12: 本表计算 | AJ12: 本表计算 | AK12: 本表计算 | AL12: 本表计算
H13: 计算 | I13: 计算 | J13: 本表计算 | O13: 自动生成 | P13: 自动生成 | Q13: 自动生成 | V13: 自动生成 | W13: 自动生成 | X13: 自动生成 | AC13: 本表计算 | AD13: 本表计算 | AE13: 本表计算 | AJ13: 本表计算 | AK13: 本表计算 | AL13: 本表计算
H14: 计算 | I14: 计算 | J14: 本表计算 | O14: 自动生成 | P14: 自动生成 | Q14: 自动生成 | V14: 自动生成 | W14: 自动生成 | X14: 自动生成 | AC14: 本表计算 | AD14: 本表计算 | AE14: 本表计算 | AJ14: 本表计算 | AK14: 本表计算 | AL14: 本表计算
H15: 计算 | I15: 计算 | J15: 本表计算 | O15: 自动生成 | P15: 自动生成 | Q15: 自动生成 | V15: 自动生成 | W15: 自动生成 | X15: 自动生成 | AC15: 本表计算 | AD15: 本表计算 | AE15: 本表计算 | AJ15: 本表计算 | AK15: 本表计算 | AL15: 本表计算
H16: 计算 | I16: 计算 | J16: 本表计算 | O16: 自动生成 | P16: 自动生成 | Q16: 自动生成 | V16: 自动生成 | W16: 自动生成 | X16: 自动生成 | AC16: 本表计算 | AD16: 本表计算 | AE16: 本表计算 | AJ16: 本表计算 | AK16: 本表计算 | AL16: 本表计算
... H23: 计算 | I23: 计算 | J23: 本表计算 | O23: 自动生成 | P23: 自动生成 | Q23: 自动生成 | V23: 自动生成 | W23: 自动生成 | X23: 自动生成 | AC23: 本表计算 | AD23: 本表计算 | AE23: 本表计算 | AJ23: 本表计算 | AK23: 本表计算 | AL23: 本表计算

Sheet 11包材成本-采购、财务
A1: ← 返回目录 | E1: 填录说明： 第一步，选择年、公司、版本、场景； 第二步，下拉选择产品系列； 第三步，分月填录单吨包装物成本数据； 第四步，填制数据完成后，单击【提交】按钮，将数据提交至系统。 单位：元/吨
A5: 责任部门：采购部、财务部
A7: 年 | B7: 2026年 | C7: 公司 | D7: xx澳华 | E7: 版本 | F7: V1 | G7: 场景 | H7: 月度
A8: 单吨包材费预测值=上期单吨包材实际费
A9: 大类 | B9: 小类 | C9: 产品系列编码 | D9: 产品系列 | E9: 单吨包材费预测值 | F9: 单吨包材费预算值 | G9: 单吨包材费同期值 | H9: 同比增减 | I9: 预算差 | J9: 备注
A10: 自动生成 | B10: 自动生成 | C10: 自动生成 | D10: 自动生成 | E10: 自动生成 | F10: 自动生成 | G10: 自动生成 | H10: 计算 | I10: 计算
E11: 自动生成 | F11: 自动生成 | G11: 自动生成 | H11: 计算 | I11: 计算
E12: 自动生成 | F12: 自动生成 | G12: 自动生成 | H12: 计算 | I12: 计算
E13: 自动生成 | F13: 自动生成 | G13: 自动生成 | H13: 计算 | I13: 计算
E14: 自动生成 | F14: 自动生成 | G14: 自动生成 | H14: 计算 | I14: 计算
E15: 自动生成 | F15: 自动生成 | G15: 自动生成 | H15: 计算 | I15: 计算
E16: 自动生成 | F16: 自动生成 | G16: 自动生成 | H16: 计算 | I16: 计算
E17: 自动生成 | F17: 自动生成 | G17: 自动生成 | H17: 计算 | I17: 计算
E18: 自动生成 | F18: 自动生成 | G18: 自动生成 | H18: 计算 | I18: 计算
E19: 自动生成 | F19: 自动生成 | G19: 自动生成 | H19: 计算 | I19: 计算

Sheet 12制造费用-生产、财务
A1: ← 返回目录 | E1: 填录说明： 第一步，选择年、公司、版本、场景； 第二步，下拉选择产品系列； 第四步，系统将根据生产预算表自动计算产品系列的单吨制造费用数据。 第四步，填制数据完成后，单击【提交】按钮，将数据提交至系统。 单位：元/吨
A5: 责任部门：生产部、财务部
A7: 年 | B7: 2026年 | C7: 公司 | D7: xx澳华 | E7: 版本 | F7: V1 | G7: 场景 | H7: 月度
A9: 大类 | B9: 小类 | C9: 产品系列编码 | D9: 产品系列 | E9: 生产大类 | F9: 预测单吨 | G9: 预算单吨 | H9: 同期单吨 | I9: 同比增减 | J9: 预算差
A10: 自动生成 | B10: 自动生成 | C10: 自动生成 | D10: 自动生成 | E10: 自动生成 | F10: 自动生成 | G10: 自动生成 | H10: 自动生成 | I10: 计算 | J10: 计算
F11: 自动生成 | G11: 自动生成 | H11: 自动生成 | I11: 计算 | J11: 计算
F12: 自动生成 | G12: 自动生成 | H12: 自动生成 | I12: 计算 | J12: 计算
F13: 自动生成 | G13: 自动生成 | H13: 自动生成 | I13: 计算 | J13: 计算
F14: 自动生成 | G14: 自动生成 | H14: 自动生成 | I14: 计算 | J14: 计算
F15: 自动生成 | G15: 自动生成 | H15: 自动生成 | I15: 计算 | J15: 计算
F16: 自动生成 | G16: 自动生成 | H16: 自动生成 | I16: 计算 | J16: 计算
F17: 自动生成 | G17: 自动生成 | H17: 自动生成 | I17: 计算 | J17: 计算
F18: 自动生成 | G18: 自动生成 | H18: 自动生成 | I18: 计算 | J18: 计算
F19: 自动生成 | G19: 自动生成 | H19: 自动生成 | I19: 计算 | J19: 计算

Sheet 13单吨制费计算表
A1: ← 返回目录 | F1: 填录说明： 第一步，选择年、公司、版本、场景； 第二步，分月填写各项目数据 第三步，填制数据完成后，单击【提交】按钮，将数据提交至系统。 单位：元
A5: 责任部门：生产部门
A7: 年 | B7: 2026年 | C7: 公司 | D7: xx澳华 | E7: 版本 | F7: V1 | G7: 场景 | H7: 月度
D8: 单吨制造费用参考值
A9: 生产大类（引用） | B9: 属性 | C9: 指标 | D9: 预测值 | E9: 预算值 | F9: 同期值 | G9: 同比增减 | H9: 预算差 | I9: 说明
A11: / | B11: 生产吨数 | D11: 自动生成 | E11: 自动生成 | F11: 自动生成 | G11: 计算 | H11: 计算
A12: / | B12: 变动 | C12: 人工费 | D12: 自动生成 | E12: 自动生成 | F12: 自动生成 | G12: 计算 | H12: 计算
A13: / | B13: 变动 | C13: 能耗-电耗 | D13: 自动生成 | E13: 自动生成 | F13: 自动生成 | G13: 计算 | H13: 计算
A14: / | B14: 变动 | C14: 能耗-汽耗 | D14: 自动生成 | E14: 自动生成 | F14: 自动生成 | G14: 计算 | H14: 计算
A15: / | B15: 变动 | C15: 机物料费 | D15: 自动生成 | E15: 自动生成 | F15: 自动生成 | G15: 计算 | H15: 计算
A16: / | B16: 变动 | C16: 其他变动费用 | D16: 自动生成 | E16: 自动生成 | F16: 自动生成 | G16: 计算 | H16: 计算
A17: / | B17: 固定 | C17: 固定费用 | D17: 自动生成 | E17: 自动生成 | F17: 自动生成 | G17: 计算 | H17: 计算
B18: 合计 | D18: 计算 | E18: 计算 | F18: 计算 | G18: 计算 | H18: 计算
A19: 沉水鱼料 | B19: 生产吨数 | D19: 自动生成 | E19: 自动生成 | F19: 自动生成 | G19: 计算 | H19: 计算
A20: 沉水鱼料 | B20: 单吨变动费用 | C20: 单吨人工费 | D20: 自动生成 | E20: 自动生成 | F20: 自动生成 | G20: 计算 | H20: 计算
A21: 沉水鱼料 | C21: 单吨能耗-电耗 | D21: 自动生成 | E21: 自动生成 | F21: 自动生成 | G21: 计算 | H21: 计算
A22: 沉水鱼料 | C22: 单吨能耗-汽耗 | D22: 自动生成 | E22: 自动生成 | F22: 自动生成 | G22: 计算 | H22: 计算
A23: 沉水鱼料 | C23: 单吨机物料费 | D23: 自动生成 | E23: 自动生成 | F23: 自动生成 | G23: 计算 | H23: 计算
A24: 沉水鱼料 | C24: 单吨其他变动费用 | D24: 自动生成 | E24: 自动生成 | F24: 自动生成 | G24: 计算 | H24: 计算
A25: 沉水鱼料 | B25: 单吨固定费用 | C25: 单吨固定费用 | D25: 自动生成 | E25: 自动生成 | F25: 自动生成 | G25: 计算 | H25: 计算
A26: 沉水鱼料 | B26: 单吨费用小计 | D26: 计算 | E26: 计算 | F26: 计算 | G26: 计算 | H26: 计算
A27: 膨化鱼料 | B27: 生产吨数 | D27: 自动生成 | E27: 自动生成 | F27: 自动生成 | G27: 计算 | H27: 计算
A28: 膨化鱼料 | B28: 单吨变动费用 | C28: 单吨人工费 | D28: 自动生成 | E28: 自动生成 | F28: 自动生成 | G28: 计算 | H28: 计算
A29: 膨化鱼料 | C29: 单吨能耗-电耗 | D29: 自动生成 | E29: 自动生成 | F29: 自动生成 | G29: 计算 | H29: 计算
A30: 膨化鱼料 | C30: 单吨能耗-汽耗 | D30: 自动生成 | E30: 自动生成 | F30: 自动生成 | G30: 计算 | H30: 计算
A31: 膨化鱼料 | C31: 单吨机物料费 | D31: 自动生成 | E31: 自动生成 | F31: 自动生成 | G31: 计算 | H31: 计算
A32: 膨化鱼料 | C32: 单吨其他变动费用 | D32: 自动生成 | E32: 自动生成 | F32: 自动生成 | G32: 计算 | H32: 计算
A33: 膨化鱼料 | B33: 单吨固定费用 | C33: 单吨固定费用 | D33: 自动生成 | E33: 自动生成 | F33: 自动生成 | G33: 计算 | H33: 计算
A34: 膨化鱼料 | B34: 单吨费用小计 | D34: 计算 | E34: 计算 | F34: 计算 | G34: 计算 | H34: 计算
A35: 虾料 | B35: 生产吨数 | D35: 自动生成 | E35: 自动生成 | F35: 自动生成 | G35: 计算 | H35: 计算
A36: 虾料 | B36: 单吨变动费用 | C36: 单吨人工费 | D36: 自动生成 | E36: 自动生成 | F36: 自动生成 | G36: 计算 | H36: 计算
A37: 虾料 | C37: 单吨能耗-电耗 | D37: 自动生成 | E37: 自动生成 | F37: 自动生成 | G37: 计算 | H37: 计算
A38: 虾料 | C38: 单吨能耗-汽耗 | D38: 自动生成 | E38: 自动生成 | F38: 自动生成 | G38: 计算 | H38: 计算
A39: 虾料 | C39: 单吨机物料费 | D39: 自动生成 | E39: 自动生成 | F39: 自动生成 | G39: 计算 | H39: 计算
A40: 虾料 | C40: 单吨其他变动费用 | D40: 自动生成 | E40: 自动生成 | F40: 自动生成 | G40: 计算 | H40: 计算
A41: 虾料 | B41: 单吨固定费用 | C41: 单吨固定费用 | D41: 自动生成 | E41: 自动生成 | F41: 自动生成 | G41: 计算 | H41: 计算
A42: 虾料 | B42: 单吨费用小计 | D42: 计算 | E42: 计算 | F42: 计算 | G42: 计算 | H42: 计算
A43: 膨化虾料 | B43: 生产吨数 | D43: 自动生成 | E43: 自动生成 | F43: 自动生成 | G43: 计算 | H43: 计算
A44: 膨化虾料 | B44: 单吨变动费用 | C44: 单吨人工费 | D44: 自动生成 | E44: 自动生成 | F44: 自动生成 | G44: 计算 | H44: 计算
A45: 膨化虾料 | C45: 单吨能耗-电耗 | D45: 自动生成 | E45: 自动生成 | F45: 自动生成 | G45: 计算 | H45: 计算
...

Sheet 14饲料销量-营销部
A1: ← 返回目录 | B1: CUBE: | C1: TONGWEI:02外销量（按客户）-导入
B2: 币种 | C2: Local
B3: 新老客户 | C3: 老客户
B4: 备用维1 | C4: 备用1不区分
B5: 备用维2 | C5: 备用2不区分
B6: 科目 | C6: 外销量
B7: 输入项 | C7: 值
B11: F0100xxx饲料外销销量录入表 | F11: 填录说明： 第一步，选择年、公司、部门、版本、场景； 第二步，下拉选择客户名称、是否大客户、产品系列； 第三步，系统将显示上年销量数，按照产品系列分月填录销量数据； 第四步，填制数据完成后，单击【提交】按钮，将数据提交至系统。 单位：吨
B15: 责任部门：营销部
G17: 0
B19: 年 | C19: 2026年 | D19: 公司 | E19: xx澳华 | F19: 部门 | G19: 虾蟹料一部 | I19: 版本 | J19: V1 | M19: 场景 | N19: 月度
B21: 行 | C21: 聚焦镇 | D21: 客户编码 | E21: 客户 | F21: 是否大客户 | G21: 大类 | H21: 小类 | I21: 产品系列编码 | J21: 产品系列 | K21: 战略产品系列 | L21: 预测值 | M21: 预算值 | N21: 同期值 | O21: 同比增减 | P21: 预算差
C23: 自动生成 | D23: 自动生成 | E23: 选择 | F23: 选择 | G23: 自动生成 | H23: 自动生成 | I23: 自动生成 | J23: 选择 | K23: 自动生成 | L23: 填写 | M23: 自动生成 | N23: 自动生成 | O23: 计算 | P23: 计算
B24: 合计 | C24: / | D24: / | E24: / | F24: / | G24: / | H24: / | L24: 计算 | M24: 计算 | N24: 计算 | O24: 计算 | P24: 计算
B25: 行1 | F25: 是 | G25: 虾料 | H25: 虾安康 | L25: 填写 | M25: 自动生成 | N25: 自动生成 | O25: 计算 | P25: 计算
B26: 行2 | F26: 否 | L26: 填写 | M26: 自动生成 | N26: 自动生成 | O26: 计算 | P26: 计算
B27: 行3 | L27: 填写 | M27: 自动生成 | N27: 自动生成 | O27: 计算 | P27: 计算
B28: 行4 | L28: 填写 | M28: 自动生成 | N28: 自动生成 | O28: 计算 | P28: 计算
B29: 行5 | L29: 填写 | M29: 自动生成 | N29: 自动生成 | O29: 计算 | P29: 计算
B30: 行6 | L30: 填写 | M30: 自动生成 | N30: 自动生成 | O30: 计算 | P30: 计算
B31: 行8 | L31: 填写 | M31: 自动生成 | N31: 自动生成 | O31: 计算 | P31: 计算
B32: 行9 | L32: 填写 | M32: 自动生成 | N32: 自动生成 | O32: 计算 | P32: 计算
B33: 行10 | L33: 填写 | M33: 自动生成 | N33: 自动生成 | O33: 计算 | P33: 计算
B34: 行11 | L34: 填写 | M34: 自动生成 | N34: 自动生成 | O34: 计算 | P34: 计算
B35: 行12 | L35: 填写 | M35: 自动生成 | N35: 自动生成 | O35: 计算 | P35: 计算
B36: 行13 | L36: 填写 | M36: 自动生成 | N36: 自动生成 | O36: 计算 | P36: 计算
B37: 行16 | L37: 填写 | M37: 自动生成 | N37: 自动生成 | O37: 计算 | P37: 计算
B38: 行17 | L38: 填写 | M38: 自动生成 | N38: 自动生成 | O38: 计算 | P38: 计算
... B119: 行100 | L119: 填写 | M119: 自动生成 | N119: 自动生成 | O119: 计算 | P119: 计算

Sheet 15动保销售额-营销部
A1: ← 返回目录 | B1: CUBE: | C1: TONGWEI:02外销量（按客户）-导入
B2: 币种 | C2: Local
B3: 新老客户 | C3: 老客户
B4: 备用维1 | C4: 备用1不区分
B5: 备用维2 | C5: 备用2不区分
B6: 科目 | C6: 外销量
B7: 输入项 | C7: 值
B11: F0100xxx动保销售额录入表（除发酵料外） | F11: 填录说明： 第一步，选择年、公司、部门、版本、场景； 第二步，下拉选择客户名称、是否大客户、产品系列； 第三步，系统将显示上年销售额，按照产品系列分月填录销售额数据； 第四步，填制数据完成后，单击【提交】按钮，将数据提交至系统。 单位：元
B15: 责任部门：营销部
G17: 0
B19: 年 | C19: 2026年 | D19: 公司 | E19: xx澳华 | F19: 部门 | G19: 虾蟹料一部 | H19: 版本 | I19: V1 | J19: 场景 | K19: 月度
B21: 行 | C21: 聚焦镇 | D21: 客户编码 | E21: 客户 | F21: 是否大客户 | G21: 大类 | H21: 预测值 | I21: 预算值 | J21: 同期值 | K21: 同比增减 | L21: 预算差
C23: 自动生成 | D23: 自动生成 | E23: 选择 | F23: 选择 | G23: 自动生成 | H23: 填写 | I23: 自动生成 | J23: 自动生成 | K23: 计算 | L23: 计算
B24: 合计 | C24: / | D24: / | E24: / | F24: / | G24: / | H24: 计算 | I24: 计算 | J24: 计算 | K24: 计算 | L24: 计算
B25: 行1 | F25: 是 | G25: 软颗粒 | H25: 填写 | I25: 自动生成 | J25: 自动生成 | K25: 计算 | L25: 计算
B26: 行2 | F26: 否 | H26: 填写 | I26: 自动生成 | J26: 自动生成 | K26: 计算 | L26: 计算
B27: 行3 | G27: 常规动保 | H27: 填写 | I27: 自动生成 | J27: 自动生成 | K27: 计算 | L27: 计算
B28: 行4 | H28: 填写 | I28: 自动生成 | J28: 自动生成 | K28: 计算 | L28: 计算
B29: 行5 | H29: 填写 | I29: 自动生成 | J29: 自动生成 | K29: 计算 | L29: 计算
B30: 行6 | H30: 填写 | I30: 自动生成 | J30: 自动生成 | K30: 计算 | L30: 计算
B31: 行8 | H31: 填写 | I31: 自动生成 | J31: 自动生成 | K31: 计算 | L31: 计算
B32: 行9 | H32: 填写 | I32: 自动生成 | J32: 自动生成 | K32: 计算 | L32: 计算
B33: 行10 | H33: 填写 | I33: 自动生成 | J33: 自动生成 | K33: 计算 | L33: 计算
B34: 行11 | H34: 填写 | I34: 自动生成 | J34: 自动生成 | K34: 计算 | L34: 计算
B35: 行12 | H35: 填写 | I35: 自动生成 | J35: 自动生成 | K35: 计算 | L35: 计算
B36: 行13 | H36: 填写 | I36: 自动生成 | J36: 自动生成 | K36: 计算 | L36: 计算
B37: 行16 | H37: 填写 | I37: 自动生成 | J37: 自动生成 | K37: 计算 | L37: 计算
B38: 行17 | H38: 填写 | I38: 自动生成 | J38: 自动生成 | K38: 计算 | L38: 计算
B39: 行18 | H39: 填写 | I39: 自动生成 | J39: 自动生成 | K39: 计算 | L39: 计算
... B119: 行100 | H119: 填写 | I119: 自动生成 | J119: 自动生成 | K119: 计算 | L119: 计算

Sheet 16动保发酵料-营销部
A1: ← 返回目录 | B1: CUBE: | C1: TONGWEI:02外销量（按客户）-导入
B2: 币种 | C2: Local
B3: 新老客户 | C3: 老客户
B4: 备用维1 | C4: 备用1不区分
B5: 备用维2 | C5: 备用2不区分
B6: 科目 | C6: 外销量
B7: 输入项 | C7: 值
B11: F0100xxx动保发酵料录入表 | F11: 填录说明： 第一步，选择年、公司、部门、版本、场景； 第二步，下拉选择客户名称、是否大客户、产品系列； 第三步，系统将显示上年销售吨位，按照产品系列分月填录销量数据； 第四步，填制数据完成后，单击【提交】按钮，将数据提交至系统。 单位：吨
B15: 责任部门：营销部
G17: 0
B19: 年 | C19: 2026年 | D19: 公司 | E19: xx澳华 | F19: 部门 | G19: 虾蟹料一部 | H19: 版本 | I19: V1 | J19: 场景 | K19: 月度
B21: 行 | C21: 聚焦镇 | D21: 客户编码 | E21: 客户 | F21: 是否大客户 | G21: 大类 | H21: 预测值 | I21: 预算值 | J21: 同期值 | K21: 同比增减 | L21: 预算差
C23: 自动生成 | D23: 自动生成 | E23: 选择 | F23: 选择 | G23: 自动生成 | H23: 填写 | I23: 自动生成 | J23: 自动生成 | K23: 计算 | L23: 计算
B24: 合计 | C24: / | D24: / | E24: / | F24: / | G24: / | H24: 计算 | I24: 计算 | J24: 计算 | K24: 计算 | L24: 计算
B25: 行1 | F25: 是 | G25: 软颗粒 | H25: 填写 | I25: 自动生成 | J25: 自动生成 | K25: 计算 | L25: 计算
B26: 行2 | F26: 否 | H26: 填写 | I26: 自动生成 | J26: 自动生成 | K26: 计算 | L26: 计算
B27: 行3 | G27: 常规动保 | H27: 填写 | I27: 自动生成 | J27: 自动生成 | K27: 计算 | L27: 计算
B28: 行4 | H28: 填写 | I28: 自动生成 | J28: 自动生成 | K28: 计算 | L28: 计算
B29: 行5 | H29: 填写 | I29: 自动生成 | J29: 自动生成 | K29: 计算 | L29: 计算
B30: 行6 | H30: 填写 | I30: 自动生成 | J30: 自动生成 | K30: 计算 | L30: 计算
B31: 行8 | H31: 填写 | I31: 自动生成 | J31: 自动生成 | K31: 计算 | L31: 计算
B32: 行9 | H32: 填写 | I32: 自动生成 | J32: 自动生成 | K32: 计算 | L32: 计算
B33: 行10 | H33: 填写 | I33: 自动生成 | J33: 自动生成 | K33: 计算 | L33: 计算
B34: 行11 | H34: 填写 | I34: 自动生成 | J34: 自动生成 | K34: 计算 | L34: 计算
B35: 行12 | H35: 填写 | I35: 自动生成 | J35: 自动生成 | K35: 计算 | L35: 计算
B36: 行13 | H36: 填写 | I36: 自动生成 | J36: 自动生成 | K36: 计算 | L36: 计算
B37: 行16 | H37: 填写 | I37: 自动生成 | J37: 自动生成 | K37: 计算 | L37: 计算
B38: 行17 | H38: 填写 | I38: 自动生成 | J38: 自动生成 | K38: 计算 | L38: 计算
B39: 行18 | H39: 填写 | I39: 自动生成 | J39: 自动生成 | K39: 计算 | L39: 计算
... B119: 行100 | H119: 填写 | I119: 自动生成 | J119: 自动生成 | K119: 计算 | L119: 计算

Sheet 17产品价目折扣表-财务部
A1: ← 返回目录 | G1: 填录说明： | H1: 第一步，选择年、公司、版本、场景；
H2: 第二步，下拉选择产品系列；
H3: 第三步，分月填录单吨牌价数据；
H4: 第四步，填制数据完成后，单击【提交】按钮，将数据提交至系统。
A5: 责任部门：财务部 | G5: 单位：元/吨
A7: 年 | B7: 2026年 | E7: 公司 | F7: xx澳华 | G7: 版本 | H7: V1 | I7: 场景 | J7: 月度
A8: 单吨折扣（含基本折扣、临时促销、年奖、月奖、买赠等所有折扣）
A9: 大类 | B9: 小类 | C9: 产品系列编码 | D9: 产品系列 | E9: 牌价 | J9: 平均单吨折扣 | O9: 销售净价
E10: 平均预测牌价 | F10: 平均预算牌价 | G10: 平均同期牌价 | H10: 同比平均牌价增减 | I10: 预算牌价差距 | J10: 平均预测单吨折扣 | K10: 平均预算单吨折扣 | L10: 平均同期单吨折扣 | M10: 同比平均单吨折扣增减 | N10: 预算单吨折扣差距 | O10: 平均预测净价 | P10: 平均预算净价 | Q10: 平均同期净价 | R10: 同比平均净价增减 | S10: 预算净价差距
A11: 自动生成 | B11: 自动生成 | E11: 填入 | F11: 自动生成 | G11: 自动生成 | H11: 计算 | I11: 计算 | J11: 填入 | K11: 自动生成 | L11: 自动生成 | M11: 计算 | N11: 计算 | O11: 填入 | P11: 自动生成 | Q11: 自动生成 | R11: 计算 | S11: 计算
F12: 自动生成 | G12: 自动生成 | H12: 计算 | I12: 计算 | J12: 填入 | K12: 自动生成 | L12: 自动生成 | M12: 计算 | N12: 计算 | O12: 填入 | P12: 自动生成 | Q12: 自动生成 | R12: 计算 | S12: 计算
F13: 自动生成 | G13: 自动生成 | H13: 计算 | I13: 计算 | J13: 填入 | K13: 自动生成 | L13: 自动生成 | M13: 计算 | N13: 计算 | O13: 填入 | P13: 自动生成 | Q13: 自动生成 | R13: 计算 | S13: 计算
F14: 自动生成 | G14: 自动生成 | H14: 计算 | I14: 计算 | J14: 填入 | K14: 自动生成 | L14: 自动生成 | M14: 计算 | N14: 计算 | O14: 填入 | P14: 自动生成 | Q14: 自动生成 | R14: 计算 | S14: 计算
F15: 自动生成 | G15: 自动生成 | H15: 计算 | I15: 计算 | J15: 填入 | K15: 自动生成 | L15: 自动生成 | M15: 计算 | N15: 计算 | O15: 填入 | P15: 自动生成 | Q15: 自动生成 | R15: 计算 | S15: 计算
F16: 自动生成 | G16: 自动生成 | H16: 计算 | I16: 计算 | J16: 填入 | K16: 自动生成 | L16: 自动生成 | M16: 计算 | N16: 计算 | O16: 填入 | P16: 自动生成 | Q16: 自动生成 | R16: 计算 | S16: 计算
F17: 自动生成 | G17: 自动生成 | H17: 计算 | I17: 计算 | J17: 填入 | K17: 自动生成 | L17: 自动生成 | M17: 计算 | N17: 计算 | O17: 填入 | P17: 自动生成 | Q17: 自动生成 | R17: 计算 | S17: 计算
F18: 自动生成 | G18: 自动生成 | H18: 计算 | I18: 计算 | J18: 填入 | K18: 自动生成 | L18: 自动生成 | M18: 计算 | N18: 计算 | O18: 填入 | P18: 自动生成 | Q18: 自动生成 | R18: 计算 | S18: 计算
